File: Roentgen/Messdaten/Ge111_40_30_Ni.xrdml
<?xml version="1.0" encoding="UTF-8"?>
<xrdMeasurements xmlns="http://www.xrdml.com/XRDMeasurement/1.3" xmlns:xsi="http://www.w3.org/2001/XMLSchema-instance" xsi:schemaLocation="http://www.xrdml.com/XRDMeasurement/1.3 http://www.xrdml.com/XRDMeasurement/1.3/XRDMeasurement.xsd" status="Completed">
	<comment>
		<entry>huhuu</entry>
		<entry>Configuration=stage XYZ Phi Psi, Owner=User-1, Creation date=17.03.2006 13:32:17</entry>
		<entry>Goniometer=PW3050/60 (Theta/Theta); Minimum step size 2Theta:0.001; Minimum step size Omega:0.001</entry>
		<entry>Sample stage=IR Stage (Phi, Tilt, X, Y, Z)</entry>
		<entry>Diffractometer system=XPERT-PRO</entry>
		<entry>Measurement program=FP, Owner=User-1, Creation date=18.04.2011 15:14:00</entry>
	</comment>
	<sample type="To be analyzed">
		<id></id>
		<name></name>
		<preparedBy></preparedBy>
	</sample>
	<xrdMeasurement measurementType="Scan" status="Completed" sampleMode="Reflection">
		<comment>
			<entry/>
		</comment>
		<usedWavelength intended="K-Alpha 1">
			<kAlpha1 unit="Angstrom">1.5405980</kAlpha1>
			<kAlpha2 unit="Angstrom">1.5444260</kAlpha2>
			<kBeta unit="Angstrom">1.3922500</kBeta>
			<ratioKAlpha2KAlpha1>0.5000</ratioKAlpha2KAlpha1>
		</usedWavelength>
		<incidentBeamPath>
			<radius unit="mm">240.00</radius>
			<xRayTube id="1010041" name="PW3373/00 Cu LFF DK369848">
				<tension unit="kV">40</tension>
				<current unit="mA">30</current>
				<anodeMaterial>Cu</anodeMaterial>
				<focus type="Line">
					<length unit="mm">12.0</length>
					<width unit="mm">0.4</width>
					<takeOffAngle unit="deg">6.0</takeOffAngle>
				</focus>
			</xRayTube>
			<sollerSlit id="21010002" name="Soller 0.04 rad.">
				<opening unit="rad">0.0400</opening>
			</sollerSlit>
			<mask id="22080002" name="Inc. Mask Fixed  10 mm (MPD/MRD)">
				<distanceToSample unit="mm">101.00</distanceToSample>
				<width unit="mm">6.60</width>
			</mask>
			<divergenceSlit id="22010012" name="Prog. Div. Slit" xsi:type="fixedDivergenceSlitType">
				<distanceToSample unit="mm">140.00</distanceToSample>
				<angle unit="deg">0.25</angle>
			</divergenceSlit>
		</incidentBeamPath>
		<sampleOffset>
			<position axis="2Theta" unit="deg">0.012</position>
			<position axis="Omega" unit="deg">-0.125</position>
		</sampleOffset>
		<diffractedBeamPath>
			<radius unit="mm">240.00</radius>
			<antiScatterSlit id="22060009" name="Prog. AS Slit" xsi:type="automaticAntiScatterSlitType">
				<observedLength unit="mm">0.5</observedLength>
				<offset unit="mm">0.00</offset>
			</antiScatterSlit>
			<detector id="7010012" name="X'Celerator Scientific" xsi:type="rtmsDetectorType">
				<phd>
					<lowerLevel unit="%">45.0</lowerLevel>
					<upperLevel unit="%">80.5</upperLevel>
				</phd>
				<mode>Scanning</mode>
				<activeLength unit="deg">2.122</activeLength>
			</detector>
		</diffractedBeamPath>
		<scan appendNumber="0" mode="Continuous" scanAxis="Gonio" status="Completed">
			<header>
				<startTimeStamp>2015-09-03T12:15:04+02:00</startTimeStamp>
				<endTimeStamp>2015-09-03T12:26:54+02:00</endTimeStamp>
				<author>
					<name>Daniel</name>
				</author>
				<source>
					<applicationSoftware version="2.2">X'Pert Data Collector</applicationSoftware>
					<instrumentControlSoftware version="1.7 ">XPERT-PRO</instrumentControlSoftware>
					<instrumentID>0000000000000819</instrumentID>
				</source>
			</header>
			<dataPoints>
				<positions axis="2Theta" unit="deg">
					<startPosition>15.00108891</startPosition>
					<endPosition>129.99550932</endPosition>
				</positions>
				<positions axis="Omega" unit="deg">
					<startPosition>7.50054446</startPosition>
					<endPosition>64.99775466</endPosition>
				</positions>
				<commonCountingTime unit="seconds">3.175</commonCountingTime>
				<intensities 13 16 15 20 13 14 14 14 20 14 15 16 13 12 29 18 21 21 19 16 18 19 12 24 12 9 10 16 19 25 20 9 16 14 25 14 19 12 21 10 6 13 13 15 15 14 14 10 25 12 13 12 12 14 19 13 13 18 16 16 15 18 13 20 15 16 9 9 16 16 10 15 9 9 13 12 21 15 10 13 9 15 14 10 20 18 13 15 13 7 15 16 9 12 20 13 20 18 8 13 8 10 7 18 9 18 12 13 9 20 14 14 8 16 8 20 7 13 16 13 6 19 15 19 12 16 10 14 7 15 12 14 13 15 14 14 13 9 14 12 20 20 15 16 16 14 13 7 13 14 18 14 19 13 16 14 14 13 13 15 7 10 18 9 13 13 14 13 27 9 6 4 19 14 14 12 14 19 15 2 13 16 7 18 15 15 14 10 10 15 18 14 18 18 20 8 13 15 8 14 8 18 13 10 19 7 10 10 2 14 7 9 9 10 14 19 14 10 19 15 15 20 16 12 10 14 9 16 16 15 10 13 16 15 16 12 12 20 14 10 16 13 10 13 18 12 24 13 14 12 7 13 12 19 16 13 21 15 9 20 15 15 18 8 8 13 13 19 12 16 18 10 15 10 12 10 15 14 16 13 14 18 10 8 10 18 16 12 16 14 21 15 16 10 9 13 14 13 15 16 10 18 15 18 20 20 10 9 19 14 6 15 21 9 19 10 10 12 13 19 12 13 9 20 20 15 6 19 8 10 14 12 14 10 18 14 16 16 19 18 9 12 9 14 16 12 12 9 7 8 16 20 18 13 10 12 19 10 12 8 18 10 13 13 13 7 9 20 9 12 8 10 10 7 9 18 8 14 12 6 10 18 14 8 12 12 18 13 12 25 8 12 16 14 10 19 15 12 21 8 13 8 18 13 13 9 14 8 16 12 16 12 10 6 8 14 6 16 12 13 8 18 13 15 10 20 13 14 16 9 12 10 18 16 16 16 14 12 21 15 9 9 8 8 12 15 8 8 19 12 21 12 7 15 16 9 14 18 13 9 7 15 15 12 12 16 4 15 19 12 10 4 15 7 9 9 8 8 14 13 13 7 8 15 16 14 12 16 8 23 6 13 9 9 10 7 9 8 12 9 9 12 6 18 13 15 15 12 8 19 24 18 14 13 16 18 4 10 23 10 13 9 9 14 7 18 18 12 14 9 4 12 12 10 7 18 10 12 6 6 13 7 12 10 6 8 7 10 7 12 4 10 13 16 8 4 12 14 7 10 10 16 6 15 13 10 15 8 16 12 14 15 16 13 15 10 10 12 14 12 8 14 10 15 10 9 13 10 13 8 12 7 14 14 14 21 9 9 8 12 12 3 13 13 10 16 15 14 10 15 8 9 7 12 12 13 15 9 14 6 3 12 12 14 9 13 14 14 12 8 7 8 13 10 6 9 4 10 9 6 13 9 12 8 10 14 9 4 7 12 9 6 12 7 4 8 8 10 6 13 10 8 6 10 9 10 10 15 9 9 7 14 4 8 14 8 7 12 14 2 3 10 7 10 7 7 8 9 8 9 2 6 14 9 15 9 10 1 15 3 10 14 8 10 8 9 12 8 8 4 10 13 9 10 6 9 19 9 10 4 4 8 4 9 15 12 9 14 13 8 16 4 10 6 7 12 12 7 7 12 7 7 8 6 8 10 7 7 7 9 9 9 9 7 9 2 7 14 6 6 3 4 8 8 6 7 8 9 6 7 8 7 4 4 4 8 12 6 4 6 6 9 8 7 8 12 8 18 9 9 10 8 3 9 7 9 7 3 10 9 3 10 13 3 10 13 8 8 8 4 8 9 3 4 7 6 7 7 4 4 15 8 20 15 15 25 20 13 6 13 10 10 8 10 7 6 9 13 2 9 3 3 9 6 4 4 9 6 4 13 6 8 7 14 9 15 8 6 3 10 6 12 13 12 8 13 4 15 13 10 3 6 6 6 6 8 6 7 7 6 3 10 13 12 8 4 8 4 10 3 9 6 8 8 12 8 10 9 7 10 16 13 14 31 44 36 36 14 12 9 4 6 4 10 14 6 7 8 8 9 8 8 4 6 9 9 4 8 7 3 2 6 9 4 4 6 6 7 9 2 7 8 7 6 7 12 6 10 4 4 3 1 7 3 9 4 4 9 3 7 6 8 7 4 3 3 2 8 3 3 8 3 2 6 6 4 7 3 7 8 3 2 4 6 6 4 8 8 6 8 7 9 3 2 1 3 4 7 4 6 6 3 6 7 7 6 10 10 14 6 8 14 21 14 12 9 10 12 10 13 15 13 9 9 12 12 15 18 12 14 14 10 15 12 13 15 20 12 15 13 13 3 13 9 16 8 10 19 19 12 12 15 12 15 13 15 12 9 14 13 8 14 25 14 9 15 15 20 20 12 26 16 13 13 6 15 21 27 21 19 13 4 14 10 18 12 12 15 12 7 18 19 21 12 14 14 7 20 13 13 14 10 16 18 14 16 20 16 10 12 18 14 24 19 10 26 24 21 23 23 31 26 25 20 25 26 21 18 21 20 20 18 32 29 38 50 48 67 152 203 292 338 282 212 144 87 58 56 43 43 44 24 29 38 30 31 15 25 33 14 25 33 27 25 20 15 24 18 19 26 24 18 15 25 18 18 23 16 12 26 14 15 14 16 14 15 23 19 21 14 19 12 18 15 29 20 20 19 21 18 18 16 24 20 13 25 21 25 18 15 18 15 18 16 16 26 18 12 20 16 14 30 21 16 20 13 12 12 12 16 24 10 19 16 18 10 15 13 19 12 9 18 13 26 20 21 19 16 13 20 20 13 18 8 13 14 14 10 16 10 14 15 8 9 13 7 8 4 10 8 8 6 15 6 7 7 10 8 7 7 14 10 7 3 8 8 3 4 2 13 8 8 10 6 8 7 6 9 10 4 9 6 9 6 4 12 14 9 7 9 6 7 8 12 13 6 10 10 15 8 13 12 16 15 18 10 10 19 15 10 7 13 10 14 14 15 12 18 16 21 21 26 18 43 35 43 77 145 184 197 236 231 178 207 219 206 201 226 184 207 198 193 204 195 197 197 173 195 184 192 204 180 202 195 170 203 214 203 204 196 235 212 204 203 203 202 213 197 221 189 195 213 219 224 213 207 215 201 210 214 243 215 208 231 227 193 224 235 236 226 242 254 227 271 261 270 253 294 261 254 312 287 312 284 294 317 327 310 361 324 368 372 424 415 429 454 488 486 556 690 803 917 1191 1487 1653 2076 2349 2458 2435 2658 2732 2908 3328 4027 4776 6335 9038 14656 25057 32671 36578 37591 35914 30099 20831 15410 17763 24623 29371 31099 29745 24028 15370 8826 5747 4410 3445 3099 2805 2515 2121 1852 1554 1365 1224 1161 1038 1007 995 787 729 597 564 481 476 446 473 437 408 379 362 364 385 316 305 347 330 310 286 309 299 275 272 282 259 270 230 229 264 238 243 216 247 230 207 224 180 176 203 203 184 176 161 168 195 187 170 173 190 191 192 180 173 162 183 176 157 141 158 166 172 179 146 146 144 158 160 143 150 140 146 143 146 135 160 118 151 146 115 147 129 145 127 133 134 121 126 151 145 123 132 144 127 116 106 118 140 130 111 136 133 116 116 115 130 124 132 123 123 103 107 113 133 103 103 126 106 130 112 107 122 129 109 121 109 112 109 98 106 113 106 111 111 98 99 116 94 107 106 105 98 109 83 92 99 105 120 87 104 94 84 121 101 103 99 87 84 61 99 121 104 89 89 88 86 111 107 89 84 84 84 89 77 88 93 100 100 78 77 83 100 82 93 82 72 70 93 73 94 92 88 96 73 77 98 83 86 64 73 90 81 106 77 80 67 83 64 72 73 86 65 64 92 99 78 66 69 73 83 80 75 89 96 106 104 100 92 88 73 66 76 83 72 86 92 83 76 76 78 100 71 64 67 69 80 78 78 80 80 94 77 75 61 75 58 88 64 55 86 75 80 76 71 72 64 78 94 101 95 89 103 86 95 76 92 72 75 73 72 52 67 60 72 59 71 61 75 56 73 49 54 54 66 61 50 77 60 61 67 46 61 50 59 47 69 52 52 60 59 47 46 50 52 65 61 65 55 58 42 67 56 65 76 53 61 46 49 46 71 50 60 54 56 54 37 47 58 52 54 58 54 46 54 41 52 47 43 61 55 53 65 43 52 37 41 56 33 65 41 41 49 75 52 58 42 42 42 49 48 36 37 47 41 40 47 54 40 41 48 47 47 33 42 46 54 64 43 38 46 46 42 54 42 43 36 48 53 27 47 37 41 50 40 42 54 50 31 48 48 43 42 37 37 46 44 60 55 27 36 47 33 35 42 50 38 41 47 40 37 27 40 49 36 29 36 31 32 27 23 49 38 37 46 46 48 40 35 40 35 38 41 32 41 36 47 43 37 33 36 42 23 35 47 30 41 25 42 32 43 37 35 33 44 29 26 32 42 38 36 41 49 44 24 47 30 32 30 41 24 32 32 43 33 30 41 30 31 36 33 35 36 23 38 27 37 35 37 30 41 27 25 37 40 43 35 41 40 47 31 35 27 38 32 35 29 31 37 26 26 36 30 18 37 26 26 21 27 24 26 40 29 37 25 20 30 31 24 42 23 30 26 30 30 30 30 24 18 33 35 21 18 30 27 19 10 21 21 23 21 20 19 24 19 21 24 25 15 31 15 13 23 23 32 24 20 26 15 20 25 32 14 30 12 14 30 23 21 25 31 32 20 23 24 21 23 20 21 13 25 12 27 23 25 18 23 12 20 21 21 21 24 24 27 23 27 23 19 26 16 16 18 21 21 24 19 23 14 27 21 14 23 21 27 21 14 25 14 10 18 26 19 19 13 19 23 14 24 20 20 14 16 20 21 14 16 24 18 25 20 27 16 16 18 30 21 16 10 13 23 20 15 19 13 18 15 10 8 19 16 14 15 9 15 19 24 16 10 18 15 15 12 21 12 18 18 15 16 20 18 15 18 12 13 16 13 18 15 14 16 14 15 16 9 15 24 10 13 23 9 10 18 14 10 24 16 18 12 10 12 6 10 15 19 9 14 6 8 12 23 14 18 13 16 13 21 10 10 10 18 13 8 19 14 15 21 12 18 9 12 14 19 10 23 18 13 19 20 23 12 16 15 13 8 12 10 19 20 12 12 12 12 7 9 13 12 16 8 13 10 7 12 13 13 10 14 9 12 9 13 12 12 13 7 7 10 18 18 7 10 10 8 10 9 13 9 4 13 10 4 12 13 15 9 14 18 13 3 16 10 13 9 18 10 14 13 18 12 8 15 8 19 10 9 8 9 7 8 10 16 8 7 9 10 14 1 9 10 8 7 10 6 8 10 10 7 3 9 4 12 12 8 4 4 9 13 4 10 10 4 18 7 6 4 13 7 2 9 16 6 9 8 10 13 7 15 4 7 8 6 8 6 8 7 12 8 6 10 13 13 8 10 8 10 8 8 10 12 13 9 13 8 4 9 8 4 14 7 7 6 12 9 6 14 3 6 9 4 7 7 4 3 7 7 6 8 12 0 6 1 9 7 14 4 4 3 2 4 6 12 4 12 14 4 3 6 6 7 12 7 2 8 6 1 7 8 4 10 12 7 3 6 4 1 4 4 4 13 8 8 3 4 4 2 6 2 3 7 6 6 4 4 2 4 8 4 7 4 10 12 4 4 3 8 6 9 7 8 7 0 6 3 4 9 10 4 9 3 3 3 6 6 7 4 6 7 4 4 6 2 4 2 3 7 14 3 9 7 2 2 3 7 7 4 1 2 6 4 3 8 2 7 7 7 2 7 2 3 1 3 8 4 7 6 6 4 13 6 10 0 7 6 6 8 1 3 8 2 6 1 6 7 2 10 3 2 6 2 4 3 3 3 6 0 3 8 4 6 3 4 8 6 3 4 4 3 9 8 4 6 3 2 8 3 7 1 3 9 1 3 2 3 7 4 4 3 2 3 7 3 7 1 3 6 1 1 1 6 3 2 6 3 4 2 10 6 6 4 4 7 6 3 2 4 6 3 3 2 6 2 2 6 1 6 6 3 2 3 7 6 4 10 0 8 6 7 3 12 14 6 12 7 3 1 3 6 4 7 6 8 6 8 8 2 6 8 7 6 2 4 4 4 6 2 2 6 6 6 4 2 4 6 3 3 3 2 0 6 2 7 2 3 2 7 1 1 1 1 3 3 0 1 2 2 6 3 6 4 1 1 1 2 3 1 3 3 3 3 6 4 3 1 6 3 1 1 3 4 4 1 4 1 2 2 4 2 3 2 6 1 3 2 2 2 1 3 3 1 2 3 2 2 1 6 2 4 6 0 7 1 1 1 2 2 2 0 1 3 2 6 3 6 6 2 4 3 1 3 0 6 8 8 6 4 4 4 1 2 4 6 3 1 2 3 3 2 4 1 3 2 0 1 1 4 1 1 4 3 1 2 2 2 2 0 9 0 2 4 0 8 6 1 1 1 2 8 3 8 0 2 1 4 4 1 6 3 3 1 3 3 2 2 0 3 1 2 2 6 2 2 1 2 0 3 2 4 1 2 2 1 1 0 3 1 1 3 2 3 1 2 2 3 0 1 1 1 2 2 3 2 4 1 1 4 2 2 2 2 4 0 4 1 1 3 3 2 0 3 2 6 2 4 3 4 2 1 1 3 0 1 0 2 0 2 2 1 3 0 3 1 3 2 2 3 4 8 4 3 2 2 4 4 6 2 1 2 3 1 1 2 4 1 0 3 1 2 3 1 2 2 0 0 2 1 1 1 2 2 2 1 0 2 3 0 3 1 4 6 2 1 1 1 3 3 1 1 4 2 3 2 2 3 6 6 3 4 3 6 2 2 1 3 2 1 1 4 1 2 4 1 3 0 2 2 2 2 1 0 4 1 3 3 1 3 3 3 2 2 1 0 1 2 0 1 3 2 0 1 1 4 1 4 0 3 3 2 4 1 2 4 3 1 2 2 2 2 2 3 1 1 1 1 1 2 0 0 3 3 0 3 3 1 4 1 2 0 3 3 2 2 2 8 2 3 2 4 1 1 0 0 4 2 2 0 6 3 2 2 0 3 1 2 0 2 3 2 1 1 1 1 3 1 3 2 0 6 0 4 6 4 2 2 1 0 2 1 1 0 0 0 0 8 3 3 2 0 2 3 2 0 3 1 1 1 1 1 3 3 0 1 2 1 7 3 2 1 3 3 3 4 4 3 1 3 2 3 2 1 2 3 2 3 1 0 1 3 0 1 1 1 1 1 1 6 6 2 0 2 3 4 3 0 1 3 3 3 1 0 2 2 0 1 0 1 0 2 4 4 2 1 0 0 0 1 2 3 0 2 3 1 1 0 0 4 3 2 8 4 2 1 1 0 2 2 1 3 3 3 1 1 3 3 2 2 0 0 0 0 3 3 4 2 2 2 2 3 3 0 0 1 2 3 0 3 0 3 3 1 3 1 1 3 0 1 3 1 3 1 3 3 4 1 1 1 1 6 2 3 1 3 2 6 0 3 2 1 4 2 2 4 2 1 2 3 1 1 0 1 4 3 3 2 0 1 2 2 4 1 1 0 2 2 1 2 2 1 1 3 0 4 1 0 2 2 0 0 0 3 1 3 1 1 0 3 3 3 0 2 1 1 3 0 2 0 0 4 1 1 3 1 1 0 2 2 0 0 2 2 1 4 8 2 2 0 3 3 1 1 3 0 1 1 2 2 1 3 1 3 3 2 2 3 1 2 0 4 0 2 0 1 1 2 1 3 0 1 1 2 0 1 0 2 1 3 0 1 0 1 2 1 1 0 4 2 1 2 3 2 3 1 0 2 1 1 1 0 2 1 1 0 0 2 2 2 1 2 3 2 1 1 4 1 1 2 2 0 1 1 2 1 2 3 1 1 3 2 0 2 2 2 4 2 3 6 2 4 2 2 0 2 2 1 1 3 3 1 6 1 1 2 1 3 2 2 2 1 2 1 0 1 3 2 1 2 2 2 3 1 2 0 4 7 2 4 1 4 4 3 1 1 0 1 2 3 2 2 0 0 0 0 2 2 1 1 2 2 3 1 7 1 3 2 2 1 3 2 1 2 1 2 3 2 2 1 1 1 2 2 2 0 2 0 1 0 2 1 2 1 3 1 0 1 0 2 4 1 1 3 4 1 1 2 1 2 1 2 1 1 2 3 4 2 1 0 2 2 1 2 6 3 2 2 1 0 0 7 2 1 2 2 3 2 2 0 3 0 1 2 2 1 2 2 3 0 1 3 2 0 2 2 0 0 0 2 1 0 1 0 2 3 1 3 1 1 2 1 2 1 2 1 0 2 1 0 2 4 1 0 1 0 1 1 1 3 2 1 2 1 1 1 2 0 4 1 8 2 0 1 3 1 4 2 2 2 1 2 3 1 0 2 2 0 0 1 0 0 0 2 1 1 4 4 2 3 1 3 1 1 3 3 1 4 4 2 2 1 3 1 0 6 2 4 3 1 1 3 2 2 1 2 1 1 4 0 2 2 3 4 2 2 2 2 0 0 4 1 2 1 1 2 3 3 2 0 1 0 4 0 3 1 1 2 2 2 2 3 0 0 1 4 2 2 4 1 1 0 1 0 0 3 2 1 8 1 3 2 1 2 3 3 2 3 3 1 1 2 0 4 2 2 0 0 1 1 2 0 1 2 1 0 0 1 1 2 2 2 0 2 1 0 2 1 2 0 0 0 3 2 1 2 1 2 1 0 0 4 0 3 1 1 2 3 1 2 2 0 4 1 0 6 3 0 1 1 4 2 3 6 2 0 1 2 2 2 0 1 0 1 3 1 3 3 2 4 1 4 2 1 0 2 1 4 2 2 2 1 0 1 1 0 1 1 3 0 2 6 2 2 0 3 2 1 3 0 2 0 4 0 2 2 2 2 1 0 2 0 1 3 0 2 1 1 1 4 1 1 2 0 6 1 1 3 0 0 1 2 1 2 0 2 0 0 1 1 1 1 0 3 0 1 0 0 2 0 1 2 1 1 4 4 2 6 2 2 1 1 3 1 2 3 1 2 2 1 0 4 2 4 2 0 1 2 1 0 2 3 0 1 1 1 1 1 2 2 2 1 0 2 0 0 0 3 0 3 2 1 4 3 6 3 2 3 3 3 4 1 4 6 1 6 0 4 0 7 1 1 4 0 2 1 1 1 2 0 2 2 3 1 3 1 3 2 3 1 2 2 2 0 1 2 1 4 0 2 2 0 4 0 3 1 2 0 1 2 2 2 1 3 2 6 3 1 6 0 1 0 0 3 0 0 0 2 2 1 1 0 0 2 0 3 1 4 1 1 1 1 2 3 1 1 1 2 3 2 2 3 0 2 1 2 1 2 1 0 3 0 1 1 3 2 0 0 2 1 3 1 7 2 1 6 1 2 2 2 2 1 2 3 1 0 2 3 0 4 2 0 2 1 1 2 3 3 1 0 1 2 1 0 0 0 2 0 1 2 2 3 3 0 1 0 3 0 1 2 1 4 2 0 2 1 0 1 3 6 4 1 1 1 0 3 1 1 2 2 0 2 1 0 2 1 1 1 1 1 1 1 4 1 1 3 2 0 1 0 2 2 4 2 3 3 2 1 2 0 1 2 0 2 3 1 1 3 1 1 1 1 2 2 2 1 1 2 3 2 3 2 0 0 0 3 4 2 2 2 4 1 3 3 2 0 1 2 2 2 0 1 2 2 2 3 0 1 2 2 1 0 1 0 1 3 1 7 1 2 3 1 0 4 1 4 1 2 1 3 1 4 1 1 3 4 0 1 2 0 2 1 1 1 1 2 1 0 0 6 2 8 0 4 2 1 1 1 2 3 1 2 1 2 0 2 3 1 1 2 2 2 2 1 3 0 1 2 3 2 3 2 1 1 6 3 3 3 4 1 2 1 1 1 0 2 0 2 1 3 3 4 3 3 3 0 3 1 1 0 2 2 1 4 0 0 0 1 0 1 1 2 4 1 3 0 3 0 0 1 0 2 1 1 0 3 2 0 0 3 3 4 2 6 4 1 1 1 1 0 0 0 2 2 1 2 2 1 1 2 1 1 1 3 0 1 2 3 2 1 3 3 1 2 1 1 1 2 2 1 0 1 1 2 3 2 2 2 2 2 0 1 1 1 1 2 4 2 0 1 1 2 1 0 2 6 1 1 1 1 3 3 1 3 2 1 3 0 2 0 6 0 0 2 2 2 1 2 0 1 1 2 1 2 2 1 0 2 3 2 2 0 1 1 0 0 2 1 3 2 2 2 2 0 1 2 2 3 1 2 1 0 1 2 2 0 2 2 1 1 2 1 0 2 0 0 3 2 1 4 0 3 1 3 1 0 3 0 2 0 2 2 2 1 6 3 1 0 1 2 0 2 2 2 2 2 1 2 2 3 2 0 3 0 0 3 0 4 0 1 2 2 4 2 1 3 4 1 2 1 0 1 3 2 3 0 1 0 0 3 1 4 2 1 1 1 0 1 1 1 0 1 2 3 2 1 2 3 3 3 2 3 0 4 6 3 1 4 1 1 1 1 1 3 2 1 0 3 1 2 1 1 4 1 2 0 2 0 1 1 2 0 0 1 0 4 0 1 2 2 1 3 0 2 1 2 2 0 1 6 4 2 4 4 4 0 1 2 3 3 4 2 1 1 2 2 0 2 0 1 1 3 0 0 2 1 3 3 0 6 0 2 0 2 1 0 0 3 1 0 1 2 0 2 1 1 2 0 0 1 0 2 1 2 0 2 2 1 1 1 2 0 2 1 0 3 4 4 1 1 4 2 4 0 2 0 4 0 2 1 0 1 0 0 0 1 1 1 1 3 2 0 3 2 3 2 0 2 2 1 2 1 4 0 1 1 2 2 0 3 0 1 1 2 1 1 1 3 3 1 2 1 0 2 2 3 3 6 0 2 0 0 2 0 2 0 1 6 2 1 3 2 1 2 1 0 2 1 1 3 2 1 2 0 0 2 1 1 1 0 2 1 3 1 1 0 1 0 2 3 0 2 1 4 1 4 1 0 0 6 2 2 2 3 1 3 1 0 1 0 1 1 2 6 2 1 6 3 1 2 1 1 2 2 2 3 2 0 3 1 1 3 7 1 4 1 6 2 3 1 3 3 8 10 16 25 41 69 104 109 88 53 46 37 18 16 16 16 7 19 6 6 12 12 12 35 35 35 56 40 21 9 10 10 3 6 4 8 1 3 1 2 6 8 2 1 1 0 3 1 2 4 6 1 1 3 1 6 2 2 3 2 1 1 2 2 3 2 1 7 4 1 2 1 8 3 1 6 0 0 1 2 2 1 1 2 0 2 1 2 2 1 1 0 2 3 1 1 1 2 0 0 0 0 1 2 0 3 1 2 2 3 0 4 1 2 1 0 1 3 3 2 3 2 1 3 7 0 3 1 3 3 3 1 3 2 0 1 3 0 0 1 2 1 1 1 0 2 1 0 0 2 1 0 1 1 6 1 3 1 2 1 0 0 1 2 0 0 0 3 1 1 1 1 1 2 1 0 0 4 0 2 0 4 2 2 0 1 2 2 2 1 2 3 1 3 0 2 1 1 1 3 3 1 0 1 4 0 1 2 1 0 4 2 2 1 7 2 1 1 3 1 0 0 3 0 1 1 1 1 1 1 7 1 0 3 1 3 1 4 4 1 6 1 4 0 1 3 2 1 2 1 1 2 0 1 1 2 2 2 1 1 1 3 1 1 3 1 4 0 1 1 1 1 1 0 3 0 3 2 3 0 2 2 0 1 0 0 1 1 3 1 4 3 1 1 0 0 0 1 2 1 1 3 1 6 2 0 2 1 4 0 0 2 3 2 2 7 2 0 2 2 0 3 1 1 2 1 2 2 1 3 2 2 2 2 2 1 1 1 0 1 1 0 0 2 1 2 1 1 1 1 0 2 1 2 2 3 1 0 0 2 1 1 1 2 0 0 1 0 3 0 0 4 1 1 1 2 1 4 0 1 3 1 1 3 0 2 0 6 3 3 4 3 1 6 2 6 1 2 2 2 0 1 2 2 2 1 1 2 1 2 2 2 1 0 6 0 2 2 0 0 0 2 0 3 2 3 2 4 2 2 0 6 3 1 0 0 2 0 1 2 1 3 1 2 1 1 0 0 0 2 1 3 1 1 0 1 0 2 2 1 2 0 3 0 2 1 0 1 1 1 3 1 3 0 1 1 3 0 6 0 1 2 0 1 0 2 2 3 2 1 0 0 1 2 3 2 2 0 0 2 0 0 1 1 3 3 0 1 0 1 0 0 0 2 2 0 0 6 1 1 1 3 3 1 4 0 2 0 3 4 0 2 3 1 1 3 2 1 1 1 0 4 4 0 0 1 0 0 1 1 1 2 0 2 1 2 2 2 1 3 2 0 3 2 1 1 2 6 2 0 2 0 2 1 1 1 2 2 0 1 1 1 1 1 0 1 0 1 1 0 1 1 0 4 3 2 2 1 0 1 1 0 3 0 1 2 0 2 2 1 0 0 0 0 1 2 2 1 0 3 0 1 2 0 2 0 0 1 0 1 2 1 2 2 0 1 2 0 0 0 3 1 1 1 2 2 2 1 0 1 3 0 1 0 0 0 0 0 0 0 1 1 2 2 1 2 2 0 1 2 3 1 1 1 0 0 0 0 1 0 0 2 2 4 1 0 4 3 2 6 0 0 1 2 1 0 1 0 1 0 3 2 1 1 3 0 0 3 2 3 3 0 3 1 4 7 3 2 0 3 0 0 1 1 2 2 1 3 0 0 0 2 1 0 0 1 0 0 4 6 1 0 2 1 0 2 1 0 3 4 1 4 3 1 3 3 3 2 1 0 4 2 3 0 2 1 1 0 4 1 2 2 3 3 3 0 3 3 0 3 1 1 0 1 2 2 0 0 1 0 3 3 0 2 1 0 1 0 1 1 1 0 3 2 0 2 2 3 2 0 3 1 1 0 1 0 1 1 2 1 0 4 0 2 1 2 4 0 2 1 0 2 1 1 2 3 1 1 3 2 1 1 2 1 2 3 1 1 4 2 3 1 1 2 1 0 3 2 1 3 1 1 4 0 2 2 1 3 4 1 1 1 2 1 4 6 2 4 2 1 3 1 3 1 2 1 1 0 0 3 4 0 3 4 3 0 0 1 2 4 2 2 1 3 1 0 0 2 1 1 3 0 4 0 1 1 4 1 2 2 0 1 1 2 2 3 1 0 1 2 2 1 0 0 2 0 2 2 0 2 1 2 2 3 0 1 0 2 1 3 1 0 0 2 2 2 3 0 0 1 3 0 2 3 1 2 1 2 2 1 1 2 1 1 2 1 2 0 1 1 3 2 0 2 6 0 4 1 2 2 0 1 1 0 0 1 1 1 2 0 7 1 2 1 0 1 0 3 1 0 2 2 0 3 1 2 2 1 3 2 1 6 1 1 0 1 0 3 1 1 1 0 2 0 1 0 3 4 1 0 0 2 0 0 2 1 1 2 0 3 6 1 0 2 2 0 2 1 0 0 3 2 1 1 1 2 1 0 0 2 3 1 1 1 2 1 0 0 0 1 2 1 1 1 1 2 0 1 0 0 4 1 0 2 0 3 1 1 2 3 1 7 0 1 1 0 2 1 0 1 1 0 0 2 1 0 1 0 2 1 6 0 2 0 1 3 0 1 1 2 1 4 1 1 2 1 1 2 1 3 0 2 0 2 1 1 1 1 3 1 2 2 3 1 1 2 1 3 3 2 1 4 1 0 2 1 1 0 1 3 2 1 1 2 2 1 1 3 1 3 1 2 2 3 0 1 2 2 0 0 1 0 2 0 3 1 1 2 2 2 0 1 2 0 1 3 3 3 4 1 3 1 0 3 1 1 0 1 1 1 0 1 3 0 1 1 3 0 2 1 3 0 2 0 2 2 1 2 2 1 0 4 0 2 2 1 3 0 1 0 2 2 1 0 0 1 0 3 2 1 1 1 2 0 3 3 1 1 1 0 0 1 2 0 1 1 1 0 0 2 2 1 6 2 1 3 2 2 1 2 0 2 0 1 2 0 3 2 2 1 0 4 2 2 2 1 1 0 0 1 2 0 3 1 0 0 0 0 2 2 2 0 3 1 0 1 0 2 1 1 3 1 3 2 0 1 2 0 1 2 1 0 1 0 2 1 1 2 3 1 3 0 1 3 1 1 1 0 2 3 3 0 1 1 0 2 0 2 1 4 3 1 2 2 2 2 0 0 1 2 1 4 2 1 0 3 2 0 0 1 2 1 3 0 2 4 1 1 2 1 1 2 1 2 2 0 3 3 0 1 1 2 1 1 0 0 2 3 3 4 0 1 1 0 1 0 0 0 2 1 0 1 1 0 0 0 0 1 3 1 2 0 0 1 1 1 0 1 1 3 3 3 2 1 4 2 1 1 2 1 0 2 1 1 1 1 0 0 1 1 0 2 3 2 1 4 4 3 1 0 0 0 0 0 3 1 1 2 1 2 2 1 1 2 0 1 2 2 1 2 2 0 3 0 2 1 3 1 2 1 2 3 1 0 1 6 0 1 1 7 0 3 0 0 2 1 1 0 1 1 1 0 0 2 2 0 1 2 0 1 6 6 0 2 3 1 1 0 0 1 1 1 0 0 0 3 0 1 1 0 2 0 1 0 1 2 1 1 0 1 4 1 2 1 1 1 1 0 2 1 1 2 3 2 1 3 1 2 0 0 4 0 2 0 1 1 1 2 2 1 3 1 4 0 1 4 0 1 0 1 2 2 2 2 2 1 1 3 3 1 1 6 3 2 1 1 0 2 3 0 1 2 1 2 2 1 1 4 1 6 1 0 0 1 0 1 3 2 2 3 0 4 1 0 2 2 1 2 1 2 1 2 3 1 1 0 1 3 2 0 1 2 1 2 1 0 1 2 1 2 2 1 1 1 2 1 2 0 2 3 4 1 1 2 2 3 3 1 0 0 3 1 3 1 1 1 1 0 2 4 1 1 2 0 0 0 1 2 0 0 3 2 1 2 1 2 1 1 0 1 0 1 1 0 2 0 3 1 0 0 1 1 0 1 1 1 0 1 3 2 1 4 0 0 2 2 1 2 0 2 0 3 0 1 0 1 1 3 6 1 1 1 0 0 0 0 0 1 4 4 0 3 1 1 0 1 1 2 0 2 2 2 1 1 1 1 0 3 0 3 0 0 1 0 2 0 0 1 1 3 1 0 0 1 1 0 0 0 4 0 1 2 1 2 1 1 0 1 0 0 0 0 1 0 0 0 1 1 1 1 0 2 0 0 3 2 2 0 1 0 0 4 0 2 1 0 1 0 1 2 2 0 1 1 1 1 4 1 1 2 0 3 2 4 1 2 1 0 0 2 0 1 1 1 0 0 3 1 1 2 1 3 0 0 6 1 3 2 6 1 3 4 1 4 0 2 2 2 2 0 1 1 2 2 0 1 1 0 0 1 2 2 1 1 1 2 2 0 0 3 1 3 1 0 2 1 1 1 1 1 1 4 0 1 0 1 1 4 3 0 0 0 1 1 0 4 0 0 0 2 0 1 1 1 0 2 4 3 1 1 1 1 0 1 0 1 1 1 1 4 0 0 4 2 2 0 2 3 4 0 1 2 2 2 2 2 1 0 1 1 3 0 2 2 0 1 0 1 1 3 1 1 0 0 1 2 2 3 0 0 2 0 0 0 3 0 0 2 1 1 2 1 1 2 0 2 1 1 4 0 0 0 0 2 1 1 0 2 0 1 3 2 2 3 1 0 2 0 2 1 1 1 1 0 2 0 2 0 1 2 0 1 0 0 0 3 1 2 0 1 2 0 1 2 1 1 2 1 0 1 1 3 0 1 0 3 1 1 1 0 2 0 2 1 0 0 1 1 0 1 0 1 1 0 1 0 2 1 0 0 2 0 1 1 1 0 0 2 4 3 2 1 1 1 1 1 0 0 2 1 0 0 0 1 2 1 2 0 0 1 1 1 0 2 1 0 1 0 0 1 0 1 0 2 2 1 0 0 0 0 0 6 2 0 1 2 2 3 0 1 2 0 2 1 0 1 2 3 1 0 2 2 0 2 2 0 3 0 1 1 2 1 3 0 0 1 2 1 1 1 0 1 1 0 0 1 0 1 0 1 1 0 0 1 0 0 1 1 0 2 1 1 0 0 3 0 1 0 3 0 1 3 4 1 2 2 1 0 1 0 1 0 1 0 1 0 1 0 0 0 0 1 1 2 0 0 1 2 2 0 1 0 1 2 1 1 0 1 3 2 2 1 0 1 1 1 3 0 0 2 2 1 1 2 2 1 2 1 2 2 0 2 1 1 0 1 1 0 1 1 1 0 0 1 0 1 2 1 2 0 1 1 2 2 2 4 1 1 1 1 1 2 3 1 1 1 1 1 1 2 2 4 1 0 2 1 2 3 0 2 1 0 7 0 0 0 1 0 1 1 1 0 2 2 1 1 1 0 0 2 1 0 1 1 0 3 2 1 1 0 1 1 0 1 2 0 1 0 2 1 1 0 2 1 1 2 2 0 2 3 2 1 1 1 2 2 2 1 1 0 1 0 2 1 0 1 1 1 1 1 2 1 4 4 2 2 0 1 1 3 0 2 0 3 0 1 0 1 0 1 0 1 1 1 2 3 1 1 2 0 1 4 1 0 2 2 2 0 2 0 3 2 0 0 2 2 1 1 1 2 2 0 0 3 2 0 0 1 1 0 2 1 1 1 1 2 0 1 2 2 2 1 0 4 1 1 3 1 2 0 1 4 3 1 1 1 2 1 1 2 1 3 1 0 1 2 0 2 1 0 0 1 1 2 3 1 1 1 1 0 2 2 0 0 2 2 0 3 3 3 0 2 0 3 1 1 0 2 0 3 1 1 0 1 1 1 2 3 0 1 1 1 1 2 0 0 1 3 1 3 1 0 2 3 0 1 0 1 1 2 2 1 2 1 1 0 2 2 3 0 0 0 3 1 1 2 0 2 0 0 2 0 1 2 1 0 2 0 1 1 1 2 2 0 1 1 1 3 0 1 0 0 1 2 0 0 0 0 1 0 0 1 4 2 0 1 3 1 1 6 6 0 1 2 0 0 1 1 4 4 7 3 1 2 1 4 1 3 2 1 2 1 3 3 3 0 2 3 2 2 0 3 0 2 3 2 3 2 0 1 4 2 4 1 2 1 2 6 3 2 0 1 4 2 1 3 2 2 1 3 1 4 3 1 4 4 3 0 3 1 1 1 1 3 2 3 2 2 6 2 0 1 1 1 2 2 1 4 1 2 2 4 1 2 1 2 3 2 2 9 2 2 0 6 2 1 3 3 2 2 1 0 3 3 2 2 2 1 4 4 3 1 0 1 1 4 6 6 2 2 3 3 2 6 1 10 8 10 8 10 16 14 25 19 21 19 19 19 16 3 12 7 4 12 9 4 8 7 7 3 4 6 7 3 2 2 4 4 2 3 3 6 7 0 0 2 3 1 3 2 3 2 3 3 2 6 1 4 1 3 3 3 2 1 0 2 2 4 2 2 2 8 2 2 2 0 6 2 4 2 3 1 1 2 3 6 3 3 2 1 4 0 1 6 2 2 4 3 3 1 1 0 3 3 2 1 2 3 3 0 2 3 1 4 2 0 3 1 1 1 1 6 1 1 2 1 0 1 2 4 0 3 2 3 3 1 2 1 0 3 0 0 3 1 2 2 0 2 1 1 2 0 1 2 0 2 2 2 1 2 0 3 1 1 0 1 3 0 1 2 1 2 2 1 1 2 1 4 1 1 1 2 1 1 1 1 3 1 1 0 1 3 2 2 2 1 0 1 3 3 1 1 1 4 1 1 0 3 1 2 1 3 1 1 2 1 4 1 2 1 0 1 2 1 3 0 2 1 2 1 1 1 0 1 4 0 1 3 2 1 1 0 1 1 0 2 0 0 2 0 0 1 2 1 2 1 1 1 2 0 1 2 0 0 1 2 0 4 4 1 1 2 0 0 1 0 3 0 0 1 1 1 1 0 0 3 2 1 2 1 3 1 1 2 2 2 0 0 2 2 0 2 2 1 2 1 0 1 2 1 2 2 1 2 4 1 0 2 0 2 1 1 1 1 1 0 0 1 1 2 0 4 1 2 1 1 1 1 0 0 0 2 1 0 1 2 2 0 0 1 2 1 2 1 0 0 2 2 1 1 2 0 1 1 2 0 0 1 0 2 3 1 0 2 2 1 2 1 2 2 1 2 1 0 1 2 1 3 0 1 0 1 0 3 0 0 1 1 2 0 2 3 0 1 1 2 0 0 1 1 1 0 0 0 0 1 2 1 0 0 0 2 1 1 3 0 0 1 0 2 1 1 0 2 0 2 0 0 1 0 3 1 1 2 1 2 0 1 2 0 2 0 1 0 0 0 0 1 1 0 3 3 2 0 2 0 1 0 1 3 3 0 1 0 2 0 1 0 4 4 1 0 2 0 6 2 1 0 0 1 0 1 0 1 0 0 1 1 0 2 2 2 2 0 2 1 0 0 3 2 2 1 3 1 3 1 0 1 3 1 2 0 0 2 1 0 1 2 0 1 0 1 1 2 0 2 3 1 1 0 0 0 0 0 0 1 0 1 1 0 2 1 3 3 0 2 2 0 1 2 1 3 2 3 1 0 4 0 3 0 0 1 1 2 1 0 1 4 1 0 0 0 1 0 0 2 1 0 4 0 1 0 2 1 2 1 4 2 0 0 1 3 0 2 3 0 0 1 1 1 2 1 4 0 0 2 1 4 1 2 0 2 2 1 2 1 0 1 1 2 2 2 2 4 6 0 0 2 2 3 1 0 2 0 1 2 0 2 1 2 1 1 1 0 1 3 3 0 0 3 1 0 1 2 0 1 2 2 1 1 0 1 1 2 2 2 2 0 1 1 1 0 0 0 3 2 2 0 0 0 1 1 0 0 2 2 1 0 3 0 1 4 2 2 1 0 1 3 0 2 2 6 2 4 1 0 3 0 4 2 3 1 0 4 2 1 1 1 0 1 1 0 0 0 0 2 0 1 4 0 1 1 2 3 1 2 3 1 2 1 1 2 3 0 1 0 1 1 3 2 6 1 0 4 2 6 4 1 0 1 3 3 1 0 2 3 1 3 2 3 1 2 3 0 1 0 1 2 1 4 0 1 1 2 0 2 0 2 3 1 2 3 1 2 3 0 2 6 2 6 3 0 6 7 3 6 2 1 1 8 8 7 7 1 7 4 7 8 6 4 14 8 6 4 8 9 9 6 3 9 7 8 7 3 13 9 7 16 9 14 6 9 6 7 7 8 6 10 6 14 10 4 3 7 8 8 8 6 14 4 6 12 6 7 7 9 4 3 6 4 7 6 6 4 7 4 10 4 12 6 8 6 6 10 4 6 8 9 8 9 3 14 3 9 4 4 7 6 8 9 4 6 6 3 10 13 8 6 6 4 4 8 6 7 6 12 3 8 7 9 3 9 9 10 9 4 10 12 8 8 9 9 4 10 10 6 10 9 7 3 4 7 4 8 7 7 3 7 1 4 6 8 6 4 2 3 6 7 7 8 13 7 4 4 1 6 9 7 4 6 13 15 13 12 7 6 8 3 7 6 7 8 12 7 2 6 8 13 1 10 9 8 10 13 6 4 2 6 6 4 8 7 7 9 8 7 8 9 9 4 3 10 6 3 14 16 7 8 8 6 3 12 6 12 9 12 8 2 8 4 13 13 9 8 6 3 1 10 4 8 9 7 6 10 2 9 12 7 7 6 3 3 9 9 8 13 7 12 13 7 7 4 7 9 10 8 6 7 10 14 4 14 9 12 6 7 10 9 8 8 10 4 10 12 10 10 13 8 23 9 12 4 7 7 14 8 9 10 10 7 6 15 6 6 9 8 13 10 15 14 12 10 14 7 13 10 9 6 10 8 15 8 6 3 9 8 12 6 12 7 7 10 9 9 9 15 9 15 14 6 10 16 16 8 13 19 10 16 15 13 16 10 16 15 12 29 9 7 13 14 9 15 14 10 19 14 13 10 14 24 19 14 21 16 18 19 13 16 18 18 25 30 21 26 21 23 16 26 15 19 21 21 20 31 18 26 27 21 30 32 29 40 36 50 49 56 50 41 63 66 63 64 50 56 56 86 59 64 70 65 50 63 80 64 56 69 49 50 70 49 63 54 48 64 65 60 69 67 63 70 94 82 73 101 118 124 123 147 135 166 183 221 212 250 260 286 403 380 435 472 578 699 807 1009 1334 1757 2517 3636 5263 6712 7599 7400 6495 4845 3576 2687 2057 1716 1261 989 904 743 608 527 463 406 427 420 414 361 375 389 367 412 444 455 490 722 867 1074 1561 2011 2669 3299 3667 3691 3233 2664 2303 1665 1229 964 768 606 515 426 327 267 253 209 212 191 160 144 155 141 143 130 99 86 87 94 73 77 70 81 71 42 64 50 81 43 59 46 55 43 47 44 52 53 37 38 38 33 27 47 29 43 26 31 31 23 29 35 26 31 26 20 42 23 19 26 24 33 25 21 30 20 26 27 24 9 14 16 23 24 15 25 20 10 10 24 15 10 21 12 12 16 9 15 14 9 24 16 20 21 12 15 7 15 20 16 23 12 14 9 14 20 12 12 15 14 12 8 9 8 18 7 15 13 13 8 9 10 10 16 8 18 12 8 8 15 10 13 16 13 15 7 13 16 19 7 10 18 10 9 8 12 7 8 10 9 9 14 9 9 9 12 12 8 18 9 14 13 10 14 10 7 8 3 15 9 12 8 12 8 6 4 6 6 7 14 9 4 10 6 6 7 10 1 12 7 12 8 9 3 9 9 9 12 9 2 10 6 9 10 9 14 12 9 10 6 2 8 10 8 6 8 8 13 6 7 6 7 6 16 8 3 6 13 9 9 10 12 7 9 7 7 3 2 8 10 3 3 7 12 4 10 7 6 10 12 7 6 8 10 7 10 4 6 10 1 14 6 4 7 12 9 7 3 9 2 7 6 2 6 4 7 4 6 8 4 6 2 7 12 4 7 2 6 3 10 1 8 8 4 7 4 7 6 4 7 2 14 4 4 3 3 6 2 3 7 6 7 1 9 8 8 9 2 7 6 9 7 6 6 3 4 8 6 9 1 9 8 3 6 8 4 4 4 10 6 4 9 2 7 2 7 3 1 9 8 10 9 12 4 4 6 4 6 3 7 2 2 3 7 12 8 3 7 8 8 4 7 3 0 9 9 3 1 4 3 6 6 2 4 8 6 8 9 7 7 4 9 9 2 2 1 6 9 8 4 6 3 4 7 3 3 6 7 12 4 1 1 7 6 8 6 4 3 2 4 8 4 4 2 2 3 3 1 9 1 7 2 7 13 9 3 7 4 4 6 2 6 4 3 4 3 4 4 6 6 2 2 2 8 3 7 4 3 3 4 4 4 2 3 4 7 8 3 6 7 8 7 2 7 4 4 7 3 6 3 4 1 1 10 1 4 3 6 4 4 7 8 2 2 3 6 4 4 1 3 4 4 3 3 6 2 1 7 7 6 3 8 3 4 2 3 8 6 2 2 2 6 1 2 6 3 3 4 0 3 3 3 6 6 9 4 9 1 2 6 2 7 1 4 1 3 3 4 4 3 6 4 1 3 8 4 0 4 6 8 2 3 10 7 3 3 4 3 3 8 6 2 2 3 1 3 3 4 6 2 0 7 7 4 3 1 3 4 3 7 4 1 7 4 3 3 0 6 2 3 6 3 8 3 6 6 9 6 1 4 4 3 6 1 4 7 7 1 2 6 6 3 3 3 3 9 3 3 6 2 3 4 3 7 4 6 4 7 2 3 6 4 4 3 1 3 3 6 4 3 8 0 2 3 4 4 3 6 1 3 4 2 2 1 0 9 3 6 3 2 4 4 2 2 8 8 1 3 4 7 6 3 1 3 2 3 4 3 4 4 3 6 1 0 7 4 3 7 2 2 9 3 2 7 1 2 4 1 1 2 1 3 3 7 6 6 6 4 6 4 2 4 4 6 1 3 4 3 4 1 3 4 2 4 4 0 6 4 7 4 2 4 6 6 7 2 4 4 7 3 7 3 9 4 1 1 3 2 6 4 2 4 7 7 6 1 4 6 0 2 6 2 2 2 3 1 4 2 3 2 4 7 3 7 8 6 2 6 4 2 2 2 2 2 1 4 2 3 1 6 6 8 2 2 3 9 2 0 4 7 2 4 3 2 1 2 3 9 1 1 4 6 2 3 7 3 3 3 6 4 3 4 4 2 4 2 2 2 3 2 2 4 4 0 2 2 4 6 1 3 6 3 9 4 6 6 2 7 4 2 7 4 3 2 7 3 4 2 6 10 2 3 12 2 7 4 4 4 6 3 1 6 3 2 3 3 3 3 4 3 7 1 4 1 4 1 1 1 2 3 3 2 4 1 8 8 1 3 4 0 2 6 4 4 3 4 3 7 2 4 7 3 3 3 3 2 3 6 6 2 3 0 1 6 4 2 2 4 3 0 4 4 3 2 1 4 2 3 4 7 2 1 3 3 6 3 0 7 1 4 7 3 2 4 1 2 3 2 2 4 8 3 3 4 2 6 2 6 1 7 0 1 9 3 6 7 2 6 8 3 6 3 2 2 1 1 3 0 1 3 1 4 4 4 2 2 3 3 0 1 2 3 2 1 4 1 3 6 6 6 7 2 4 3 4 3 3 6 4 3 6 4 6 1 3 3 7 3 4 3 4 3 1 1 4 4 3 9 4 9 4 2 2 4 4 6 6 4 6 3 4 1 3 2 6 4 3 2 2 4 1 2 4 2 8 1 3 3 2 1 3 7 4 0 1 8 3 2 3 4 4 2 2 3 2 2 2 2 4 1 4 0 7 3 1 2 4 2 4 2 1 6 6 2 4 2 1 7 3 3 2 8 1 3 2 2 2 2 0 4 2 1 4 2 7 3 7 0 2 1 3 7 2 2 2 2 6 7 3 1 2 1 3 3 6 4 1 2 2 0 4 2 1 2 3 6 3 3 3 3 3 1 4 2 6 4 6 9 3 7 6 4 2 2 4 6 6 6 2 8 1 2 3 4 7 1 0 6 1 2 2 2 2 3 4 4 0 3 4 4 2 1 2 2 7 2 2 4 3 6 4 3 2 4 2 3 8 0 0 1 6 1 4 6 4 4 4 8 6 2 7 2 2 2 6 1 1 4 2 2 3 3 2 6 3 4 2 3 3 3 2 2 3 2 4 4 1 3 2 3 2 2 3 2 1 1 3 6 1 3 3 1 3 1 4 3 0 4 7 0 4 4 9 3 7 4 2 3 3 2 2 6 2 2 3 3 0 3 2 3 1 1 1 4 0 4 3 2 0 6 1 1 3 1 0 2 0 3 6 1 1 3 2 4 2 2 6 0 0 2 2 6 2 2 1 7 3 3 3 1 2 3 6 4 0 3 1 2 1 3 1 0 6 3 1 3 2 4 1 3 3 9 3 4 3 3 1 4 6 2 6 1 2 3 2 6 0 3 4 1 4 2 0 2 1 3 3 1 1 3 6 3 0 4 3 2 3 2 2 2 1 1 4 4 0 3 3 2 3 3 6 7 2 4 2 3 1 0 3 2 1 3 1 2 1 3 3 2 1 4 1 2 8 4 4 4 3 3 4 1 1 7 3 2 4 1 0 2 1 1 3 1 3 0 2 3 2 4 1 3 1 2 2 7 1 4 7 2 3 3 0 2 1 1 0 2 0 3 0 6 1 0 4 3 1 3 6 0 0 1 2 0 1 3 2 1 7 1 1 2 0 1 4 0 1 3 2 4 1 7 8 3 2 6 3 4 1 2 1 2 4 1 0 2 4 1 1 1 0 7 1 2 3 4 3 3 2 7 1 0 3 3 7 2 2 4 2 3 6 1 7 2 6 0 2 3 1 1 8 0 6 4 3 0 2 1 2 2 3 3 1 3 2 3 3 6 3 2 6 1 3 7 1 2 7 6 2 1 1 3 2 3 3 4 2 3 6 1 3 2 3 1 2 2 4 6 2 1 4 2 8 1 2 2 1 2 4 6 1 6 2 0 6 1 2 8 2 1 2 4 4 2 2 2 1 6 3 3 7 2 2 3 2 4 7 3 1 1 2 6 1 2 0 0 2 1 2 2 4 0 2 3 2 3 3 1 4 2 3 3 1 2 2 1 4 0 2 1 2 1 2 3 3 3 1 1 4 3 1 3 3 2 8 3 1 0 1 2 1 2 7 2 3 3 1 1 2 2 1 4 1 2 6 3 2 3 4 2 1 1 1 2 2 1 1 2 2 1 1 4 0 3 1 2 2 0 3 6 1 0 2 0 3 3 8 1 3 3 2 1 3 0 3 1 0 1 2 1 1 3 3 1 0 2 6 0 3 4 1 2 2 0 4 3 2 2 4 3 3 1 4 2 2 1 1 1 4 2 3 1 0 2 6 3 4 1 2 2 3 1 1 1 2 1 1 4 2 1 3 2 2 4 4 1 2 2 1 1 7 3 2 0 0 4 1 0 2 1 2 3 1 1 3 0 3 2 0 2 1 3 2 3 4 3 0 1 1 1 0 2 3 2 3 3 3 2 1 0 3 1 2 1 3 1 1 2 1 2 3 3 2 4 0 1 1 2 2 0 3 4 2 2 1 0 1 2 3 3 3 1 2 2 2 1 1 6 2 2 1 0 0 1 3 4 0 2 1 2 1 7 2 2 2 2 3 2 4 1 1 1 4 1 2 0 1 2 3 2 1 1 4 1 1 3 2 6 3 7 3 4 2 2 3 2 1 3 2 1 0 4 1 2 2 2 1 0 2 2 2 0 1 3 0 0 3 2 1 3 1 7 2 1 0 0 2 1 1 1 0 6 3 4 3 2 3 0 1 2 3 1 1 3 3 1 2 2 3 3 3 7 3 4 0 3 3 1 1 0 0 2 4 2 2 2 2 3 2 1 1 1 3 3 2 0 0 3 1 2 4 2 1 2 3 2 2 1 1 4 1 3 3 7 3 4 4 2 2 0 4 1 0 3 0 2 1 4 1 0 4 1 1 3 3 4 0 4 2 3 0 2 4 3 4 3 2 2 4 4 1 4 2 4 2 1 3 1 0 2 3 2 1 2 2 1 1 2 3 4 1 0 2 4 3 0 3 6 1 2 2 0 1 3 1 4 3 1 1 2 4 2 1 1 0 1 1 2 4 1 1 2 3 1 6 1 0 3 2 1 2 0 2 1 3 0 1 3 1 2 0 1 2 1 3 6 1 2 0 2 7 7 2 4 1 2 0 4 1 2 1 3 0 2 0 0 3 1 2 7 3 2 2 2 0 2 9 3 1 3 3 1 3 2 3 4 3 0 1 3 2 2 0 6 1 2 2 2 0 2 3 3 2 1 2 1 4 3 3 0 2 3 4 3 7 2 2 1 2 3 3 0 0 4 1 1 2 2 4 0 3 2 1 1 2 2 1 2 0 2 3 0 1 3 2 3 0 1 2 2 1 3 1 2 0 1 1 0 0 2 3 3 4 3 0 1 3 7 0 1 3 1 3 1 1 2 2 0 0 2 1 6 4 2 1 1 3 1 1 2 1 1 2 1 0 2 2 1 3 1 1 0 1 7 4 0 3 6 2 2 4 3 2 4 0 1 3 2 0 4 4 3 0 1 3 1 4 1 1 1 2 3 1 0 2 4 1 0 2 1 3 2 2 0 2 0 0 2 4 3 4 3 1 2 2 0 3 3 4 0 3 1 2 2 4 1 1 2 1 1 1 0 3 2 0 2 1 0 2 0 2 4 2 1 2 2 2 2 1 2 3 3 0 0 1 2 2 2 4 0 1 7 2 3 2 1 0 0 2 2 6 0 1 6 2 2 0 1 2 0 2 1 2 1 2 1 3 3 4 0 0 1 1 3 2 1 1 6 2 1 2 1 0 1 1 4 1 1 1 1 4 1 3 2 6 3 6 0 0 0 2 3 1 1 6 1 1 0 2 4 2 1 3 0 4 3 3 3 4 2 2 1 1 3 0 0 1 1 3 6 0 6 1 2 1 2 4 4 0 3 1 0 1 1 1 0 1 3 0 6 3 3 2 2 4 2 1 0 1 3 4 2 4 3 1 3 2 2 0 1 2 2 2 3 0 0 2 1 4 8 3 0 2 1 3 1 3 2 1 2 3 0 2 0 0 1 2 0 1 1 3 1 3 2 2 0 6 3 2 3 1 2 1 3 1 0 0 1 0 1 0 0 3 4 2 1 4 2 1 1 2 4 1 1 0 2 1 1 0 1 0 2 2 3 1 2 4 3 1 1 1 0 4 0 0 2 1 2 2 1 2 2 2 1 1 2 1 2 0 3 1 2 1 0 0 6 6 0 1 1 1 2 1 1 1 4 2 2 0 0 3 1 0 0 2 1 1 2 0 2 1 3 1 0 6 6 1 3 3 1 2 2 2 3 3 3 2 3 1 2 1 1 2 2 2 1 2 0 3 1 1 4 0 2 0 1 2 3 3 2 6 1 3 0 2 2 3 3 2 1 2 1 2 1 0 1 1 2 1 1 6 2 1 1 2 2 0 1 0 0 2 6 1 2 0 4 4 1 1 2 1 1 2 1 2 3 0 4 2 1 0 2 0 1 0 0 1 1 0 2 2 0 1 1 1 3 1 0 1 2 0 4 0 0 0 1 3 2 4 1 2 2 1 1 2 3 3 1 1 4 2 0 1 3 0 3 0 0 1 2 0 1 2 0 2 2 3 1 0 2 2 2 1 2 1 1 2 0 4 2 0 0 2 0 4 0 2 0 0 1 6 1 0 3 1 3 4 3 3 1 3 0 0 1 3 3 2 1 2 0 0 2 1 0 1 2 3 1 2 0 2 2 0 1 3 1 0 2 1 0 1 0 0 2 2 3 1 4 1 4 1 1 2 0 0 0 3 0 1 2 3 2 3 4 3 1 3 2 0 6 3 0 4 3 2 4 2 0 1 2 3 0 2 3 2 1 0 2 2 3 1 0 3 3 4 1 2 3 1 6 6 0 0 2 2 1 4 2 1 3 0 2 3 3 1 2 1 6 3 3 2 6 3 2 1 0 0 3 0 1 2 1 0 1 2 1 1 2 2 2 3 1 1 3 3 4 4 0 1 1 3 1 1 2 0 3 0 1 0 0 4 2 2 2 6 2 0 1 0 3 2 2 3 1 1 0 0 1 2 3 1 3 0 0 1 1 2 1 1 3 1 3 0 6 6 1 6 3 1 4 0 0 4 1 2 1 4 4 7 2 2 8 1 4 2 0 2 6 0 1 3 4 1 6 1 2 4 2 2 0 6 3 6 3 6 4 4 2 4 2 3 0 0 2 1 9 1 7 3 3 4 3 8 3 4 1 3 3 7 7 1 1 1 1 3 1 1 2 3 6 6 2 4 0 2 3 4 2 3 3 1 4 1 1 3 1 6 7 4 2 8 2 6 2 3 7 1 2 1 3 6 3 4 3 7 6 4 6 2 7 3 2 6 4 6 6 6 4 12 7 9 6 13 7 7 10 4 18 16 19 19 18 9 20 14 18 14 18 13 6 4 10 4 8 7 4 2 6 1 7 7 4 4 4 2 1 4 3 3 2 4 4 4 4 3 2 2 9 3 1 1 4 6 2 1 0 6 2 4 3 6 3 2 4 4 3 4 2 2 6 3 7 9 8 4 3 3 7 3 4 3 1 2 1 7 4 3 2 1 3 0 4 2 4 3 2 2 6 1 2 1 2 3 1 6 2 4 6 3 3 8 3 2 2 2 3 2 2 3 2 4 1 1 1 2 3 2 3 3 1 1 1 1 2 2 2 3 1 3 1 2 1 2 2 1 1 1 2 3 0 3 1 2 2 1 2 1 1 1 1 7 4 0 3 0 3 2 2 2 2 2 1 0 3 1 3 1 0 0 1 2 1 1 0 3 1 3 1 2 2 1 2 2 0 2 0 3 1 1 4 3 2 1 2 3 1 0 1 0 1 0 2 2 3 0 2 2 3 1 2 2 1 2 4 1 2 1 1 4 1 1 0 1 0 4 0 7 4 1 1 2 2 0 3 0 3 1 1 2 3 0 1 2 1 1 2 1 4 2 2 0 2 1 0 1 4 2 2 2 0 1 0 2 0 2 2 1 1 0 2 2 1 1 1 0 0 2 4 2 0 1 1 2 2 1 2 4 1 1 2 4 2 2 0 4 2 3 2 0 2 0 2 1 2 1 2 3 1 2 1 2 0 3 0 1 2 1 0 0 2 0 6 1 2 2 2 1 0 4 1 0 0 0 3 0 1 2 0 4 1 1 2 1 1 1 1 2 1 2 3 0 4 0 6 1 4 2 1 1 4 0 0 2 1 2 1 2 0 3 1 2 0 1 1 0 1 1 1 0 0 1 1 0 1 1 1 1 1 1 7 1 0 3 7 4 0 2 0 0 0 0 2 1 4 1 1 1 1 1 1 1 2 0 2 1 0 3 2 1 2 0 2 2 2 0 3 1 3 2 0 3 2 1 2 4 4 1 2 0 4 1 4 1 2 1 2 6 0 2 1 1 2 2 1 1 3 4 2 1 1 1 3 2 3 1 3 2 0 2 4 0 1 1 1 1 1 0 3 3 0 4 4 3 0 0 1 1 0 2 1 1 2 1 2 2 1 2 1 0 2 1 1 4 0 1 2 1 3 1 0 1 1 0 1 2 2 6 1 1 2 1 4 0 4 0 1 1 2 0 4 1 2 1 0 1 1 0 3 2 1 2 0 1 2 2 2 2 2 1 3 2 1 0 1 3 1 0 2 2 1 3 1 4 0 1 1 2 0 1 1 6 0 1 2 2 1 1 2 2 4 3 6 1 1 1 1 1 2 0 2 1 1 2 2 2 1 2 2 3 1 0 2 0 1 0 6 0 0 1 1 2 2 1 2 1 4 1 0 3 3 0 0 0 2 1 1 1 4 4 1 0 0 2 1 2 3 1 2 1 2 3 4 1 1 1 2 1 1 3 2 1 1 2 1 1 1 3 0 1 1 1 0 0 0 1 3 0 2 1 1 1 3 0 1 4 2 2 0 1 1 0 1 4 1 1 6 3 0 2 1 2 1 2 1 2 3 0 3 1 2 1 1 3 1 6 8 4 2 0 3 1 1 2 2 2 3 2 1 1 1 0 2 2 1 2 0 0 2 0 0 1 1 1 0 2 3 1 2 0 0 2 0 2 0 3 1 0 0 2 2 4 2 2 1 1 2 0 0 1 1 0 0 0 1 0 1 2 6 2 3 2 0 1 3 0 1 2 0 1 0 1 2 2 1 1 0 2 4 1 1 1 2 2 0 1 1 4 1 1 0 3 1 0 3 3 1 1 2 2 2 2 2 1 1 0 1 0 1 1 1 4 1 2 1 1 1 2 0 0 2 0 4 2 3 0 0 2 0 1 3 2 1 0 3 1 4 3 2 2 1 0 1 1 3 1 0 2 3 2 0 1 3 1 1 2 0 0 3 2 1 3 1 1 1 3 1 1 1 2 1 4 4 2 2 2 0 3 1 1 6 2 0 3 4 2 1 1 0 2 0 1 1 1 1 2 0 3 6 2 2 3 1 1 0 2 2 2 0 3 2 1 2 0 1 2 1 2 3 4 2 1 0 3 0 0 0 2 1 0 2 4 1 1 2 1 2 1 3 3 2 1 3 1 2 1 0 2 0 2 1 0 0 2 0 0 0 2 1 4 3 3 1 1 1 3 0 2 0 1 1 1 2 0 1 1 1 0 2 1 1 2 4 1 0 2 3 2 1 1 0 3 0 1 2 1 1 0 1 2 0 2 0 4 1 1 0 2 2 0 6 2 0 1 2 0 2 2 2 0 2 2 1 4 0 0 1 2 3 3 1 2 0 1 3 2 1 2 0 1 0 1 1 1 1 1 2 1 1 1 2 1 3 2 2 1 0 0 0 3 2 1 2 2 0 1 2 2 0 0 2 2 3 1 0 4 1 3 3 1 3 3 1 0 2 3 6 1 0 2 2 2 0 0 2 2 3 1 0 1 2 0 1 2 1 1 1 2 1 6 1 1 1 3 2 2 7 2 1 1 4 4 1 2 1 2 1 2 2 0 1 0 0 1 2 2 3 0 3 2 2 1 3 0 3 2 2 6 0 0 3 1 0 1 2 1 3 1 2 0 0 2 1 0 1 1 1 1 1 1 1 0 0 1 0 3 1 3 2 1 0 2 2 2 0 1 2 1 7 0 2 1 0 3 2 0 2 0 2 3 0 1 1 0 0 2 3 2 3 0 0 0 1 0 3 1 1 1 3 2 0 0 1 3 1 3 0 2 0 0 3 2 2 0 1 1 0 6 1 1 0 3 0 3 2 0 0 0 3 1 0 2 1 1 1 0 1 2 2 2 0 2 3 0 1 2 3 1 0 2 2 0 1 4 1 1 3 1 0 2 1 3 0 3 0 0 1 0 1 0 4 3 1 2 2 3 2 3 1 3 2 1 3 1 0 1 0 2 2 2 0 1 0 3 3 1 2 1 2 0 2 1 0 0 2 1 1 0 0 0 1 2 2 0 0 0 0 0 1 6 2 2 0 1 4 1 1 3 2 2 0 2 2 1 3 1 2 1 1 3 2 2 2 4 2 4 0 0 1 1 3 2 1 2 2 4 2 0 2 1 0 0 2 1 1 3 2 1 3 2 2 1 3 1 1 1 1 0 1 2 1 2 1 2 2 6 2 2 2 1 1 1 4 1 0 0 1 3 3 2 2 2 4 4 2 1 1 1 1 1 3 2 2 2 1 2 1 3 2 1 1 2 1 1 0 2 1 2 1 3 2 4 3 2 1 1 4 2 1 2 2 7 2 1 3 2 1 7 0 2 2 2 4 2 2 2 1 1 1 3 3 1 2 0 2 1 4 0 6 0 2 1 2 2 2 1 2 2 1 1 1 3 3 2 2 2 0 3 4 0 0 1 1 7 0 0 6 3 0 0 0 1 1 2 0 3 2 2 0 1 1 2 1 4 2 1 2 1 2 2 1 0 2 1 0 3 2 3 2 0 0 1 4 2 2 4 2 2 2</intensities>
			</dataPoints>
		</scan>
	</xrdMeasurement>
</xrdMeasurements>