File: Roentgen/Messdaten/Si111_40_30.xrdml
<?xml version="1.0" encoding="UTF-8"?>
<xrdMeasurements xmlns="http://www.xrdml.com/XRDMeasurement/1.3" xmlns:xsi="http://www.w3.org/2001/XMLSchema-instance" xsi:schemaLocation="http://www.xrdml.com/XRDMeasurement/1.3 http://www.xrdml.com/XRDMeasurement/1.3/XRDMeasurement.xsd" status="Completed">
	<comment>
		<entry>huhuu</entry>
		<entry>Configuration=stage XYZ Phi Psi, Owner=User-1, Creation date=17.03.2006 13:32:17</entry>
		<entry>Goniometer=PW3050/60 (Theta/Theta); Minimum step size 2Theta:0.001; Minimum step size Omega:0.001</entry>
		<entry>Sample stage=IR Stage (Phi, Tilt, X, Y, Z)</entry>
		<entry>Diffractometer system=XPERT-PRO</entry>
		<entry>Measurement program=FP, Owner=User-1, Creation date=18.04.2011 15:14:00</entry>
	</comment>
	<sample type="To be analyzed">
		<id></id>
		<name></name>
		<preparedBy></preparedBy>
	</sample>
	<xrdMeasurement measurementType="Scan" status="Completed" sampleMode="Reflection">
		<comment>
			<entry/>
		</comment>
		<usedWavelength intended="K-Alpha 1">
			<kAlpha1 unit="Angstrom">1.5405980</kAlpha1>
			<kAlpha2 unit="Angstrom">1.5444260</kAlpha2>
			<kBeta unit="Angstrom">1.3922500</kBeta>
			<ratioKAlpha2KAlpha1>0.5000</ratioKAlpha2KAlpha1>
		</usedWavelength>
		<incidentBeamPath>
			<radius unit="mm">240.00</radius>
			<xRayTube id="1010041" name="PW3373/00 Cu LFF DK369848">
				<tension unit="kV">40</tension>
				<current unit="mA">30</current>
				<anodeMaterial>Cu</anodeMaterial>
				<focus type="Line">
					<length unit="mm">12.0</length>
					<width unit="mm">0.4</width>
					<takeOffAngle unit="deg">6.0</takeOffAngle>
				</focus>
			</xRayTube>
			<sollerSlit id="21010002" name="Soller 0.04 rad.">
				<opening unit="rad">0.0400</opening>
			</sollerSlit>
			<mask id="22080002" name="Inc. Mask Fixed  10 mm (MPD/MRD)">
				<distanceToSample unit="mm">101.00</distanceToSample>
				<width unit="mm">6.60</width>
			</mask>
			<divergenceSlit id="22010012" name="Prog. Div. Slit" xsi:type="fixedDivergenceSlitType">
				<distanceToSample unit="mm">140.00</distanceToSample>
				<angle unit="deg">0.25</angle>
			</divergenceSlit>
		</incidentBeamPath>
		<sampleOffset>
			<position axis="2Theta" unit="deg">0.012</position>
			<position axis="Omega" unit="deg">0.012</position>
		</sampleOffset>
		<diffractedBeamPath>
			<radius unit="mm">240.00</radius>
			<antiScatterSlit id="22060009" name="Prog. AS Slit" xsi:type="automaticAntiScatterSlitType">
				<observedLength unit="mm">0.5</observedLength>
				<offset unit="mm">0.00</offset>
			</antiScatterSlit>
			<detector id="7010012" name="X'Celerator Scientific" xsi:type="rtmsDetectorType">
				<phd>
					<lowerLevel unit="%">45.0</lowerLevel>
					<upperLevel unit="%">80.5</upperLevel>
				</phd>
				<mode>Scanning</mode>
				<activeLength unit="deg">2.122</activeLength>
			</detector>
		</diffractedBeamPath>
		<scan appendNumber="0" mode="Continuous" scanAxis="Gonio" status="Completed">
			<header>
				<startTimeStamp>2015-09-03T11:17:53+02:00</startTimeStamp>
				<endTimeStamp>2015-09-03T11:29:42+02:00</endTimeStamp>
				<author>
					<name>Daniel</name>
				</author>
				<source>
					<applicationSoftware version="2.2">X'Pert Data Collector</applicationSoftware>
					<instrumentControlSoftware version="1.7 ">XPERT-PRO</instrumentControlSoftware>
					<instrumentID>0000000000000819</instrumentID>
				</source>
			</header>
			<dataPoints>
				<positions axis="2Theta" unit="deg">
					<startPosition>15.00108891</startPosition>
					<endPosition>129.99550932</endPosition>
				</positions>
				<positions axis="Omega" unit="deg">
					<startPosition>7.50054446</startPosition>
					<endPosition>64.99775466</endPosition>
				</positions>
				<commonCountingTime unit="seconds">3.175</commonCountingTime>
				<intensities 29 31 35 19 25 24 31 35 18 29 32 15 19 24 29 29 32 30 26 13 32 23 24 20 15 24 26 30 18 25 32 23 30 29 29 29 24 29 15 29 30 35 37 23 19 27 27 31 24 16 12 26 16 33 27 23 24 20 20 26 30 25 40 29 37 30 36 24 30 24 23 25 38 32 19 27 31 23 26 18 37 31 20 33 27 33 41 21 35 30 43 24 27 33 29 33 29 27 27 14 29 35 33 38 32 25 42 30 20 27 33 36 35 29 25 29 32 40 29 24 20 36 27 37 42 29 30 18 41 26 25 24 30 27 30 26 36 35 35 23 31 26 53 37 38 33 36 33 21 26 32 35 19 32 36 33 14 33 40 46 32 25 50 30 32 36 40 32 32 31 20 29 31 29 27 33 29 38 32 27 40 41 20 44 30 43 40 38 33 26 25 32 26 29 25 42 36 40 19 49 42 37 33 26 30 38 24 29 26 38 32 33 38 21 29 30 33 20 37 31 44 27 37 44 32 44 37 35 36 38 41 38 44 44 23 31 41 38 33 37 31 41 26 42 50 35 35 38 32 49 41 42 36 30 43 35 37 36 27 29 35 30 50 41 40 38 32 44 41 48 48 53 38 46 30 38 38 31 38 41 38 50 46 43 43 40 29 61 44 26 48 38 35 37 38 50 40 33 37 40 46 53 46 42 29 46 49 43 40 46 36 43 40 65 38 49 33 40 58 42 46 48 44 43 46 43 50 52 48 44 47 43 41 35 52 49 52 52 44 50 50 56 48 53 44 38 41 46 58 41 33 41 50 46 50 61 47 35 44 35 38 52 63 38 48 40 60 47 58 44 49 44 47 54 47 46 43 60 47 56 54 54 58 38 54 59 61 64 53 43 65 43 42 54 55 58 50 54 70 75 61 43 67 52 65 38 55 55 58 64 48 41 53 58 52 49 65 59 49 58 72 76 52 50 44 50 73 44 49 56 46 60 59 59 60 73 69 69 75 48 64 70 63 58 60 61 66 48 75 50 65 59 54 53 67 67 69 64 70 83 71 77 65 76 67 72 70 50 61 50 63 71 69 70 66 54 58 77 66 69 65 56 72 72 75 43 52 71 63 64 66 65 71 65 67 93 55 82 69 71 70 84 70 67 61 65 70 60 73 78 73 76 71 67 75 96 75 75 61 73 82 72 65 77 80 76 70 58 80 80 72 69 89 75 72 96 109 116 106 92 72 75 92 80 70 94 76 81 82 92 96 94 84 86 89 92 71 72 87 61 84 78 86 86 90 87 77 70 64 87 88 84 86 76 80 95 73 84 73 81 70 84 100 82 83 84 81 86 87 88 89 73 81 101 82 83 77 84 87 82 72 98 89 81 75 88 100 107 87 113 78 103 103 106 101 149 175 210 183 210 149 96 95 104 104 103 93 75 78 66 76 88 72 99 64 77 84 86 92 80 70 73 83 96 72 76 76 92 87 89 86 77 77 86 89 70 80 88 93 77 81 88 69 75 92 84 88 87 66 99 106 82 83 77 78 83 77 69 83 89 72 88 76 69 75 82 100 72 81 80 90 88 93 100 89 81 89 76 89 90 89 100 96 109 94 78 84 94 87 84 80 84 77 72 88 77 98 65 96 84 81 83 88 94 65 90 99 98 89 92 83 103 92 99 70 75 64 80 63 70 61 82 78 88 82 77 67 83 87 95 90 96 95 82 86 71 86 90 84 88 94 101 66 82 70 78 84 87 81 101 101 82 84 80 89 93 99 92 93 90 86 86 83 84 89 72 95 77 83 88 89 75 83 78 84 87 70 89 77 77 65 87 78 88 89 84 84 82 86 47 76 83 77 76 72 60 72 72 82 58 81 88 73 86 80 78 75 75 88 83 80 87 67 86 73 84 90 89 67 76 66 77 78 77 71 64 86 73 83 59 64 82 99 83 81 72 90 86 78 71 76 81 84 87 76 73 83 100 59 95 78 88 75 86 81 80 82 110 103 80 81 98 86 77 92 76 72 70 87 84 81 71 73 72 84 86 72 84 84 67 70 83 84 87 82 71 103 80 93 77 76 80 81 67 80 83 60 72 98 82 69 81 87 77 81 93 104 93 88 111 104 96 93 121 103 81 113 134 140 140 210 277 321 372 313 298 202 186 155 140 120 112 93 80 76 80 86 66 90 89 77 67 95 86 81 76 76 73 90 87 80 71 83 80 96 87 82 87 99 93 124 175 151 174 167 129 139 112 94 93 89 88 66 76 80 70 83 93 67 78 76 83 76 93 92 82 87 99 88 103 87 106 99 89 95 106 98 126 118 112 124 167 219 306 492 741 834 777 644 423 231 180 130 111 110 88 82 73 87 81 70 78 100 98 103 100 87 99 95 75 81 70 82 81 67 72 73 80 80 78 71 93 60 80 93 73 100 118 96 136 130 145 117 132 101 106 73 63 72 78 82 69 67 81 90 66 69 98 58 77 59 71 87 71 60 67 66 67 69 56 53 67 72 58 53 54 59 65 65 55 70 58 69 54 75 63 67 71 59 60 54 56 59 65 59 64 59 66 53 61 55 55 67 66 66 54 64 75 64 66 59 60 52 60 80 48 49 61 67 61 70 52 59 63 59 50 60 70 70 63 61 56 83 75 67 47 59 55 56 49 49 48 41 53 56 52 58 50 65 53 60 59 60 64 58 59 56 75 66 71 65 67 70 54 56 46 63 60 56 56 58 54 36 54 52 56 53 56 54 50 65 67 72 59 58 53 54 61 58 78 56 65 59 60 65 58 52 63 54 52 72 60 84 75 73 63 82 86 89 90 100 127 113 157 181 230 368 460 547 561 573 447 402 407 457 429 500 448 447 459 455 568 600 666 715 760 984 1449 2076 3509 6474 11449 16703 19818 19307 15834 10170 5959 3583 2441 1745 1411 1150 954 804 675 677 681 585 535 540 467 452 415 408 360 368 366 391 321 335 306 310 317 264 283 312 265 297 289 281 287 304 300 293 293 282 303 260 288 280 264 259 271 263 219 266 261 236 241 259 270 260 236 259 265 255 264 267 254 267 265 255 220 230 226 235 231 220 209 231 204 218 241 216 213 202 210 192 191 204 192 221 185 203 221 192 214 195 209 192 173 203 172 200 210 209 198 183 175 193 166 189 164 189 167 189 184 155 179 191 198 175 183 183 169 186 184 169 179 160 184 161 158 170 181 163 149 170 156 176 175 195 147 166 198 174 190 184 179 185 185 163 169 167 153 162 153 145 192 189 180 178 163 180 200 192 151 179 212 157 164 175 186 213 203 226 246 216 247 240 230 233 235 318 305 362 433 499 797 1167 1567 1734 1756 1274 912 642 506 366 294 263 267 254 202 197 206 192 181 235 191 198 231 224 203 219 276 328 358 370 329 276 264 237 204 170 191 169 169 186 169 161 178 181 180 176 186 147 170 193 164 143 167 172 189 162 184 155 184 192 170 164 166 166 174 162 168 166 152 173 190 208 186 167 184 197 156 198 169 178 187 175 190 191 164 158 204 207 220 185 221 212 235 218 202 230 216 201 195 212 203 241 260 229 241 238 249 250 267 259 273 264 255 305 273 306 311 352 367 362 387 419 404 454 507 562 627 830 997 1289 1566 1865 2042 2197 2231 2379 2474 2430 2659 3053 3441 4058 5210 7165 11443 20643 29915 33556 34950 34842 31804 24253 15835 13491 17877 24461 28385 29610 28278 22369 13297 6856 4337 3031 2496 1839 1509 1235 1083 1021 958 806 749 692 638 620 585 516 511 438 443 430 418 379 400 383 363 329 303 347 320 315 292 322 267 303 305 263 295 283 275 272 226 242 253 232 212 233 237 242 190 207 218 207 221 207 200 202 212 178 223 180 190 176 160 193 170 197 164 176 186 174 174 167 163 152 162 161 155 153 138 143 135 149 170 141 144 144 152 149 149 164 153 151 160 158 164 135 151 126 145 132 146 140 134 132 161 135 138 135 138 153 126 117 127 129 115 107 126 149 123 134 117 138 116 134 116 99 127 127 109 92 120 129 133 105 120 122 129 126 103 109 113 94 106 111 128 120 116 115 112 118 100 98 104 111 90 105 100 126 110 89 105 117 103 96 109 98 109 103 107 111 127 100 89 109 115 99 110 93 76 100 117 96 100 92 100 127 101 104 111 101 92 95 94 101 95 88 103 93 78 101 87 84 107 71 95 106 73 87 92 115 96 105 95 98 105 96 81 105 92 112 99 96 95 93 87 88 101 80 89 100 76 86 98 75 86 81 86 106 118 89 73 75 83 95 90 83 94 70 100 104 105 99 98 103 103 88 93 83 83 84 90 87 99 104 95 77 70 86 81 105 67 101 88 109 104 82 83 96 71 83 99 77 73 100 94 64 106 95 98 93 73 82 80 98 100 100 89 100 90 121 107 80 99 84 80 72 58 86 67 82 78 70 89 71 80 58 65 71 82 77 54 72 75 81 70 70 64 67 63 67 94 60 64 66 63 75 72 63 65 60 69 42 67 73 66 75 72 69 67 75 55 66 87 81 67 80 58 72 73 69 78 56 70 76 59 63 73 65 58 52 64 67 61 77 69 56 67 55 54 65 67 53 70 52 71 48 81 40 56 58 59 69 69 65 55 52 54 55 65 47 48 65 64 56 56 58 53 55 64 53 78 56 61 63 47 43 69 48 67 61 60 50 59 48 44 67 55 53 54 46 52 49 50 69 41 42 52 50 60 49 58 49 53 46 44 50 54 55 70 64 41 50 48 43 46 53 58 49 70 54 65 50 50 48 43 44 65 54 65 52 47 64 55 42 52 63 59 65 58 48 49 69 40 59 49 66 55 59 59 58 49 42 61 65 59 47 43 63 55 36 47 47 61 43 49 44 48 49 59 33 48 35 58 41 32 42 43 48 40 31 47 53 52 40 49 55 50 50 41 46 42 52 50 55 52 40 60 55 52 47 41 44 47 46 53 48 44 65 35 42 48 24 50 48 37 48 41 38 50 38 58 40 53 54 53 32 52 38 46 43 35 56 42 43 54 31 41 40 33 52 46 40 40 42 33 50 46 46 46 33 37 41 47 35 41 37 37 31 40 37 50 49 32 38 32 41 40 30 35 32 35 54 37 47 35 37 37 41 40 25 35 31 44 44 31 29 32 46 43 30 41 30 35 35 26 44 32 40 42 40 26 35 27 26 40 31 43 29 37 36 30 31 32 48 30 31 29 37 41 38 19 37 46 35 30 29 35 23 33 35 36 15 29 20 31 26 32 27 29 21 21 37 29 23 37 29 29 24 29 31 29 32 36 33 44 35 30 23 33 16 33 32 27 21 30 37 24 47 24 24 27 42 26 23 25 21 37 24 30 38 21 30 27 27 23 27 20 31 21 32 40 19 30 30 25 32 31 27 35 25 36 33 30 12 23 27 25 21 35 16 24 29 23 24 31 27 23 23 26 27 23 21 29 21 23 35 33 27 20 27 20 20 24 23 27 18 15 30 24 29 24 25 26 24 35 19 18 26 23 25 16 31 33 15 26 24 29 18 18 20 18 29 19 25 27 25 25 33 14 19 20 31 26 23 19 10 24 26 23 20 27 23 24 25 26 23 27 26 26 23 25 31 19 26 24 13 27 35 20 24 19 20 19 23 19 15 19 21 15 13 20 27 20 29 32 12 25 16 23 19 19 25 29 20 24 14 23 19 24 15 14 19 19 24 16 26 23 15 19 18 16 18 13 19 38 24 37 33 23 25 16 18 23 20 36 21 16 25 15 18 20 24 18 16 25 23 19 14 15 13 13 23 13 16 12 14 19 14 16 9 12 12 15 20 13 21 23 21 18 20 18 21 9 13 21 16 13 15 12 12 15 13 20 16 13 10 15 18 19 13 16 7 20 12 14 14 8 12 19 13 15 18 18 6 15 9 13 15 10 19 15 9 13 12 15 14 15 16 13 18 15 12 10 15 9 7 13 16 8 8 4 15 14 14 12 12 13 19 16 9 14 18 9 14 15 16 10 13 15 15 6 19 4 10 15 8 10 18 10 15 10 9 10 13 12 4 8 10 9 7 9 13 13 15 12 15 14 16 12 10 13 16 8 12 14 13 6 16 7 14 8 6 3 9 9 18 12 15 12 14 8 15 14 14 4 13 4 6 12 15 12 6 18 10 10 10 15 12 14 9 8 10 10 6 15 6 9 13 8 3 10 4 9 15 9 9 15 9 13 12 9 6 8 8 6 4 10 9 4 12 10 4 13 18 13 7 7 3 7 8 10 9 12 14 9 10 10 19 10 6 14 10 9 7 9 10 9 13 9 6 9 9 7 9 6 14 8 8 10 10 9 9 6 8 8 6 19 4 8 10 9 10 8 14 14 14 9 8 8 6 6 14 7 10 9 12 9 10 8 7 14 8 8 7 18 1 2 10 2 9 3 3 7 7 10 8 6 9 12 8 7 6 7 7 8 8 6 8 4 3 7 7 2 7 7 3 14 4 12 9 12 7 4 8 9 4 15 4 9 6 10 3 4 7 6 1 6 3 4 2 13 7 6 12 6 8 8 9 9 7 6 7 4 9 14 12 9 9 9 14 8 6 9 9 9 10 16 33 23 21 8 8 14 12 12 16 14 15 9 15 8 4 12 7 6 9 4 7 6 9 2 4 4 8 8 8 4 6 7 10 6 2 9 4 0 3 4 7 3 6 4 8 7 3 4 8 6 6 2 3 3 4 1 6 6 7 6 3 4 3 4 8 4 9 4 6 4 4 1 8 3 6 4 7 7 2 3 4 4 3 1 6 9 1 7 7 4 7 3 3 8 8 2 6 8 4 4 4 7 3 2 6 6 2 6 3 3 7 1 0 6 2 2 6 7 4 3 4 6 7 4 2 0 2 6 6 2 8 6 3 3 2 7 6 6 7 6 2 3 2 2 2 2 4 3 2 8 3 3 8 3 4 7 2 2 1 2 6 2 4 4 4 3 2 2 0 4 4 6 7 1 1 1 6 1 4 6 1 4 6 4 2 6 4 7 2 4 2 4 3 3 7 4 2 2 2 6 2 3 3 8 1 1 2 2 2 3 7 2 7 3 4 2 3 4 6 3 2 7 4 3 6 0 3 4 2 4 4 1 3 4 2 2 2 1 4 7 2 3 0 2 3 3 3 4 3 6 2 2 1 4 6 7 1 1 2 2 7 2 3 0 4 9 3 6 2 3 1 2 4 2 4 2 3 3 6 0 1 2 2 2 4 1 7 1 6 3 4 7 3 2 4 2 4 3 4 10 3 3 4 4 4 9 1 0 1 6 6 2 1 2 4 3 7 1 2 2 7 9 2 4 3 4 6 4 3 4 4 3 0 4 3 4 8 4 2 2 6 3 2 1 3 1 1 2 2 0 6 3 1 0 3 6 2 6 2 3 2 4 1 2 4 7 2 1 3 2 3 2 0 0 2 4 2 6 6 4 3 3 3 2 7 3 1 1 4 2 1 2 2 6 4 1 4 2 2 3 1 7 2 7 6 1 3 4 3 1 2 4 2 1 2 1 0 0 3 0 3 2 1 1 2 0 2 1 3 3 3 4 4 1 3 1 10 1 4 3 2 3 1 2 3 3 2 1 1 4 1 2 3 1 0 1 0 4 2 4 0 6 1 1 0 4 7 4 1 2 2 3 1 2 7 4 3 4 4 2 1 4 4 2 3 1 1 1 2 4 4 2 4 1 1 2 7 6 8 2 10 2 2 0 2 3 2 2 1 3 2 2 2 4 3 3 2 1 1 6 6 3 9 7 1 2 1 3 3 4 3 0 3 7 6 0 3 2 1 2 2 3 3 0 6 6 2 2 4 2 3 2 1 0 0 2 0 2 1 1 1 0 4 6 2 2 0 4 2 4 6 3 3 3 2 1 2 6 2 1 1 2 0 2 1 1 4 3 6 1 2 3 3 2 1 6 1 1 4 0 4 2 1 4 1 3 0 1 2 2 3 4 6 3 3 1 1 1 0 3 1 2 4 0 7 0 1 1 1 2 2 1 3 2 1 2 4 4 2 1 1 0 0 2 1 2 3 0 4 1 0 4 3 4 4 1 4 3 3 3 1 1 3 1 2 4 3 3 3 2 2 0 2 2 1 3 0 4 1 3 6 2 2 2 0 2 4 1 1 1 2 3 2 2 4 0 3 1 3 2 1 4 0 2 3 2 0 1 1 0 1 3 1 4 6 0 3 2 4 2 4 3 6 1 2 2 9 1 6 2 0 2 3 3 2 1 0 1 1 1 4 9 2 6 2 4 1 1 1 1 2 1 4 2 1 2 2 2 0 1 0 1 2 1 3 9 1 2 4 2 4 1 2 1 7 3 1 0 2 2 1 3 1 1 1 6 1 3 4 3 2 1 2 2 1 0 3 4 2 2 0 2 0 1 2 2 2 2 1 3 3 2 2 2 2 2 1 2 1 2 3 2 2 1 0 3 1 2 0 2 0 4 0 8 2 2 1 1 0 1 4 1 2 2 1 1 2 1 1 1 0 1 6 0 3 2 2 1 6 3 1 4 6 4 4 2 2 3 7 2 2 2 1 2 2 3 0 2 2 2 2 4 2 1 3 0 2 1 4 3 0 3 3 2 3 2 2 6 3 2 6 6 0 2 1 3 2 2 2 0 1 0 2 2 1 3 3 4 4 3 2 2 4 2 1 4 2 4 2 2 1 4 1 1 2 2 3 6 2 1 1 0 6 3 2 1 1 3 2 2 4 2 4 3 1 1 6 2 3 2 1 1 1 1 1 1 0 1 0 2 0 6 0 3 2 1 2 2 3 3 3 2 3 0 2 2 2 3 2 1 2 2 2 6 4 3 3 1 2 1 7 0 1 6 0 2 1 2 3 3 7 7 4 2 4 4 2 2 2 6 2 1 1 1 2 2 1 4 3 1 3 2 0 4 2 2 0 0 2 2 1 6 1 3 1 2 2 2 3 1 3 2 2 2 2 2 3 2 6 4 0 1 4 6 2 1 1 4 4 0 3 2 4 1 2 3 2 4 6 4 3 3 3 2 2 1 2 2 3 1 3 2 7 1 2 2 3 7 2 3 7 2 0 1 1 1 1 0 6 2 3 2 1 1 4 1 0 0 1 1 2 3 4 3 3 0 0 0 0 2 2 3 2 0 0 2 2 1 2 2 1 3 1 1 2 2 0 2 1 1 2 0 6 1 6 1 3 2 2 3 2 0 1 3 3 2 1 3 1 3 2 1 1 2 1 2 1 4 3 1 0 3 3 2 2 2 3 1 2 2 2 2 3 1 2 0 2 3 3 6 3 1 3 1 4 6 2 2 7 3 6 4 1 1 0 3 2 1 2 1 3 0 2 1 0 2 2 3 2 2 3 3 6 3 4 0 2 4 4 2 2 3 3 3 0 1 1 4 1 0 6 4 4 2 1 3 2 1 3 0 2 1 3 1 3 0 2 3 3 6 0 0 4 2 7 1 2 0 8 2 6 1 3 3 4 0 3 0 2 1 0 1 4 1 1 3 1 1 1 3 0 0 2 1 2 3 0 1 4 4 3 0 3 3 2 0 1 4 0 4 2 2 2 0 2 3 2 2 3 3 1 2 4 3 6 2 3 1 1 2 3 1 3 1 4 1 1 3 1 3 1 0 1 3 4 3 4 1 6 2 2 2 1 4 2 3 4 1 2 3 2 1 4 2 2 7 1 6 3 2 3 4 1 3 3 2 0 2 1 3 1 3 1 1 1 1 1 0 1 3 4 3 4 1 2 3 1 6 3 0 1 4 0 4 3 1 3 2 3 3 1 4 2 1 1 6 2 1 2 2 2 3 3 1 1 4 0 1 0 7 2 1 3 4 2 3 4 3 3 1 2 3 7 6 6 3 1 3 2 4 1 4 4 0 3 1 8 1 4 3 2 6 2 3 2 4 1 3 2 1 2 1 7 2 0 2 2 0 1 1 2 1 2 2 4 3 4 1 4 1 2 1 4 2 1 3 2 4 1 2 6 4 4 1 3 0 7 0 2 2 1 2 7 2 4 4 1 3 3 2 2 6 2 3 4 3 2 3 2 1 0 6 1 3 1 3 2 7 6 2 1 6 1 2 0 2 4 3 2 1 7 1 3 0 0 3 2 3 1 1 9 7 4 6 2 7 3 3 4 3 1 1 2 2 1 3 3 6 3 0 2 3 1 3 2 3 4 7 1 2 3 3 3 2 4 4 3 7 4 3 2 2 3 1 7 6 9 9 8 13 24 29 42 26 46 41 25 19 19 12 8 8 8 4 3 2 8 1 8 3 2 4 4 3 4 6 1 4 1 4 3 3 4 3 2 1 3 2 4 4 3 6 3 4 1 7 3 6 2 2 6 4 3 7 2 3 3 3 10 3 3 2 4 6 6 1 3 0 3 3 1 2 3 1 0 3 9 4 3 0 7 3 2 2 1 4 4 2 2 1 3 4 3 1 4 0 3 0 2 3 2 2 0 3 3 1 1 6 2 6 3 6 2 3 1 1 6 2 2 2 1 3 2 3 7 6 2 0 6 4 3 3 2 1 3 2 2 2 2 2 2 1 2 4 3 1 3 2 4 2 2 3 1 6 6 0 2 2 2 3 2 0 3 2 2 2 1 2 1 4 2 6 1 6 7 6 4 0 6 1 2 0 2 4 1 3 3 2 4 4 3 3 2 4 0 1 6 0 3 3 0 4 4 3 0 3 2 1 7 2 3 0 2 1 2 2 2 2 0 3 1 1 2 3 4 4 2 2 4 3 1 3 7 6 2 1 2 3 7 3 7 2 3 3 4 3 2 0 1 6 4 2 2 0 4 6 3 2 4 2 3 2 0 3 6 0 2 2 1 1 4 1 8 6 1 4 0 3 2 1 3 9 3 2 4 7 7 7 9 4 4 3 1 0 7 1 2 0 3 8 1 6 6 1 0 3 3 6 1 7 1 4 3 6 2 6 6 0 7 0 1 3 3 3 0 7 2 4 3 2 3 7 1 3 4 1 4 3 0 1 2 3 2 4 6 4 3 3 3 3 3 2 4 3 4 2 2 1 3 3 1 3 2 6 3 6 6 4 2 3 6 3 3 2 2 6 3 1 2 7 6 2 1 1 2 3 2 1 3 4 6 4 1 6 1 1 3 2 3 2 2 4 0 2 1 3 0 1 3 1 2 1 3 3 3 4 4 4 4 3 6 8 1 6 4 6 3 6 2 2 3 6 1 2 1 6 3 0 4 4 3 1 2 4 1 2 3 1 3 4 3 0 8 6 4 2 3 4 1 2 1 1 3 3 9 1 6 1 2 2 2 1 6 1 7 3 4 3 4 2 7 1 3 7 4 1 1 3 6 3 4 7 3 3 4 6 3 4 6 1 4 1 2 2 2 1 4 2 6 2 2 4 3 1 3 2 2 4 4 2 0 2 3 3 2 3 6 6 6 1 0 2 4 7 4 2 1 8 4 6 6 3 2 2 4 4 1 3 3 0 1 1 6 3 4 3 3 4 1 3 4 3 4 3 3 1 9 3 4 3 6 3 7 4 2 2 1 1 6 6 8 4 4 2 2 0 6 3 7 6 3 3 4 0 1 1 3 2 3 6 4 3 3 2 2 6 3 4 3 6 2 7 1 12 3 2 4 8 3 3 0 3 6 3 2 1 3 4 3 1 6 4 1 4 4 6 8 7 3 4 6 1 3 6 3 4 1 7 2 1 2 4 4 3 6 3 4 7 8 6 2 3 6 3 4 7 4 2 2 3 4 6 4 4 1 7 3 3 8 2 3 3 2 4 7 3 8 13 6 4 3 7 4 4 7 2 3 1 6 1 4 8 7 3 7 3 6 2 8 2 9 7 6 2 8 4 4 3 8 3 7 8 6 10 7 12 10 7 4 6 12 14 23 30 38 61 100 138 166 138 110 98 55 33 13 21 18 9 10 18 15 15 15 20 40 42 70 75 92 60 42 36 19 24 7 14 10 3 3 2 3 7 4 3 9 4 8 9 7 4 4 3 4 2 3 4 3 3 3 1 4 6 4 4 8 0 7 7 3 7 1 3 1 6 2 2 2 7 2 8 10 7 8 2 6 4 2 4 7 3 6 3 4 3 1 9 3 4 4 4 3 10 2 7 0 7 2 2 3 3 6 1 2 3 3 1 3 2 6 4 2 3 6 4 2 2 8 10 2 6 2 4 4 6 3 4 4 4 4 4 6 4 8 1 2 6 4 3 9 1 3 4 4 8 8 8 2 2 3 2 2 3 1 3 4 4 4 2 3 2 7 1 3 2 2 7 6 2 1 0 6 3 4 4 9 3 0 3 6 4 7 4 3 4 3 6 4 6 8 7 3 0 4 3 2 4 2 8 3 7 7 2 4 8 6 6 3 7 6 3 6 6 3 1 2 3 2 3 4 3 2 7 1 3 2 2 1 6 6 3 6 2 4 3 8 7 2 4 4 6 2 3 7 3 9 4 4 8 4 6 3 4 6 2 2 6 2 6 7 6 8 7 4 0 2 6 12 8 10 2 8 6 6 2 9 6 3 7 4 1 7 3 3 1 3 8 7 2 3 0 7 8 3 9 3 4 2 6 6 3 10 10 4 2 6 8 7 4 7 3 0 3 8 9 8 10 8 2 3 0 4 1 2 3 6 3 4 6 2 2 1 9 4 7 2 2 6 7 4 2 2 8 8 1 3 1 3 3 6 3 2 3 4 9 8 6 6 12 3 6 4 2 4 0 4 4 3 6 1 2 3 6 4 7 6 4 3 3 3 6 6 4 2 4 1 4 2 2 3 9 6 6 7 6 1 1 1 3 4 4 3 4 2 9 7 1 2 6 4 4 6 3 7 2 2 12 3 7 4 2 7 2 4 3 6 4 2 2 2 6 3 7 3 4 3 2 6 4 6 7 8 4 6 6 3 6 1 9 1 3 4 1 2 3 1 2 3 2 1 3 8 2 3 7 6 9 3 7 4 8 7 7 4 6 6 8 9 6 2 2 4 3 7 4 3 4 4 2 8 3 2 2 3 4 2 4 4 7 6 6 3 2 7 6 4 3 3 9 6 6 4 3 9 3 9 6 3 4 6 3 1 2 6 7 3 6 4 7 7 9 6 6 10 12 7 4 3 4 7 8 10 15 16 10 14 9 9 10 9 7 4 8 9 8 9 2 6 6 8 6 3 7 4 4 3 1 2 1 2 3 2 6 7 6 7 4 6 6 8 4 4 7 1 8 1 3 0 9 9 6 3 1 7 0 4 4 3 8 1 4 4 6 2 6 4 7 10 4 3 4 4 2 2 7 7 4 6 4 3 1 7 7 1 7 4 7 3 2 9 2 9 8 4 6 6 4 7 7 2 2 1 8 4 4 4 6 1 4 4 4 6 3 3 2 4 6 2 4 4 3 6 1 2 2 3 2 3 3 2 2 10 1 7 10 8 6 7 7 4 10 8 4 12 7 6 2 2 10 1 6 1 6 2 2 8 3 6 2 3 4 4 8 6 6 7 8 3 6 8 2 8 1 7 3 1 6 6 6 2 7 3 7 1 3 3 9 4 6 3 6 4 4 2 4 1 1 3 3 2 9 1 6 1 4 3 6 6 3 3 4 6 1 4 4 2 4 2 6 12 8 9 2 8 6 7 4 4 1 4 3 2 4 6 2 3 6 3 7 6 7 4 3 6 6 6 6 9 6 1 7 2 7 4 3 7 6 3 2 3 3 4 2 4 4 7 3 10 3 3 2 3 2 4 2 4 2 3 6 8 4 9 4 2 4 8 6 12 6 3 2 4 4 4 4 6 2 2 6 1 2 1 8 3 4 4 6 2 0 3 1 4 3 8 6 4 2 3 6 3 4 4 3 3 2 3 7 3 6 6 3 3 6 8 4 2 4 4 6 2 2 0 4 1 4 2 7 6 6 4 2 6 1 3 3 3 6 3 9 7 7 1 7 4 10 1 1 4 6 3 4 1 3 6 4 8 0 6 3 3 7 3 4 3 6 7 2 7 2 4 2 1 2 7 10 1 3 3 6 3 3 4 9 2 1 6 4 6 15 7 4 6 6 4 3 2 6 7 3 4 4 7 6 4 2 6 6 7 6 8 3 3 3 7 2 1 2 6 3 2 1 4 4 2 2 2 8 12 2 7 6 4 3 6 2 3 6 3 6 7 3 8 2 7 2 3 2 2 3 3 2 8 4 6 7 1 3 0 2 6 4 2 6 8 3 7 7 3 4 6 7 4 1 2 6 1 2 3 4 4 4 4 3 4 6 1 3 2 9 4 6 1 6 1 4 3 6 7 2 7 3 6 2 8 1 4 2 3 4 4 6 3 3 2 4 6 3 3 4 2 1 2 6 9 7 10 8 2 2 6 3 8 4 4 4 7 6 6 1 2 1 4 0 4 6 4 4 7 2 3 9 6 1 4 7 4 6 7 0 4 3 9 2 6 2 4 3 3 2 3 3 7 1 4 6 6 7 7 3 4 2 7 13 4 4 2 4 7 9 2 4 3 4 6 2 6 8 9 7 2 4 3 3 2 3 3 6 3 4 3 3 4 3 3 3 4 4 6 3 6 7 7 1 1 4 4 4 0 1 3 4 8 6 10 4 3 9 3 3 2 7 1 3 4 6 1 2 4 3 0 2 2 8 6 2 1 1 3 4 10 1 4 4 6 4 7 2 7 6 10 4 0 1 4 3 2 3 4 4 2 2 3 4 1 3 3 2 9 7 8 6 6 6 7 4 6 2 8 2 2 2 3 7 4 3 2 6 6 3 10 2 6 1 1 7 2 6 1 7 6 4 2 7 3 3 4 8 3 3 2 7 3 3 6 0 2 7 4 3 3 4 1 10 2 6 3 4 3 4 4 3 2 4 3 4 1 6 4 0 6 2 3 2 2 7 3 3 4 3 6 10 6 2 2 7 4 2 4 4 4 2 4 3 8 3 3 2 7 9 3 3 4 3 4 4 4 2 4 3 4 6 3 6 12 4 4 4 7 7 3 7 0 6 8 2 3 3 8 2 1 3 4 2 6 4 2 7 9 3 6 1 3 1 1 4 7 3 7 7 4 3 3 4 6 7 2 2 3 3 2 3 2 4 6 3 3 3 2 3 8 3 1 2 6 8 3 1 4 2 2 4 2 4 3 3 4 3 1 2 1 1 2 10 4 2 2 1 4 1 2 4 1 1 3 6 4 4 3 6 3 6 2 3 2 4 2 8 3 2 4 3 4 1 2 7 3 4 7 4 3 0 6 4 3 7 6 7 7 3 3 4 1 3 4 4 2 4 6 10 4 3 8 3 3 8 4 0 2 4 1 0 7 4 3 4 8 8 0 4 2 6 8 6 6 4 4 6 7 2 3 6 2 6 6 4 3 3 4 7 3 3 9 4 4 3 7 1 7 2 3 7 8 4 2 4 0 6 6 2 6 4 2 6 4 4 3 6 3 4 4 4 2 4 4 3 1 1 4 2 4 2 2 4 7 2 2 1 3 8 4 4 6 7 6 4 7 3 2 4 6 4 4 3 6 8 6 3 9 0 3 3 3 2 6 0 1 4 8 3 4 3 7 8 4 3 4 4 3 6 2 3 6 7 6 2 3 12 7 6 4 3 3 3 2 3 2 1 2 3 6 3 3 3 3 7 9 2 7 4 3 0 1 4 4 6 2 3 1 1 4 6 8 3 7 4 8 3 7 6 2 6 3 4 3 12 4 10 8 6 12 6 7 8 8 10 10 12 20 23 19 13 20 20 26 15 8 18 12 15 10 7 14 7 12 6 10 12 4 4 2 7 0 2 9 2 7 4 12 2 3 6 4 4 6 3 4 3 7 7 7 6 8 12 6 3 3 6 4 2 8 2 6 8 4 4 3 6 6 3 0 4 2 8 3 3 7 4 4 8 4 6 0 6 3 6 7 4 3 2 4 4 2 7 2 4 0 6 4 3 4 6 3 3 3 4 4 4 3 8 1 0 4 4 4 2 1 9 2 7 2 2 1 7 4 3 2 4 3 6 8 1 6 4 3 7 6 4 4 6 7 1 7 2 4 3 3 6 4 1 3 3 4 3 12 2 6 10 13 8 8 12 12 10 8 7 8 9 8 6 8 7 2 8 8 8 4 2 9 8 2 7 8 3 4 4 8 2 6 4 3 2 8 1 3 4 3 2 2 3 3 1 1 0 3 4 6 6 6 2 3 0 8 1 7 2 6 4 6 2 6 3 0 4 7 2 3 7 2 2 3 7 8 1 3 1 2 3 1 1 4 4 4 2 7 0 3 2 2 8 1 3 1 3 6 6 4 8 6 6 8 7 7 8 4 2 3 6 3 4 2 1 3 9 2 6 6 2 4 4 1 2 2 2 2 8 2 2 6 8 2 7 7 8 4 3 12 3 6 3 13 14 3 10 9 14 8 7 7 16 10 13 19 16 15 25 30 40 49 50 44 37 37 41 41 31 18 25 12 7 8 10 6 9 12 6 2 6 2 7 8 4 8 9 7 8 7 3 4 7 7 6 2 7 14 12 8 6 2 4 8 3 1 6 3 7 3 2 2 7 8 4 4 3 1 2 7 3 3 6 4 0 3 3 8 2 7 1 2 2 3 4 6 9 4 9 3 2 3 4 2 4 2 6 8 2 3 2 4 4 7 3 3 7 7 3 0 1 3 3 6 4 6 2 3 6 7 8 3 7 2 2 7 3 8 4 1 3 3 6 2 2 6 3 0 4 2 3 8 1 4 2 2 7 4 3 4 2 3 4 2 3 6 1 4 7 4 8 2 4 9 4 4 3 4 4 8 6 9 4 8 9 6 7 7 7 9 3 4 6 9 4 7 3 0 6 7 2 2 1 1 2 4 1 4 4 6 1 4 4 3 9 1 3 4 6 3 3 6 4 7 3 1 1 1 6 2 7 3 1 6 3 3 3 2 7 3 6 3 4 1 2 2 6 0 4 7 3 2 2 3 4 4 3 2 6 7 4 1 2 1 4 7 4 6 3 2 3 3 3 4 1 1 4 4 6 1 0 0 1 6 1 4 1 4 2 3 4 2 6 4 4 2 0 3 6 1 3 3 6 3 3 0 7 3 3 4 3 4 3 4 6 2 0 1 4 4 1 1 6 3 1 3 1 4 3 8 3 4 2 4 7 3 0 6 4 3 2 4 2 4 8 1 4 6 2 7 7 8 1 7 2 1 2 6 2 2 2 3 2 4 2 4 2 1 3 6 6 6 6 4 4 8 3 3 2 4 3 7 3 1 6 2 2 3 3 3 0 4 2 3 4 3 7 2 2 1 2 3 2 3 1 4 0 6 1 6 6 3 2 6 4 8 4 7 3 3 3 8 1 4 0 2 3 0 9 0 2 6 3 4 3 1 9 0 3 7 4 3 6 3 3 4 3 2 3 6 2 6 3 3 4 4 2 3 3 2 3 3 2 1 2 1 1 7 3 3 2 2 1 2 3 4 3 6 3 3 4 6 4 6 3 0 3 3 1 2 3 4 1 0 3 2 6 2 3 3 2 3 3 1 1 1 1 2 0 3 4 6 2 8 7 3 2 0 10 1 7 3 1 6 1 3 6 6 2 1 1 7 7 1 1 2 2 4 2 1 3 3 7 1 2 1 1 3 2 1 7 0 2 2 6 2 1 2 2 4 6 6 2 4 1 4 0 2 4 1 2 3 3 4 3 6 2 3 3 2 0 10 2 6 4 0 1 2 4 3 6 6 3 9 6 4 1 4 6 4 1 4 0 4 3 7 2 6 6 3 2 4 3 4 3 6 4 8 3 4 6 2 4 3 9 7 2 3 2 1 0 3 1 3 8 4 2 3 6 3 2 7 8 1 2 9 2 6 1 2 6 1 8 2 7 0 2 1 3 4 2 6 2 2 6 6 9 3 4 4 4 2 2 3 2 0 0 0 2 2 1 0 1 6 7 4 3 7 6 4 4 8 1 3 3 4 4 7 8 3 6 6 3 4 8 1 2 2 4 4 2 6 6 2 3 1 7 6 7 6 8 3 3 4 7 0 6 6 2 6 0 2 1 1 3 2 2 2 2 6 7 4 7 0 3 1 2 2 7 3 9 2 8 3 6 4 4 0 1 3 7 2 8 4 3 3 4 1 6 4 7 1 3 2 7 2 4 1 6 3 4 1 7 4 3 2 2 6 1 1 7 4 3 1 2 3 3 6 9 4 2 4 3 4 4 8 7 4 2 2 8 1 2 0 3 3 4 2 2 9 6 4 3 4 1 9 12 8 4 6 6 6 3 8 4 8 4 2 0 10 7 4 9 4 4 9 8 8 9 8 12 10 8 7 12 9 12 8 6 14 6 8 19 13 24 23 25 35 36 18 32 29 18 13 15 20 12 16 14 13 15 9 13 12 16 12 7 9 20 14 14 15 18 12 9 16 15 9 16 14 8 8 15 13 8 12 18 24 12 16 23 10 16 12 14 14 12 12 25 19 13 13 21 20 26 9 10 12 23 15 18 23 21 31 26 24 24 36 33 29 37 46 55 49 52 70 70 83 70 109 105 126 143 183 224 258 292 345 393 521 660 804 945 1078 1252 1443 1358 1420 1228 1030 945 664 530 446 333 282 258 227 232 210 172 169 120 111 72 92 71 66 47 50 44 63 61 58 48 55 49 42 36 38 44 65 49 35 30 27 31 24 30 31 38 31 29 26 29 24 23 25 26 19 19 19 23 24 26 27 24 27 19 23 16 14 13 19 19 15 13 15 13 19 14 13 13 21 9 20 10 18 18 14 21 13 10 12 19 19 15 19 15 9 12 20 10 10 20 18 9 12 26 9 13 12 6 23 8 14 8 8 10 9 12 13 9 14 14 14 12 9 15 9 18 12 16 18 7 13 9 10 19 14 15 9 19 13 8 8 3 18 15 9 9 2 13 12 18 14 13 6 9 6 9 7 13 9 6 12 7 10 10 12 9 19 7 10 9 14 12 13 12 14 16 8 14 8 9 13 6 7 4 16 12 7 9 13 15 13 10 10 8 7 13 16 14 9 18 14 8 6 8 9 8 8 16 16 18 15 4 14 19 10 13 12 7 8 8 16 13 9 10 12 12 8 14 7 13 14 10 6 7 12 8 8 12 12 8 12 15 13 8 12 8 9 8 14 7 8 10 10 7 15 8 9 6 14 10 8 4 14 12 9 7 9 10 7 8 7 10 13 12 9 7 9 6 13 10 10 9 10 8 4 4 6 2 9 4 12 12 8 7 7 4 8 6 4 10 15 16 6 8 12 9 7 4 2 13 1 13 8 6 8 12 10 7 6 10 12 10 12 9 8 8 6 8 6 7 3 8 9 6 6 3 8 14 12 7 8 8 8 4 4 8 9 8 14 12 14 9 9 12 10 7 10 8 8 7 9 13 7 9 3 10 7 4 8 9 4 8 8 8 9 9 8 10 12 6 8 10 8 8 8 2 15 7 4 7 9 7 4 8 10 10 10 3 4 13 4 4 7 7 10 4 9 9 4 10 9 13 10 7 4 9 15 7 7 7 9 4 0 9 13 8 9 12 12 8 10 4 9 3 6 4 8 13 12 6 4 8 3 9 13 3 6 2 8 9 6 6 0 6 4 4 2 4 4 4 1 9 7 9 7 8 6 10 7 10 8 6 8 10 14 3 9 4 3 7 7 10 15 12 7 3 13 6 2 8 12 2 7 6 7 4 9 4 9 9 10 2 8 8 4 7 3 7 8 9 1 3 6 8 4 9 8 7 8 6 9 3 9 9 6 12 4 4 9 7 8 10 8 12 6 9 6 8 12 14 9 9 9 12 10 2 7 12 2 1 10 3 3 7 10 9 6 7 9 7 4 13 8 8 9 9 4 6 9 10 4 7 8 1 8 4 3 6 10 7 7 12 6 7 8 6 7 2 3 2 10 3 9 4 4 9 6 4 6 9 10 3 8 1 9 4 8 10 7 8 6 8 9 7 7 6 10 4 6 4 8 9 4 7 6 10 7 3 7 12 4 7 10 9 10 12 7 7 4 10 8 14 8 8 4 7 6 7 10 4 9 9 10 8 12 20 12 9 6 9 12 4 8 7 9 4 13 9 13 12 3 4 10 4 4 6 6 9 9 9 6 7 9 14 6 8 12 12 20 6 7 6 10 8 8 2 7 13 10 13 10 7 9 12 4 9 8 9 14 12 10 10 9 4 7 9 12 9 1 3 8 10 12 7 3 9 7 7 12 8 4 15 13 14 6 15 13 10 12 12 26 16 24 15 26 21 24 31 24 29 25 31 41 33 33 52 56 69 82 98 71 71 93 69 72 53 64 38 38 36 18 26 35 20 19 27 19 18 9 12 9 13 13 7 20 4 14 4 10 19 6 12 4 12 8 15 6 6 8 14 10 3 8 12 9 12 13 12 9 14 15 3 3 2 7 16 13 10 16 9 7 10 8 4 7 2 14 10 9 9 9 12 3 4 12 3 7 8 13 4 8 6 4 8 13 8 7 10 6 9 8 12 10 10 16 7 10 14 8 15 13 18 21 13 14 21 12 14 20 15 18 16 13 13 12 14 9 9 9 6 7 6 7 9 6 10 7 8 13 12 9 8 4 9 8 9 6 7 12 7 7 7 8 13 7 12 7 9 9 10 9 2 6 7 4 10 7 6 7 9 7 7 6 6 6 6 13 3 8 9 6 15 7 2 7 6 8 10 18 9 7 8 12 8 7 9 7 9 9 6 9 6 7 4 8 8 4 7 8 3 3 4 7 12 7 4 3 9 12 8 6 12 7 8 7 4 3 9 7 6 9 4 9 12 2 7 7 4 7 12 9 7 6 10 13 6 4 4 7 9 9 9 9 6 7 14 12 12 13 8 4 9 3 7 10 8 4 8 13 6 8 6 12 10 10 4 7 8 6 7 12 10 4 7 7 8 6 3 3 6 7 12 9 3 4 6 12 7 8 6 15 10 6 10 14 10 12 8 12 9 4 9 10 9 6 6 6 9 9 7 8 4 10 12 3 10 7 7 3 15 3 4 12 4 9 4 10 2 10 13 10 7 8 7 4 10 4 7 10 10 9 9 8 6 6 8 4 6 10 7 9 6 8 15 10 10 13 8 9 15 3 7 3 4 13 8 1 12 8 4 14 8 6 9 12 9 6 8 13 6 9 19 8 6 6 6 9 7 10 2 14 7 7 8 15 4 20 9 7 13 12 7 15 15 8 8 12 8 10 8 8 10 8 8 10 18 6 12 12 15 6 18 13 8 20 19 14 9 13 8 12 14 12 21 8 10 8 4 16 13 13 15 13 6 9 8 12 8 7 4 10 16 9 15 10 10 12 20 14 7 15 14 7 15 15 9 12 13 14 13 7 13 18 16 10 16 4 6 12 10 6 15 15 14 9 13 18 12 19 9 13 12 12 12 19 19 10 14 15 14 16 14 15 16 21 24 16 14 15 15 10 18 13 23 19 24 16 18 23 20 30 15 23 30 31 30 27 29 27 42 41 46 42 49 49 44 31 48 56 53 58 52 54 55 58 87 54 43 61 58 63 66 53 52 76 59 65 64 48 50 35 55 55 59 56 50 54 64 63 69 55 72 81 76 73 95 80 87 100 100 96 109 96 112 135 116 160 166 224 202 244 282 305 351 383 437 490 578 660 791 984 1276 1608 2056 2863 4119 5679 7311 7896 7627 6844 5518 4158 3121 2369 1863 1506 1195 887 792 647 524 526 358 377 351 361 337 320 289 307 356 357 334 380 446 488 574 724 886 1224 1628 2097 2810 3299 3679 3728 3665 3140 2435 2024 1584 1209 944 737 549 437 414 320 286 248 193 191 161 151 141 135 132 120 96 96 84 73 72 84 77 87 52 56 77 72 52 56 69 50 55 50 44 50 56 46 41 37 36 53 32 32 33 46 40 30 31 40 26 32 29 31 29 29 19 20 30 41 32 32 20 25 16 26 31 37 25 26 18 10 20 19 20 10 27 23 29 16 19 13 20 21 25 16 15 21 19 18 18 30 14 15 15 24 23 18 20 16 23 21 18 25 14 8 20 10 12 13 13 16 10 13 19 8 12 14 14 10 19 16 14 18 14 14 9 16 12 15 16 15 15 15 16 12 8 14 10 20 12 8 19 8 19 13 13 12 13 19 12 15 15 18 13 13 19 20 7 10 8 20 10 10 16 6 6 7 4 10 14 14 14 15 8 13 10 8 10 12 7 13 9 12 4 9 10 7 7 7 14 10 6 12 7 9 14 13 7 14 7 3 10 10 4 12 10 6 3 7 12 10 14 7 13 7 7 6 10 12 10 3 9 7 13 15 9 8 4 6 10 10 6 6 13 14 7 6 6 8 2 3 14 6 15 8 4 9 10 10 12 6 8 4 12 9 6 8 8 4 12 10 7 10 9 8 0 9 10 7 4 13 9 7 7 8 7 7 7 10 13 6 9 7 9 13 6 6 9 7 7 4 7 12 2 8 8 7 7 9 7 10 12 4 8 4 3 6 9 12 8 7 3 18 8 16 12 9 7 7 8 8 9 4 6 13 3 10 2 4 9 9 12 9 3 7 15 6 8 2 9 9 9 8 6 7 13 4 3 7 8 7 6 6 9 10 6 8 12 2 7 12 7 6 8 6 3 7 12 6 10 4 6 7 4 6 10 3 9 6 4 9 7 16 10 7 8 3 4 6 10 8 3 7 2 9 2 3 7 6 9 9 6 7 3 8 2 4 4 8 4 6 6 12 7 6 10 7 8 6 9 6 8 3 13 7 9 9 10 8 13 10 8 4 3 6 9 6 2 4 10 1 7 4 10 7 7 6 2 9 8 6 7 6 6 1 6 8 6 8 3 6 12 10 8 10 7 9 8 4 7 10 7 7 4 3 8 12 10 14 12 10 4 7 7 9 4 3 6 2 6 1 8 8 7 7 7 3 12 8 0 3 4 4 12 10 8 4 4 9 6 4 8 1 6 3 6 4 7 8 3 2 8 7 4 4 4 8 8 6 9 3 10 1 2 6 9 7 12 7 9 6 9 4 7 3 9 1 6 6 9 2 4 7 6 7 10 6 6 9 4 1 2 7 7 4 7 4 9 9 3 3 8 3 9 2 4 6 2 4 4 9 8 7 3 4 4 4 2 3 7 6 9 7 7 8 3 7 8 8 3 10 10 6 3 9 8 3 12 8 3 6 7 12 9 6 8 4 6 4 7 10 9 3 13 1 7 7 3 7 4 7 6 9 4 8 3 9 4 8 4 7 0 7 2 4 3 8 10 6 9 3 8 4 4 8 6 6 3 6 3 3 14 8 7 6 7 6 2 8 3 8 6 6 6 7 9 3 9 7 12 2 4 8 10 7 8 3 9 4 4 7 8 6 9 3 7 6 3 6 4 4 6 8 6 8 9 3 3 6 4 4 3 6 6 2 3 2 3 6 6 3 4 3 7 2 6 3 6 1 4 3 7 7 4 7 3 3 7 7 3 4 6 6 7 2 4 4 9 3 4 6 4 6 7 3 0 3 2 6 10 4 3 6 7 3 1 2 7 2 7 9 2 8 7 6 3 2 3 3 6 7 3 9 4 9 6 8 4 3 6 1 7 3 10 2 4 2 3 4 6 6 3 6 4 4 6 6 4 4 2 3 6 4 10 3 2 8 3 7 4 6 7 6 6 7 6 7 7 6 8 4 6 7 4 0 4 4 2 7 9 4 7 7 7 3 1 7 6 4 9 3 6 7 7 4 6 4 8 2 7 8 8 7 3 8 3 4 6 2 3 3 4 8 9 4 3 10 9 2 8 4 2 2 8 4 4 3 4 4 4 4 1 7 6 3 2 2 3 2 3 8 3 6 8 9 13 7 7 1 4 6 4 4 3 4 6 8 7 7 6 6 4 7 4 2 7 12 7 2 12 4 4 6 7 6 3 7 6 2 2 9 6 6 2 6 4 10 8 3 3 4 6 1 4 6 9 4 6 4 2 0 2 3 8 9 2 3 3 4 6 3 3 6 6 4 1 4 6 12 6 3 3 4 6 6 2 7 6 6 3 7 6 1 2 12 3 4 4 6 7 8 4 4 3 4 7 6 4 8 7 3 6 12 3 7 4 1 3 6 9 6 3 3 6 6 4 8 3 6 7 4 1 0 1 4 13 4 10 6 1 7 3 12 2 8 6 3 3 8 15 7 4 7 8 6 6 3 2 7 8 2 0 4 6 2 2 3 6 3 6 4 8 4 6 1 7 3 4 2 10 3 8 2 6 3 9 1 3 7 9 4 6 0 7 4 7 4 3 6 1 2 7 3 4 1 10 7 7 4 2 8 3 7 8 4 9 9 4 7 7 4 6 6 4 7 3 6 9 7 4 6 3 6 4 8 8 4 7 9 8 6 7 6 10 6 3 10 4 9 18 10 7 10 12 9 16 9 10 7 13 13 8 20 4 18 20 14 14 10 13 16 20 7 15 10 13 13 9 7 9 6 13 9 4 7 8 7 7 9 12 8 4 8 3 6 6 6 6 7 8 6 7 4 7 7 2 2 4 12 7 6 7 9 6 3 7 9 7 6 7 3 6 4 2 8 7 6 3 6 4 2 2 4 7 6 3 2 8 4 2 4 14 4 10 6 6 4 3 7 10 4 9 7 3 7 1 4 9 6 1 2 8 4 3 2 6 4 4 2 6 2 4 1 4 4 4 3 4 3 3 4 4 7 6 7 3 3 7 3 10 2 3 1 8 8 7 4 2 8 4 8 6 6 7 1 3 4 9 6 6 10 2 2 3 4 3 1 3 6 12 4 4 4 3 10 6 4 8 3 8 7 6 4 6 6 7 6 6 9 4 6 4 9 2 3 4 1 4 10 6 8 3 8 3 8 6 6 9 8 4 4 3 3 10 12 6 3 3 9 4 6 4 8 4 4 7 4 8 3 9 4 2 14 4 4 6 7 9 4 9 2 1 4 10 7 4 7 1 4 2 9 10 6 2 4 2 2 7 6 4 7 6 13 1 7 7 8 9 8 7 8 4 13 9 4 7 8 16 12 8 7 8 6 7 9 6 10 9 9 7 10 10 9 13 8 8 16 3 6 4 6 4 10 8 2 3 8 3 8 4 2 7 3 1 3 2 3 3 6 14 7 8 4 1 10 2 1 6 3 3 4 7 6 2 6 4 7 6 1 6 8 10 3 7 0 4 3 8 4 7 3 8 1 8 7 7 2 2 2 2 4 6 3 7 9 2 6 7 9 3 1 3 13 4 3 7 2 8 3 1 7 6 10 3 8 6 3 1 4 4 10 7 4 7 7 4 6 3 8 4 2 4 7 3 4 9 3 4 2 2 4 6 2 4 10 4 6 3 4 3 6 4 1 4 9 7 2 7 4 6 4 7 8 3 6 6 3 6 4 4 1 4 7 6 6 3 2 3 6 4 8 6 6 3 2 10 7 4 6 3 3 9 8 6 4 4 7 9 7 12 3 4 7 8 8 13 3 4 4 4 4 7 7 7 7 2 8 4 4 3 2 12 3 3 7 9 3 9 6 4 6 6 2 3 2 4 7 2 4 4 6 3 0 4 3 7 7 6 4 12 0 8 12 4 8 10 1 6 7 1 7 4 6 8 4 6 10 6 6 12 7 3 4 3 3 8 13 9 12 12 10 9 13 14 12 18 10 20 12 16 19 26 13 26 33 29 37 41 38 38 35 32 30 29 38 21 21 16 13 14 18 9 15 18 10 10 8 10 6 8 8 6 3 7 7 15 7 6 8 7 3 12 12 7 2 4 7 3 8 7 4 1 8 4 9 9 4 10 12 6 2 4 4 6 6 3 3 8 7 2 2 7 4 8 8 8 4 3 4 2 8 8 3 9 7 2 4 2 4 9 4 6 6 4 3 9 7 6 8 6 1 2 6 7 7 3 9 3 3 2 2 3 7 1 3 4 6 4 4 4 2 3 8 4 4 4 6 3 1 8 4 4 4 10 6 9 7 7 6 6 7 3 3 1 9 2 3 3 8 6 3 8 2 4 6 8 7 4 4 6 7 3 7 8 8 9 8 6 3 7 6 1 3 4 7 4 2 3 6 4 3 1 4 10 7 3 3 1 8 7 2 7 2 4 2 3 6 2 2 4 3 7 8 6 3 3 1 4 3 8 0 3 7 7 6 3 1 3 8 3 4 3 6 2 9 6 2 4 7 2 6 6 3 4 6 6 10 4 2 3 4 7 2 6 4 4 8 2 9 7 7 2 4 8 2 6 1 1 9 6 6 7 6 6 7 4 1 2 2 6 3 7 8 3 2 1 3 4 6 7 7 4 3 2 8 3 6 1 2 4 6 7 6 9 7 4 2 4 7 1 6 4 8 6 8 7 9 12 3 6 8 3 9 3 8 10 7 6 3 7 9 1 6 7 9 2 3 4 4 1 6 3 6 4 2 3 2 4 2 8 4 2 4 2 2 8 4 2 7 3 2 3 2 3 3 4 8 2 6 2 4 4 3 3 6 7 7 2 3 6 8 3 4 9 8 1 4 3 2 6 3 8 4 6 10 4 2 7 6 2 1 3 7 6 10 2 2 8 6 8 2 4 4 4 3 3 6 2 4 4 3 4 7 2 3 6 3 10 6 4 2 3 1 1 1 6 4 4 6 3 3 4 7 4 1 2 3 6 4 3 4 4 7 6 6 2 9 2 3 2 7 7 4 6 9 2 4 3 3 2 3 4 3 2 7 1 6 7 6 6 7 7 8 4 4 10 8 6 8 4 1 3 7 2 2 1 1 8 2 8 4 6 6 4 6 6 3 6 7 6 4 4 2 3 3 2 4 9 4 2 4 4 2 6 3 9 2 2 1 6 7 12 7 1 4 6 3 3 3 1 2 10 3 3 7 8 1 3 7 4 3 6 1 2 6 3 6 4 2 8 1 3 7 4 6 3 2 1 8 6 10 2 2 10 6 3 1 4 10 3 4 2 6 10 7 9 10 2 7 2 6 6 1 2 2 3 4 3 3 3 6 6 2 12 8 3 9 8 4 0 3 0 2 6 3 9 2 6 6 6 2 1 1 6 0 7 3 13 12 3 4 9 6 6 4 4 4 2 3 6 7 7 6 6 6 1 4 3 6 6 2 3 1 9 8 7 6 2 1 2 7 7 1 3 4 12 8 9 3 8 3 8 6 4 2 1 1 4 4 3 4 4 4 3 3 3 2 4 7 1 1 6 1 1 7 8 3 2 4 3 7 7 2 4 1 6 9 7 3 3 1 7 2 1 2 6 6 4 4 4 3 2 8 3 2 7 3 7 1 2 7 4 2 4 0 4 4 3 1 8 2 1 3 1 2 7 4 6 3 4 1 1 4 8 7 6 8 4 4 1 3 4 3 1 4 1 2 6 4 4 3 12 4 8 2 6 2 4 4 6 3 3 6 1 1 3 6 1 6 6 10 7 2 4 1 4 8 2 4 9 2 2 3 3 1 3 2 3 7 2 8 6 4 2 2 6 4 2 9 6 3 3 1 6 4 1 7 4 4 3 7 3 3 3 9 3 2 4 8 7 4 3 1 6 8 3 7 7 3 3 6 3 4 2 7 3 3 7 1 2 3 7 3 6 1 8 4 6 7 1 6 1 2 2 6 3 1 3 6 7 3 4 6 6 2 0 4 1 3 6 4 6 9 4 3 1 3 2 3 6 1 4 8 3 4 7 8 4 3 3 6 0 4 2 6 4 1 6 3 3 6 7 2 3 2 1 3 3 3 4 3 2 6 3 2 7 9 3 2 4 7 6 2 3 4 3 2 6 1 4 6 1 1 3 0 3 4 4 4 6 8 4 7 6 3 2 3 8 3 8 4 2 4 4 3 4 0 7 8 3 7 6 6 2 1 3 2 6 2 3 1 0 6 0 4 3 7 4 3 7 4 2 2 7 6 2 2 4 1 3 3 2 1 2 1 1 7 2 8 6 7 4 2 4 4 4 2 8 9 2 1 3 6 2 2 4 3 4 3 3 4 6 2 3 6 4 4 3 3 0 7 6 6 3 2 2 6 6 4 3 4 3 3 6 3 7 2 7 7 9 7 1 1 6 6 6 3 7 2 7 2 4 3 6 4 8 4 6 4 3 1 4 3 6 3 3 1 0 10 1 4 1 2 4 2 4 1 2 8 6 2 6 2 0 1 1 7 6 7 1 6 4 7 4 6 4 3 4 0 4 3 4 1 3 4 6 2 2 4 4 3 4 3 6 2 3 2 3 3 3 3 4 3 2 4 3 2 7 3 4 1 2 3 4 7 4 6 6 6 6 4 7 6 0 3 0 2 4 3 4 2 4 6 0 3 3 3 1 4 3 3 4 3 6 3 4 7 2 2 7 3 2 3 3 8 1 2 4 6 6 6 3 6 3 6 8 4 6 2 3 6 4 3 3 12 2 4 2 2 2 1 6 7 8 0 10 6 2 6 4 3 4 2 2 3 4 1 3 7 1 3 3 4 3 3 3 3 2 0 1 6 3 2 1 6 3 1 3 9 4 3 2 1 2 8 7 4 2 8 1 3 3 3 0 7 8 7 6 2 3 2 4 7 4 2 2 7 3 2 2 7 8 4 8 4 4 4 3 1 8 8 1 7 1 6 6 2 8 3 6 3 4 1 2 4 1 4 2 6 3 2 2 3 1 1 3 2 6 4 3 3 1 3 3 6 2 4 4 2 0 2 6 2 3 3 6 3 4 3 4 3 2 3 4 4 7 6 4 6 2 3 2 3 3 4 2 4 4 3 2 2 1 3 3 1 7 2 0 2 2 3 3 7 7 2 2 3 3 6 6 8 2 3 3 6 7 2 3 7 4 3 3 4 3 4 3 7 8 2 0 3 4 3 7 3 4 6 2 3 3 6 7 4 4 2 4 2 3 6 2 6 3 3 8 6 10 2 12 2 2 6 2 7 1 7 3 4 3 1 3 6 10 8 4 4 4 0 6 7 3 3 4 1 4 3 4 8 1 8 8 7 3 1 6 8 4 4 1 4 0 3 12 4 7 9 2 9 4 2 0 3 4 7 2 10 3 14 6 7 3 3 7 8 3 3 4 2 6 6 6 7 1 12 14 6 8 6 6 6 13 3 4 4 9 6 3 6 3 7 3 7 1 6 7 4 3 3 6 9 6 4 4 4 4 4 4 9 4 9 2 6 9 3 4 4 6 2 7 2 2 6 7 6 7 3 6 6 2 4 7 10 4 2 7 4 7 4 12 3 4 7 4 2 7 6 7 6 2 6 6 2 10 7 8 6 0 2 7 6 10 6 7 8 3 8 10 2 6 6 4 6 3 4 7 6 4 4 8 7 7 8 6 6 12 14 9 10 8 12 1 9 6 4 12 7 12 13 13 13 10 13 7 16 8 13 12 15 7 4 13 10 15 13 19 13 15 23 15 18 29 26 32 30 24 19 27 24 26 31 25 23 13 15 21 9 14 15 21 15 18 12 16 18 8 13 7 12 16 13 13 15 16 18 8 7 12 13 14 18 9 18 8 14 10 10 10 14 8 12 19 10 7 13 15 16 13 14 8 13 14 19 15 8 12 12 16 7 8 23 14 12 13 12 13 10 13 19 15 16 13 19 15 14 9 21 14 18 14 15 16 8 18 15 15 9 19 10 18 18 15 21 9 12 8 10 15 15 13 19 16 15 16 16 25 13 16 9 18 19 13 12 20 16 20 21 19 19 15 18 18 29 14 16 18 21 15 13 16 13 30 26 20 15 23 32 30 23 24 27 27 29 32 27 32 30 29 35 24 42 25 35 27 44 30 46 48 42 52 63 52 47 69 56 67 63 89 86 82 101 93 105 111 118 143 126 155 152 189 216 216 219 250 297 327 341 358 400 449 478 577 595 672 747 817 857 909 1024 1118 1246 1249 1243 1288 1282 1254 1191 1128 1128 1006 943 851 774 693 649 528 476 465 361 333 312 300 278 238 225 248 237 233 214 180 218 183 186 160 120 143 113 120 94 101 112 110 110 101 93 66 75 64 66 59 58 55 49 61 56 59 54 55 49 56 56 59 54 52 36 40 38 32 27 32 40 32 30 38 65 46 41 24 32 42 30 26 24 40 31 25 36 38 19 30 30 44 38 29 26 25 24 35 21 36 15 20 19 31 24 30 18 18 19 26 27 31 20 16 31 15 31 24 19 18 15 26 25 18 32 20 31 24 21 23 25 20 24 20 26 18 29 24 15 23 21 23 26 9 25 27 8 18 16 23 32 19 16 18 13 14 19 14 14 19 10 12 19 18 12 16 10 12 20 16 15 27 19 18 9 16 14 8 15 14 6 21 12 7 10 23 13 14 13 18 8 29 19 19 14 15 20 9 19 14 14 20 15 23 19 10 10 15 10 16 12 12 16 14 19 8 20 7 10 13 12 13 7 15 6 7 9 15 13 13 15 19 13 18 10 15 12 19 15 12 14 16 9 13 8 8 10 8 18 21 12 16 19 14 10 6 16 14 16 19 10 9 13 8 21 15 12 13 13 7 12 8 4 9 14 13 10 13 10 7 15 9 15 2 10 9 9 16 16 9 12 9 13 13 16 9 15 10 12 8 14 4 10 8 12 9 13 4 6 4 14 18 13 8 4 19 7 10 14 7 14 9 15 10 15 9 14 7 8 12 3 13 7 10 12 14 8 12 9 8 8 15 15 10 6 12 13 12 12 8 8 9 8 9 13 12 13 15 13 14 13 9 4 9 15 6 19 15 2 13 19 9 9 9 4 16 9 10 9 14 18 7 10 7 14 13 23 16 4 10 8 6 9 14 12 9 8 15 12 7 14 12 12 15 16 13 12 8 12 6 14 7 9 6 12 13 7 6 3 9 2 9 14 8 9 6 6 14 4 8 8 15 9 10 7 4 7 7 8 9 12 8 14 7 12 9 7 8 10 7 10 8 8 8 12 6 13 21 23 14 12 7 12 4 13 10 13 4 9 12 9 10 8 15 8 10 9 6 7 9 8 10 8 12 7 9 7 13 10 9 15 12 9 6 12 3 9 14 9 10 9 3 10 9 9 9 4 9 14 12 14 13 9 14 6 13 9 8 13 9 13 4 9 6 7 14 15 6 18 4 9 7 10 14 7 4 10 13 9 8 10 7 20 10 12 16 9 12 8 10 7 12 16 10 10 9 8 9 12 12 6 10 9 7 6 12 8 9 7 8 3 7 10</intensities>
			</dataPoints>
		</scan>
	</xrdMeasurement>
</xrdMeasurements>