File: Roentgen/Messdaten/Si111_40_30_Ni.xrdml
<?xml version="1.0" encoding="UTF-8"?>
<xrdMeasurements xmlns="http://www.xrdml.com/XRDMeasurement/1.3" xmlns:xsi="http://www.w3.org/2001/XMLSchema-instance" xsi:schemaLocation="http://www.xrdml.com/XRDMeasurement/1.3 http://www.xrdml.com/XRDMeasurement/1.3/XRDMeasurement.xsd" status="Completed">
	<comment>
		<entry>huhuu</entry>
		<entry>Configuration=stage XYZ Phi Psi, Owner=User-1, Creation date=17.03.2006 13:32:17</entry>
		<entry>Goniometer=PW3050/60 (Theta/Theta); Minimum step size 2Theta:0.001; Minimum step size Omega:0.001</entry>
		<entry>Sample stage=IR Stage (Phi, Tilt, X, Y, Z)</entry>
		<entry>Diffractometer system=XPERT-PRO</entry>
		<entry>Measurement program=FP, Owner=User-1, Creation date=18.04.2011 15:14:00</entry>
	</comment>
	<sample type="To be analyzed">
		<id></id>
		<name></name>
		<preparedBy></preparedBy>
	</sample>
	<xrdMeasurement measurementType="Scan" status="Completed" sampleMode="Reflection">
		<comment>
			<entry/>
		</comment>
		<usedWavelength intended="K-Alpha 1">
			<kAlpha1 unit="Angstrom">1.5405980</kAlpha1>
			<kAlpha2 unit="Angstrom">1.5444260</kAlpha2>
			<kBeta unit="Angstrom">1.3922500</kBeta>
			<ratioKAlpha2KAlpha1>0.5000</ratioKAlpha2KAlpha1>
		</usedWavelength>
		<incidentBeamPath>
			<radius unit="mm">240.00</radius>
			<xRayTube id="1010041" name="PW3373/00 Cu LFF DK369848">
				<tension unit="kV">40</tension>
				<current unit="mA">30</current>
				<anodeMaterial>Cu</anodeMaterial>
				<focus type="Line">
					<length unit="mm">12.0</length>
					<width unit="mm">0.4</width>
					<takeOffAngle unit="deg">6.0</takeOffAngle>
				</focus>
			</xRayTube>
			<sollerSlit id="21010002" name="Soller 0.04 rad.">
				<opening unit="rad">0.0400</opening>
			</sollerSlit>
			<mask id="22080002" name="Inc. Mask Fixed  10 mm (MPD/MRD)">
				<distanceToSample unit="mm">101.00</distanceToSample>
				<width unit="mm">6.60</width>
			</mask>
			<divergenceSlit id="22010012" name="Prog. Div. Slit" xsi:type="fixedDivergenceSlitType">
				<distanceToSample unit="mm">140.00</distanceToSample>
				<angle unit="deg">0.25</angle>
			</divergenceSlit>
		</incidentBeamPath>
		<sampleOffset>
			<position axis="2Theta" unit="deg">0.012</position>
			<position axis="Omega" unit="deg">0.012</position>
		</sampleOffset>
		<diffractedBeamPath>
			<radius unit="mm">240.00</radius>
			<antiScatterSlit id="22060009" name="Prog. AS Slit" xsi:type="automaticAntiScatterSlitType">
				<observedLength unit="mm">0.5</observedLength>
				<offset unit="mm">0.00</offset>
			</antiScatterSlit>
			<detector id="7010012" name="X'Celerator Scientific" xsi:type="rtmsDetectorType">
				<phd>
					<lowerLevel unit="%">45.0</lowerLevel>
					<upperLevel unit="%">80.5</upperLevel>
				</phd>
				<mode>Scanning</mode>
				<activeLength unit="deg">2.122</activeLength>
			</detector>
		</diffractedBeamPath>
		<scan appendNumber="0" mode="Continuous" scanAxis="Gonio" status="Completed">
			<header>
				<startTimeStamp>2015-09-03T11:31:07+02:00</startTimeStamp>
				<endTimeStamp>2015-09-03T11:43:00+02:00</endTimeStamp>
				<author>
					<name>Daniel</name>
				</author>
				<source>
					<applicationSoftware version="2.2">X'Pert Data Collector</applicationSoftware>
					<instrumentControlSoftware version="1.7 ">XPERT-PRO</instrumentControlSoftware>
					<instrumentID>0000000000000819</instrumentID>
				</source>
			</header>
			<dataPoints>
				<positions axis="2Theta" unit="deg">
					<startPosition>15.00108891</startPosition>
					<endPosition>129.99550932</endPosition>
				</positions>
				<positions axis="Omega" unit="deg">
					<startPosition>7.50054446</startPosition>
					<endPosition>64.99775466</endPosition>
				</positions>
				<commonCountingTime unit="seconds">3.175</commonCountingTime>
				<intensities 12 12 4 9 7 6 13 3 4 9 4 6 15 6 7 7 8 4 13 6 3 6 3 3 6 4 6 19 8 7 9 7 12 6 8 8 4 9 6 13 9 10 7 6 9 9 3 15 7 9 10 8 8 9 6 14 9 7 9 10 8 7 7 3 3 8 10 9 6 7 7 6 9 8 4 4 8 8 8 1 6 9 12 4 7 6 7 12 6 7 6 6 14 4 7 7 6 3 7 6 9 9 8 4 10 3 8 14 6 4 9 8 4 9 10 9 8 8 7 10 7 10 10 9 13 4 2 12 9 6 6 9 7 12 7 9 8 12 4 10 3 3 4 9 8 6 9 10 10 12 3 8 8 2 9 8 12 14 3 6 8 8 13 9 9 4 4 6 7 7 4 6 4 8 8 6 9 6 7 8 9 9 8 2 6 8 14 8 12 6 6 9 6 4 6 14 9 9 3 10 3 7 7 9 8 3 7 4 7 6 4 7 16 3 12 7 8 8 10 15 8 12 9 2 8 9 9 8 8 15 8 15 9 8 4 6 7 10 3 4 4 7 8 4 8 7 9 3 9 6 13 10 6 8 8 9 12 14 4 6 10 13 9 6 12 1 3 6 6 9 8 13 15 10 9 4 15 2 8 8 4 9 7 12 12 6 6 8 8 9 4 6 7 6 13 2 6 6 2 3 8 12 2 6 7 4 7 7 8 12 8 12 7 9 2 8 8 6 4 6 12 8 7 8 9 7 7 8 7 7 6 4 6 12 1 8 9 13 13 8 6 10 14 2 7 7 12 2 3 2 2 13 6 8 10 13 6 6 9 10 7 6 7 9 6 10 6 10 12 8 6 7 8 12 8 6 7 13 9 3 8 8 3 14 10 6 8 6 4 6 14 12 7 12 4 8 4 9 14 15 4 4 7 8 10 6 7 6 13 7 12 8 7 8 8 7 12 6 6 2 9 4 7 4 3 6 13 6 4 3 6 9 6 12 4 9 10 6 9 9 14 3 8 13 9 8 0 6 7 9 4 12 8 12 4 9 16 6 6 13 4 9 9 6 14 8 10 12 7 8 6 9 10 7 3 12 13 6 3 2 9 10 8 6 9 6 4 7 9 10 8 10 9 8 13 7 14 12 7 7 18 6 9 8 12 6 9 8 6 9 3 6 1 10 3 4 4 2 3 6 9 3 8 6 9 6 9 10 4 6 2 7 13 10 7 8 14 7 8 8 4 4 8 9 2 13 6 8 4 9 10 8 2 9 4 6 3 6 3 6 3 3 7 3 9 12 8 3 4 8 9 8 13 2 6 2 7 4 1 10 9 10 7 7 7 6 8 8 3 3 8 10 8 7 9 7 8 7 8 4 3 7 3 6 7 7 3 10 4 9 8 7 6 3 16 12 14 15 23 18 6 14 15 7 10 4 9 8 6 6 3 9 7 9 4 1 9 10 10 4 6 3 8 7 2 2 10 6 10 6 6 7 4 16 3 4 3 0 7 1 7 6 6 6 13 4 8 4 3 10 8 2 6 3 6 6 1 3 7 7 7 6 3 4 2 2 4 4 3 3 7 12 3 4 4 1 8 2 6 6 6 1 6 2 3 4 4 6 3 7 3 4 2 1 7 6 0 4 3 3 3 4 6 4 3 2 3 4 6 8 9 9 3 3 7 3 4 6 7 13 7 9 6 7 3 9 3 9 7 7 6 3 8 1 3 7 3 6 2 7 8 4 8 7 4 4 4 4 3 9 9 4 3 10 4 3 4 4 3 4 8 3 4 8 6 2 7 8 4 6 3 7 3 3 3 7 3 3 1 6 7 2 6 3 6 7 3 2 4 4 4 4 6 4 2 3 4 4 6 1 3 4 6 2 3 2 0 6 0 2 2 6 3 3 4 3 1 8 4 2 1 1 4 6 1 4 3 6 6 2 3 1 1 1 1 4 2 4 6 4 1 6 8 3 2 4 4 2 3 4 1 1 3 3 4 4 1 7 1 0 1 4 1 4 2 4 2 2 1 2 4 2 1 6 2 0 8 6 8 3 6 1 1 1 6 2 4 4 2 4 1 4 6 6 3 3 2 2 6 1 7 0 4 3 2 2 6 0 1 2 3 2 9 0 3 6 1 7 4 3 4 12 10 13 13 6 8 4 2 6 1 2 3 2 2 4 6 6 1 4 1 1 7 1 6 2 1 3 3 2 9 4 4 3 2 6 2 7 9 4 2 4 8 2 6 3 7 1 2 7 0 1 2 3 3 1 2 3 3 1 3 3 3 1 1 2 6 7 1 4 0 1 2 1 9 4 3 6 3 6 6 3 6 10 16 10 15 12 12 6 4 7 1 2 1 0 2 8 3 3 2 2 2 6 1 2 1 2 2 3 1 1 1 2 0 2 3 1 4 4 1 1 6 1 4 0 1 3 0 6 2 4 8 3 4 1 2 2 0 3 6 2 1 2 2 2 4 1 0 1 4 4 3 3 2 1 2 7 3 2 1 0 1 4 2 6 4 1 2 1 1 3 2 2 1 2 0 4 0 1 3 3 2 3 3 3 1 6 2 1 2 0 2 2 0 2 2 0 1 0 3 1 2 2 1 3 4 1 1 1 3 2 1 2 1 1 1 3 2 2 3 0 1 0 1 2 1 1 2 1 1 2 1 4 1 1 3 1 1 1 1 2 2 2 1 2 1 2 1 0 1 2 0 2 4 1 2 7 6 4 1 1 3 8 2 7 2 6 2 6 7 2 3 4 6 6 7 7 6 6 4 6 7 6 10 4 3 6 7 6 7 6 7 3 12 10 4 6 12 9 7 6 6 9 13 9 8 6 4 19 8 8 7 9 10 6 14 6 4 7 12 9 6 10 7 8 16 8 18 25 42 87 127 183 150 116 70 23 25 19 13 15 7 16 10 20 7 13 8 12 7 4 10 6 8 8 13 9 10 12 3 6 12 9 8 10 2 6 4 4 7 9 8 7 4 7 7 9 7 13 8 6 4 10 3 10 7 4 6 13 8 3 7 3 16 4 3 4 13 10 8 9 1 7 3 10 13 10 7 4 7 9 2 3 3 6 4 12 3 7 4 8 4 10 7 4 6 8 7 9 4 4 4 6 6 12 3 3 6 2 4 14 4 8 6 4 12 4 13 2 6 9 2 6 6 4 2 7 8 7 3 7 6 8 7 6 3 7 3 6 6 9 3 8 15 4 12 9 3 6 2 4 2 6 6 9 12 3 9 8 0 2 9 3 9 10 7 8 7 3 2 12 4 9 4 6 4 4 7 8 4 2 8 4 7 8 2 2 6 9 9 8 8 7 3 6 8 1 4 2 1 8 2 2 2 7 2 7 12 3 6 6 9 9 10 15 21 43 47 64 84 94 98 82 81 88 90 93 88 86 71 88 87 81 80 71 81 64 80 63 77 73 66 63 60 73 78 96 63 55 64 100 78 81 89 76 69 72 69 71 95 66 70 88 86 72 86 80 88 88 69 77 101 99 99 93 92 86 84 87 103 98 101 93 70 107 89 83 95 96 82 77 120 117 104 117 93 105 104 122 129 140 124 130 145 138 136 132 151 179 156 183 192 250 206 275 349 466 526 614 785 923 944 972 957 1086 1098 1122 1292 1483 1688 2259 3100 5213 10803 18965 24640 27006 26664 22395 13749 7503 6118 8696 13542 17192 18320 17132 12321 6280 3099 1832 1263 954 789 637 533 503 392 343 326 313 294 263 248 238 227 196 190 181 166 163 176 161 172 150 149 123 117 133 129 127 124 140 109 121 111 103 110 101 110 93 96 98 86 93 72 78 88 94 99 70 112 98 78 82 82 90 81 92 76 75 89 64 69 75 75 56 59 42 63 81 65 61 61 47 73 63 73 52 66 61 55 80 56 63 65 49 70 76 50 66 47 55 59 49 59 56 49 55 55 71 48 59 43 43 54 60 48 60 53 55 54 59 60 58 49 29 60 63 42 42 59 41 43 59 42 44 46 38 38 44 47 43 53 47 40 42 31 50 46 35 32 50 41 37 43 36 48 35 36 40 60 29 52 32 43 38 30 36 43 38 44 33 33 42 46 48 47 42 40 40 32 44 31 44 40 36 37 38 31 37 37 31 32 41 37 40 36 32 32 42 41 24 35 36 40 37 37 32 23 35 43 40 24 30 30 48 27 32 29 38 27 30 33 29 35 29 30 40 46 30 38 36 27 33 18 20 29 27 35 32 31 35 36 20 40 26 29 36 44 23 29 18 44 32 24 27 24 33 41 35 37 33 31 31 35 37 24 41 32 26 30 33 26 30 21 33 26 30 33 31 26 37 24 38 29 21 29 35 27 23 31 20 24 19 32 25 27 30 29 40 21 30 42 37 23 33 31 19 36 44 30 38 46 33 21 31 20 41 29 27 26 24 24 41 21 24 24 25 25 19 23 27 29 31 26 20 20 27 27 27 24 23 24 23 23 26 19 25 23 32 25 19 26 20 29 16 29 26 20 16 20 24 15 21 14 9 26 24 19 19 23 14 14 25 15 23 15 21 23 20 13 20 10 18 18 19 18 10 20 18 26 20 19 19 16 15 18 19 18 19 20 14 8 18 20 20 21 14 13 27 19 16 25 24 8 18 16 23 21 16 14 15 16 9 14 19 12 12 16 18 13 20 18 21 19 15 23 13 23 12 30 19 19 18 18 19 13 9 14 12 12 21 18 15 14 12 14 15 19 18 13 13 25 15 16 21 23 15 15 10 19 15 13 13 19 15 16 14 15 15 8 16 10 9 15 15 18 23 13 23 20 12 15 12 13 21 20 18 18 14 10 8 9 18 20 21 16 19 13 13 15 8 14 12 14 9 20 14 20 15 14 15 24 20 7 14 19 13 10 14 18 9 8 13 19 9 14 12 9 13 15 20 13 12 21 9 9 15 4 9 16 14 6 16 12 13 13 12 16 8 13 10 6 15 10 13 14 14 10 9 14 14 10 7 14 13 7 13 9 18 10 9 10 8 7 16 8 13 19 13 16 9 14 14 9 12 13 9 10 12 13 25 14 7 12 4 14 7 9 13 15 14 14 18 7 8 9 6 10 4 16 10 14 9 7 6 10 7 8 7 9 9 10 13 13 6 9 8 9 12 3 8 1 9 6 9 10 2 7 2 8 13 9 3 12 10 9 6 3 9 9 8 9 9 10 15 4 13 4 7 6 6 4 8 8 10 9 3 6 10 8 6 6 2 9 4 7 3 7 16 3 7 13 10 14 4 7 7 6 9 6 12 10 9 2 7 7 8 7 12 10 8 6 7 12 6 4 7 8 7 4 7 6 7 7 3 3 8 10 4 10 8 3 9 8 3 10 4 8 7 7 7 10 14 4 9 12 4 7 6 9 0 4 2 3 4 7 6 6 7 3 2 7 2 6 6 6 7 2 6 4 6 3 6 7 10 4 9 2 8 7 9 3 4 4 3 7 4 4 6 2 4 6 8 10 10 3 7 6 6 3 8 2 3 3 1 9 3 4 3 1 9 2 2 3 9 6 6 3 9 3 7 4 3 4 6 6 1 4 3 3 4 4 7 9 6 6 6 6 6 12 1 8 4 9 8 7 1 1 7 2 2 4 7 8 2 4 2 6 2 3 7 2 3 6 4 6 2 1 4 6 6 4 1 2 3 8 2 3 3 3 1 4 6 9 4 3 3 0 4 4 2 1 3 1 9 4 9 7 6 4 3 2 8 6 4 3 2 2 6 1 6 4 7 4 1 3 1 0 2 3 3 1 1 4 2 1 2 1 2 0 8 1 3 3 2 4 4 3 6 6 4 3 3 2 1 4 1 2 0 3 3 3 2 2 0 1 0 4 3 0 2 1 0 2 3 4 1 3 6 1 2 6 6 0 3 2 1 0 2 0 1 1 4 1 3 1 3 4 3 1 4 3 2 2 4 7 1 3 2 9 1 8 2 3 2 0 7 2 4 3 1 1 2 0 1 4 2 3 2 4 6 0 2 4 1 2 4 0 2 3 4 3 1 0 2 2 3 1 3 4 1 0 2 2 2 3 2 2 3 3 2 7 2 1 4 1 0 3 3 2 3 2 1 1 3 4 3 3 3 3 4 4 1 0 1 1 1 0 1 3 1 0 1 2 0 2 0 2 4 3 1 2 2 1 4 2 2 3 2 2 2 1 2 2 1 1 2 0 1 4 3 1 2 3 2 2 1 0 1 2 1 0 1 1 1 1 4 1 3 2 3 3 2 3 1 4 2 1 1 2 2 1 3 2 2 0 3 0 0 3 1 1 3 1 1 0 0 1 4 6 1 1 0 0 3 1 4 1 1 4 0 1 2 3 0 1 1 3 1 2 1 1 2 1 0 4 1 0 2 3 0 1 1 1 2 1 0 1 0 0 1 1 2 1 1 1 0 1 2 0 1 1 3 0 1 4 2 2 1 2 3 0 2 1 0 0 0 2 3 2 1 2 0 1 4 1 0 7 1 3 0 1 0 3 2 2 1 1 2 1 0 3 1 1 1 1 2 0 2 2 1 1 1 4 0 3 2 0 1 1 2 2 1 2 1 3 3 3 3 1 0 1 1 4 2 3 1 2 2 2 1 2 2 1 1 1 1 0 1 1 2 0 2 1 3 1 2 0 2 1 3 1 1 0 0 2 1 2 2 1 2 2 3 1 0 0 3 0 2 0 1 0 1 1 2 2 2 0 2 1 0 1 0 3 1 2 1 3 1 3 0 1 2 3 1 1 2 0 2 1 1 2 0 3 1 0 2 0 0 2 0 0 1 1 3 2 2 0 0 2 2 0 1 0 0 0 0 1 2 1 1 1 0 1 4 1 1 1 0 1 1 1 0 2 1 2 1 2 0 0 0 1 0 1 1 0 1 0 4 0 2 0 2 0 1 2 0 1 0 0 1 1 1 2 3 2 1 2 2 1 7 0 3 0 1 2 0 0 1 0 0 0 0 0 0 0 2 0 1 0 0 1 1 2 0 0 1 0 1 2 1 0 2 0 0 0 0 0 0 0 1 0 1 1 0 2 0 0 1 0 2 0 1 0 1 1 2 0 1 1 0 0 0 0 1 0 1 1 1 0 1 1 1 1 0 1 1 0 2 0 1 0 0 2 0 1 2 0 4 2 1 1 2 0 0 1 0 0 0 0 0 0 0 2 2 2 1 1 1 1 0 1 1 1 2 0 0 1 1 2 0 0 0 0 1 0 0 0 0 2 0 0 0 2 0 0 0 0 1 1 0 1 0 1 1 2 4 2 1 1 0 1 1 2 0 1 1 0 1 0 2 0 3 1 1 0 1 2 1 1 0 0 0 0 1 0 1 2 0 2 0 2 0 2 0 0 0 3 1 0 6 0 0 0 1 0 1 0 0 1 1 0 0 0 0 0 1 1 0 1 1 1 0 1 0 1 0 1 1 0 0 1 1 1 0 2 0 2 0 2 0 0 1 0 2 1 0 0 1 0 1 1 1 2 1 2 0 1 0 1 0 2 0 1 1 1 1 1 0 2 0 1 0 0 1 1 1 2 0 2 2 1 0 0 1 2 1 1 1 1 1 1 1 3 1 0 4 0 1 1 0 0 0 0 0 2 0 1 1 1 1 1 1 0 2 1 0 0 0 1 1 2 0 2 1 0 0 1 0 1 2 1 1 0 2 0 0 1 1 1 1 1 0 0 1 1 2 1 3 0 1 3 3 3 0 1 1 0 1 2 1 0 2 0 2 0 0 1 2 1 1 2 1 0 1 2 0 2 0 2 0 2 0 0 1 1 2 0 0 2 0 0 0 0 1 1 0 2 0 0 2 1 2 2 1 1 2 0 1 2 2 1 2 0 1 0 0 1 0 0 1 0 3 0 1 3 0 1 0 1 1 1 0 4 0 1 2 3 0 1 2 0 1 0 0 1 1 0 2 0 0 1 0 1 0 1 0 1 0 0 0 2 0 0 2 2 1 1 1 0 1 0 1 1 0 0 0 1 1 1 1 4 0 1 0 1 2 0 1 0 1 0 1 0 0 3 0 2 0 0 2 0 0 0 0 0 1 2 0 2 0 1 0 0 0 1 3 3 0 1 0 2 0 2 0 0 2 1 0 2 0 1 0 0 0 1 1 0 2 0 1 0 0 1 1 2 0 1 0 2 0 2 1 1 1 0 0 1 0 0 0 0 0 2 0 1 1 0 2 1 0 0 1 2 0 2 0 0 0 0 1 1 3 0 1 1 1 0 0 1 0 0 2 0 1 0 0 1 1 1 1 2 1 0 1 0 2 1 0 2 0 0 0 2 1 0 1 0 3 3 2 1 2 0 0 0 2 1 0 1 0 0 2 0 0 0 0 0 0 1 0 1 0 0 3 2 1 2 0 1 1 0 1 1 0 1 1 2 1 0 0 0 1 0 1 1 2 1 1 1 2 1 1 0 0 1 1 1 2 1 1 0 0 0 0 0 1 2 0 1 0 0 1 0 1 0 0 0 0 0 0 0 1 1 3 1 1 0 0 2 0 1 0 1 1 0 1 1 0 0 0 2 0 0 0 1 1 1 4 0 0 0 1 1 0 0 0 1 1 1 0 2 0 0 0 2 0 1 0 1 2 0 0 1 1 1 1 0 1 2 3 1 1 0 1 0 0 1 1 1 0 0 1 0 0 1 1 0 2 0 2 1 0 1 3 1 1 1 1 2 3 1 2 1 0 4 0 1 0 1 1 2 0 0 2 1 1 1 0 0 1 0 0 1 0 0 0 1 1 2 1 0 1 0 1 0 1 0 1 0 0 0 2 0 0 1 1 0 0 1 2 2 1 0 2 1 0 1 0 0 1 2 2 0 1 0 0 1 0 0 0 2 0 0 2 0 1 0 0 1 0 0 0 0 0 1 1 4 3 0 1 1 0 2 0 0 0 0 3 0 2 0 0 2 3 0 1 2 1 0 0 0 0 1 2 1 0 0 1 0 1 1 2 0 1 0 1 0 4 0 1 2 1 2 2 0 1 0 0 0 0 2 0 0 0 0 0 0 2 1 0 2 2 0 1 1 1 1 0 1 1 0 1 0 1 1 1 1 0 2 0 1 1 1 0 0 1 2 1 2 1 1 3 0 1 0 0 0 0 0 2 1 0 0 0 2 1 1 0 1 0 1 1 1 1 0 1 0 0 2 0 3 0 2 0 1 1 0 0 1 0 1 3 1 0 0 3 1 1 0 0 0 1 2 0 1 1 0 0 2 1 0 6 1 2 0 1 0 0 2 0 1 2 0 0 0 1 1 0 0 1 0 2 1 0 0 0 0 0 1 2 0 0 0 2 0 1 0 0 0 0 1 1 0 1 2 1 1 0 1 0 1 0 4 1 2 1 0 2 0 1 2 0 0 2 0 1 1 1 1 0 2 1 0 0 1 1 0 0 1 2 0 2 1 1 0 1 2 0 0 0 0 1 1 1 1 0 1 0 1 0 0 2 2 3 1 2 0 1 1 1 1 0 1 1 2 1 2 2 2 0 1 1 2 1 1 1 0 0 1 0 2 1 1 0 2 1 1 2 1 1 3 0 1 1 0 2 0 0 0 1 0 2 1 0 1 0 1 0 0 0 0 1 1 1 0 0 1 0 3 0 0 0 1 0 1 2 0 2 1 2 1 1 0 0 0 0 0 2 0 1 0 1 2 0 1 0 3 1 2 0 2 0 1 0 0 1 0 0 1 0 0 1 0 0 0 1 1 1 1 1 1 1 2 0 2 1 2 0 2 0 1 0 0 0 0 3 2 1 0 0 0 1 1 0 1 0 1 0 0 3 1 2 0 1 0 2 0 0 0 1 0 0 1 1 1 1 0 1 1 0 1 2 0 0 0 0 0 0 1 0 0 1 0 0 2 2 1 2 1 0 1 0 0 0 1 0 0 1 0 0 2 0 4 1 2 0 0 0 1 0 1 0 1 2 0 0 0 1 1 0 1 1 2 0 0 0 0 0 0 1 1 0 1 1 1 1 0 0 0 1 0 0 0 0 0 0 1 0 0 0 0 1 0 0 0 0 0 0 0 0 2 1 1 0 1 1 0 0 0 1 2 0 0 1 0 0 0 0 0 0 0 1 0 1 2 2 0 1 1 1 0 3 0 0 0 1 0 0 0 1 0 1 1 0 1 1 0 0 3 1 2 1 0 0 0 0 0 0 1 1 0 2 1 0 1 0 0 0 2 1 0 0 0 2 0 3 1 1 0 1 0 1 0 2 0 1 0 0 0 0 1 0 0 3 2 2 1 1 2 0 1 0 2 0 0 0 1 0 0 0 0 0 0 1 0 2 1 1 0 2 2 1 1 1 0 0 1 0 2 0 0 1 1 1 1 1 0 2 0 0 0 0 1 0 2 0 1 0 2 2 1 1 0 1 0 1 1 1 0 0 2 0 0 0 0 3 0 2 1 0 1 2 0 1 0 0 0 0 0 0 0 0 1 0 0 0 0 1 2 1 3 1 1 1 0 0 1 3 0 0 0 0 1 0 0 0 1 0 0 0 0 0 0 1 1 2 1 1 1 1 1 2 0 1 0 0 0 0 3 1 0 0 0 0 0 2 1 0 0 0 1 1 1 1 0 1 0 0 0 1 1 0 1 1 0 1 0 0 0 0 1 1 1 0 0 2 1 0 0 0 1 2 1 0 1 0 1 1 1 1 1 1 0 0 1 1 0 2 0 0 4 1 2 1 0 1 0 0 1 0 0 0 1 0 1 0 3 0 0 0 1 1 2 1 0 1 0 1 2 1 1 0 1 1 2 0 2 0 0 0 1 0 1 0 0 1 1 1 0 0 1 0 1 1 0 2 1 0 1 1 3 1 0 0 0 0 0 1 0 0 1 0 1 1 0 1 0 0 0 0 1 0 0 0 0 1 0 1 0 3 0 1 0 2 1 0 2 0 1 0 0 4 2 0 1 1 1 1 0 1 0 0 0 2 0 2 0 3 1 0 3 1 1 2 0 2 1 0 0 0 3 0 1 0 0 1 0 2 1 0 0 1 0 0 3 1 1 0 0 1 1 0 1 1 1 1 1 0 0 0 1 2 0 3 0 0 0 0 0 0 1 0 0 0 0 1 0 0 0 1 1 1 0 2 0 1 1 0 3 2 0 0 0 0 1 1 1 1 1 1 2 1 1 1 0 0 1 1 0 2 1 0 0 2 0 1 0 1 0 0 0 1 0 0 0 0 1 2 0 0 0 0 1 0 4 2 2 0 0 0 1 1 1 1 1 0 0 0 0 1 0 2 2 0 0 0 1 0 2 0 0 2 0 3 0 2 0 2 2 0 0 1 2 0 2 0 1 1 3 0 1 0 1 0 2 0 2 1 1 1 1 0 0 0 0 0 0 0 0 0 1 0 0 3 2 2 1 0 1 0 1 1 0 0 0 0 3 1 1 1 0 1 3 0 2 1 0 2 1 0 2 1 2 2 1 1 0 0 0 0 0 2 0 1 1 0 1 0 2 0 1 2 1 1 1 1 1 0 0 0 0 0 1 0 2 0 1 1 1 1 0 0 0 1 0 1 3 0 1 1 2 1 0 0 1 0 2 1 0 3 0 2 0 0 0 1 2 0 1 1 0 1 1 2 1 1 1 1 3 1 1 1 1 0 2 0 0 0 0 3 0 1 0 2 0 0 1 2 0 1 0 1 1 1 0 1 0 1 2 0 0 0 1 1 0 1 0 1 1 0 0 4 0 2 1 2 2 1 1 0 1 1 0 1 2 0 1 4 2 1 0 0 1 3 4 1 1 3 0 0 1 0 3 2 1 3 3 3 0 2 1 3 0 1 1 1 0 1 1 3 1 3 3 1 1 1 0 2 3 0 3 1 4 3 3 9 4 7 12 24 43 69 71 64 37 36 21 10 8 6 3 2 2 2 8 3 4 7 18 20 40 33 23 25 20 7 8 4 4 3 3 3 1 2 2 1 4 2 1 1 0 1 0 3 1 1 2 1 1 0 0 2 0 0 0 0 2 1 3 0 0 0 2 3 0 0 2 0 0 0 1 0 0 0 0 0 0 1 1 0 0 0 1 0 0 0 1 0 1 0 0 1 0 1 0 0 0 0 1 2 3 1 2 1 1 0 1 0 0 0 0 2 2 2 3 0 0 4 0 4 0 2 1 0 1 0 2 0 0 0 0 0 1 1 1 0 0 1 0 2 0 0 1 1 1 0 0 1 3 0 1 0 0 0 0 0 1 1 0 2 1 0 1 0 1 0 0 1 0 1 3 3 0 2 1 2 1 0 2 0 2 1 1 2 1 1 1 3 1 0 1 0 1 0 1 2 0 0 1 0 0 0 2 1 0 0 1 0 0 0 1 0 0 0 0 0 1 0 2 0 1 1 0 0 1 1 2 0 0 0 0 2 0 2 1 1 0 0 0 1 1 0 0 3 0 1 1 1 0 1 1 1 1 0 0 0 2 1 0 0 1 1 0 2 1 0 2 1 0 1 2 0 3 1 2 1 0 1 0 0 1 1 0 0 0 1 0 0 1 0 1 2 4 0 1 2 0 1 0 2 1 0 0 0 0 2 1 1 0 0 0 2 0 1 0 3 0 0 0 0 0 3 0 0 2 1 1 1 0 1 1 0 0 0 1 0 1 0 2 1 1 1 0 0 0 0 0 0 2 0 0 0 0 0 1 0 1 2 0 0 1 2 1 2 2 1 0 0 1 1 0 0 3 1 2 1 0 0 0 1 1 1 0 0 0 0 1 0 1 0 1 0 1 0 1 0 0 0 0 1 1 2 0 1 0 1 0 1 0 0 0 0 0 0 0 1 0 1 0 0 0 0 1 0 2 1 1 1 0 0 2 0 1 1 1 2 1 1 1 0 1 0 2 0 0 1 1 0 0 0 1 2 0 0 0 0 0 1 0 1 0 0 2 1 0 0 0 1 0 0 1 0 3 1 3 1 0 2 2 0 2 0 1 0 2 0 0 1 1 1 1 1 0 0 0 0 1 1 2 0 0 0 0 0 1 0 1 1 0 0 0 1 0 0 0 0 1 0 1 1 1 1 1 0 0 0 1 0 1 0 1 0 0 0 0 2 0 0 0 1 0 0 1 2 0 2 2 1 1 0 3 1 1 1 2 0 1 1 1 1 1 0 0 1 2 1 0 1 0 0 0 0 1 1 0 0 1 1 0 0 4 1 1 0 3 1 1 1 0 0 1 1 1 1 0 0 1 0 2 0 0 0 0 0 1 0 0 0 1 2 1 0 1 0 1 0 0 2 0 2 2 0 1 0 1 3 0 0 0 0 0 1 1 1 0 1 1 1 1 0 1 0 0 1 1 1 0 0 0 2 0 2 0 0 1 0 0 2 0 0 2 0 1 2 0 1 0 0 0 0 1 1 0 0 1 0 0 0 0 0 1 0 2 0 2 2 0 0 1 2 0 0 1 0 0 0 0 1 0 0 0 1 0 3 0 3 2 0 0 0 0 0 1 0 1 0 0 0 0 2 0 2 0 1 0 0 0 0 0 2 0 1 0 2 1 0 0 0 1 1 1 0 1 0 0 0 0 1 0 0 1 1 1 1 0 1 1 1 0 1 0 0 0 1 0 1 0 1 0 2 0 0 1 0 3 0 0 0 3 1 0 0 4 0 0 1 0 0 0 2 1 2 0 0 0 0 0 0 2 1 0 0 0 2 0 1 0 0 3 2 1 1 0 2 0 0 0 0 0 1 0 1 0 0 1 2 1 0 0 1 0 2 0 0 0 0 2 1 1 1 0 0 1 0 0 1 2 1 1 1 1 0 0 1 0 2 1 0 0 0 0 0 0 1 1 0 0 1 1 1 0 0 0 0 0 0 0 0 0 0 0 0 0 1 0 0 2 4 0 1 0 1 1 0 0 0 0 0 0 1 2 1 1 0 0 1 0 0 1 0 1 0 2 0 0 0 1 1 0 0 0 1 0 3 0 0 1 1 1 1 1 0 0 0 0 1 0 1 0 0 0 0 0 0 1 0 0 0 1 0 0 0 1 0 1 0 4 0 1 0 3 0 1 1 1 0 1 0 0 1 0 0 0 1 1 1 0 2 2 0 1 0 0 0 0 1 1 0 0 1 1 1 0 3 0 3 1 0 0 1 1 0 0 0 1 0 0 0 2 0 0 0 0 1 1 1 0 3 0 2 1 2 1 3 0 1 0 1 0 1 0 0 0 2 0 1 1 0 1 0 0 0 0 0 1 1 1 0 3 0 1 1 0 1 1 1 0 0 0 0 0 0 0 1 0 0 0 1 0 0 0 1 0 0 1 0 0 0 0 0 2 0 1 3 0 0 1 0 0 0 0 0 0 0 0 0 1 0 1 0 0 0 0 0 2 0 1 0 0 0 1 0 2 0 1 0 2 0 0 0 0 0 0 0 0 0 1 1 1 0 0 0 0 0 0 0 1 0 0 0 0 1 0 0 1 0 1 0 0 0 0 0 0 0 0 1 2 0 2 2 0 1 0 1 0 0 1 1 1 3 0 0 0 2 0 0 1 1 1 0 1 0 0 1 0 1 0 0 2 1 0 0 1 0 1 0 0 1 0 0 0 1 0 2 0 1 0 0 0 0 1 0 0 0 1 0 0 1 0 0 0 0 2 0 0 0 0 0 0 1 1 0 1 0 0 1 0 0 0 0 0 1 1 0 2 0 0 0 0 0 0 0 0 1 0 1 0 0 0 0 0 0 1 0 0 0 0 1 1 0 0 0 0 1 0 0 0 1 0 0 0 1 1 0 1 0 1 0 1 0 1 0 2 1 0 0 0 0 0 0 0 0 2 0 0 1 0 0 0 1 0 0 0 0 1 2 0 0 0 0 2 0 1 0 0 0 3 0 1 0 1 0 1 0 1 0 0 0 0 0 1 0 1 1 0 0 2 0 2 1 1 0 1 0 0 1 0 0 2 0 1 0 0 1 0 0 1 0 1 0 0 0 2 0 1 0 0 0 0 0 1 0 1 0 0 0 1 0 1 0 0 0 0 1 0 0 0 0 0 0 0 0 1 2 0 0 2 0 1 2 0 0 0 0 0 0 0 1 0 0 0 0 1 0 1 1 0 0 0 1 0 1 0 0 0 0 3 0 0 1 1 0 1 1 0 0 1 1 1 2 0 0 1 0 1 0 0 1 1 1 0 1 0 0 1 0 0 0 0 1 2 1 0 0 0 0 0 1 0 0 1 0 1 0 0 0 0 0 0 1 0 0 0 0 0 0 0 0 2 0 0 0 0 0 0 1 0 0 0 2 1 0 2 1 0 0 1 1 0 0 0 0 2 0 1 0 1 0 1 0 1 0 1 0 0 0 1 1 0 0 1 0 0 0 0 0 0 1 0 0 1 1 0 1 1 0 1 1 1 0 0 1 0 0 2 1 0 0 0 0 0 0 0 0 0 0 2 0 0 1 0 0 1 0 0 0 1 0 0 1 2 1 1 0 0 1 0 0 0 0 1 2 1 1 0 1 1 0 0 0 0 0 1 0 0 1 0 1 0 0 0 1 0 0 1 2 0 1 0 0 0 0 0 0 0 1 0 1 0 1 0 1 0 0 1 0 1 0 1 0 0 1 2 1 0 0 1 0 0 3 0 0 0 0 0 0 0 0 1 0 0 1 0 1 0 0 0 0 0 0 0 0 1 0 0 2 0 0 1 2 2 0 0 1 0 0 0 1 0 0 3 0 1 1 0 1 0 0 0 0 1 0 1 1 2 0 1 2 2 0 1 0 0 0 1 1 0 1 0 0 0 0 1 0 1 0 1 0 0 0 0 1 0 1 0 1 1 0 1 0 0 0 0 0 1 0 0 0 0 1 0 0 0 1 0 1 0 0 1 0 0 3 1 0 0 0 0 0 0 0 1 0 1 0 1 0 0 1 0 1 0 0 1 2 1 1 0 0 1 1 0 0 1 0 1 0 0 0 0 0 1 1 1 0 1 0 0 0 1 1 0 1 1 2 1 1 1 1 0 1 1 0 1 0 0 0 0 2 1 0 0 2 1 0 1 0 0 0 0 1 0 0 1 0 0 1 0 0 1 1 2 2 0 0 1 1 1 0 0 0 0 0 1 0 0 1 0 1 1 1 1 1 1 1 1 1 0 1 0 1 1 0 1 0 0 1 0 1 0 0 0 0 0 0 0 0 1 0 0 0 0 0 0 0 1 0 1 0 0 0 0 0 0 2 0 1 1 0 0 1 1 0 1 0 0 0 0 0 0 1 0 0 0 2 0 0 0 0 0 0 0 1 0 1 0 1 1 0 0 0 0 1 2 1 1 1 1 0 0 1 0 1 0 1 0 1 0 0 0 0 1 0 0 1 0 1 0 0 0 1 1 1 0 0 2 0 0 0 2 0 0 1 1 0 0 2 0 2 1 0 0 1 0 1 4 0 1 1 0 0 0 0 1 1 0 0 3 1 2 1 0 1 1 2 1 1 1 1 0 1 0 0 0 0 0 1 0 0 1 1 0 0 0 0 2 0 0 1 0 0 0 0 0 0 0 0 0 1 1 1 0 0 0 1 1 0 0 0 0 1 0 0 0 2 0 0 0 0 0 0 0 0 4 0 0 1 1 0 0 1 0 0 2 0 0 1 0 1 0 0 1 1 1 0 1 0 0 0 0 0 0 0 0 2 0 0 0 0 1 1 0 0 0 0 0 0 0 0 0 1 0 0 0 0 0 1 1 0 1 1 1 0 0 1 0 0 2 1 0 1 0 0 0 0 1 1 0 0 2 0 0 0 0 2 0 1 0 0 1 0 0 0 1 2 1 1 1 0 0 1 0 0 0 0 0 0 0 0 0 0 0 1 1 0 0 0 0 1 0 0 0 0 0 0 0 1 0 0 0 1 0 0 0 0 0 1 0 0 1 0 1 0 0 1 0 0 1 1 2 1 0 1 0 0 0 0 1 1 0 1 0 1 1 1 1 0 1 0 1 0 0 0 1 1 2 0 1 2 0 0 0 0 0 0 0 1 0 1 0 0 1 0 0 0 0 0 1 0 0 0 2 0 0 0 0 0 0 0 1 1 0 0 0 0 0 0 0 0 1 0 1 0 0 0 0 0 0 0 1 0 0 1 0 0 0 0 0 0 0 0 1 0 0 0 0 0 1 1 1 0 0 0 1 0 1 1 0 0 0 0 0 0 0 0 0 0 1 0 1 0 0 0 0 0 0 2 0 1 1 0 1 0 0 0 1 0 0 0 0 0 2 0 0 1 0 0 0 0 0 0 0 0 0 0 0 0 1 0 0 0 0 0 0 1 0 1 0 0 1 1 0 1 0 0 0 0 0 0 1 0 1 2 0 1 0 0 0 0 0 0 0 0 1 0 0 0 0 0 0 0 0 0 0 0 0 0 0 0 0 0 0 0 0 0 0 0 0 0 1 0 1 0 0 1 1 1 2 0 0 0 0 0 2 0 1 0 1 0 1 0 0 0 0 0 2 1 0 1 0 0 0 0 0 0 0 0 0 0 1 0 0 0 0 0 1 0 0 0 0 0 0 0 1 0 1 0 0 0 0 2 1 0 0 0 0 0 0 0 0 1 1 0 0 1 0 0 1 1 1 0 0 0 0 2 0 0 0 0 1 0 0 0 0 0 0 0 0 0 0 1 0 0 0 0 0 0 0 0 0 0 0 0 0 0 1 0 0 1 0 1 1 0 0 0 0 0 0 0 0 0 1 0 1 0 0 0 1 0 0 0 0 0 0 1 0 2 0 0 1 0 0 0 2 0 0 0 0 0 0 0 0 0 0 0 0 0 0 0 0 0 0 0 0 2 1 0 0 0 0 1 0 0 0 0 1 0 0 1 1 1 0 1 1 0 0 2 1 1 0 0 0 0 0 2 0 1 0 1 0 0 0 0 0 0 0 0 0 0 0 0 0 0 0 1 0 2 0 1 0 0 0 0 0 1 0 3 0 1 0 0 0 0 0 1 1 0 0 0 0 0 1 1 1 1 2 0 0 0 0 0 0 0 0 1 2 0 0 0 1 0 1 3 0 1 1 0 0 0 0 1 1 1 0 0 0 0 1 0 0 0 0 0 1 0 0 2 0 0 0 0 0 0 0 1 1 0 1 1 1 0 0 0 0 0 0 0 0 0 0 0 0 1 1 0 1 0 0 1 0 0 0 1 0 1 0 0 0 0 0 0 2 0 0 1 0 0 0 0 0 0 0 0 0 0 0 0 1 0 1 0 1 0 0 0 0 1 0 0 0 0 1 0 0 0 1 0 0 1 0 1 0 1 1 0 0 0 1 0 0 0 0 0 1 0 0 1 0 0 0 1 0 0 0 0 1 0 0 1 0 0 0 0 0 0 0 0 1 0 0 0 1 0 0 0 2 0 0 1 0 0 2 2 0 0 0 0 0 0 1 0 0 1 1 0 0 3 1 1 0 1 0 0 0 1 1 0 0 1 2 1 3 2 1 1 0 1 0 0 0 0 1 1 0 0 0 2 1 3 2 3 3 1 4 2 1 0 1 1 3 4 4 4 6 4 6 6 9 6 4 4 2 0 6 2 1 1 3 2 0 1 1 0 0 0 0 0 2 0 1 0 2 0 3 0 1 0 0 0 3 1 3 1 0 1 0 2 0 1 2 0 1 1 3 1 0 0 0 2 0 1 0 0 0 1 0 2 0 0 0 2 2 1 0 0 3 3 2 1 0 1 0 2 0 2 2 1 0 0 1 2 3 1 0 1 0 1 0 1 0 1 0 0 1 1 1 1 2 2 0 1 3 1 1 0 1 0 0 2 0 1 1 2 2 0 0 1 0 0 1 0 1 1 2 0 0 0 1 1 0 0 0 0 0 2 0 0 1 0 0 1 1 0 0 2 2 2 0 2 0 1 0 1 0 1 1 0 0 0 2 2 0 1 0 0 0 1 1 1 0 0 0 1 0 1 2 0 0 0 0 1 0 0 1 1 1 0 0 0 0 0 0 1 0 2 1 1 2 1 0 0 0 0 0 1 0 2 0 0 0 0 0 1 1 1 0 2 0 0 0 1 0 0 0 1 1 0 1 1 0 3 0 0 0 0 0 1 0 0 0 0 0 0 1 1 0 1 0 0 1 0 0 0 0 0 0 0 0 1 1 1 1 0 1 1 0 0 0 1 0 1 0 1 0 0 0 0 1 0 1 0 0 1 1 0 0 0 0 0 1 1 0 0 0 1 0 0 0 0 1 1 0 0 1 1 0 1 0 0 1 0 0 0 0 0 0 1 0 1 1 0 2 1 0 0 2 0 0 0 1 0 0 0 0 1 0 0 0 1 0 0 0 0 0 0 1 1 0 0 0 0 0 2 0 0 1 2 0 0 0 1 0 1 0 0 0 0 2 1 0 0 0 0 0 0 1 1 1 0 0 0 0 0 0 0 0 0 0 0 0 0 1 1 2 0 1 0 1 0 0 0 0 1 0 0 0 0 0 0 0 0 0 0 0 0 0 0 0 1 0 0 0 0 0 0 1 0 0 0 1 1 0 0 0 0 1 1 1 0 0 0 0 0 0 1 1 0 1 0 0 1 0 0 0 0 0 3 0 0 1 0 0 2 0 0 0 1 0 0 1 1 0 1 0 0 0 1 0 0 0 0 0 0 0 0 1 1 0 0 1 0 1 0 0 1 0 0 0 0 1 0 0 0 0 0 1 0 0 0 1 2 0 1 0 0 0 0 0 0 1 0 0 1 0 2 0 0 0 0 2 0 0 0 1 0 1 1 3 0 0 0 1 0 0 0 0 0 1 0 1 0 0 0 0 0 0 0 1 0 1 0 0 1 0 2 0 0 0 0 0 0 1 0 0 0 0 0 0 0 1 0 0 0 0 1 0 0 0 0 0 0 0 0 0 1 0 0 0 0 0 0 0 0 0 3 0 0 0 0 0 0 0 1 1 1 0 0 0 0 1 0 0 0 1 0 0 0 0 0 0 1 0 0 0 1 0 1 0 3 0 0 0 2 1 0 0 0 1 0 0 0 2 0 1 0 0 0 0 0 1 0 1 0 2 0 0 0 2 0 0 0 1 0 1 1 0 0 1 1 0 0 0 0 0 0 0 1 0 0 0 0 0 0 0 0 0 0 0 1 0 1 0 0 1 1 0 2 0 0 1 1 1 0 0 0 0 1 0 0 1 1 1 1 2 1 2 0 1 1 2 0 2 0 0 0 0 0 0 0 0 0 0 0 1 2 0 1 0 0 0 0 1 0 1 0 2 0 0 0 0 0 0 0 0 0 0 1 0 0 0 0 0 1 0 0 1 0 1 0 0 0 0 0 0 1 0 1 2 0 1 0 2 0 1 1 0 1 0 2 2 1 0 1 0 2 0 0 1 0 0 0 0 0 0 0 0 1 0 1 1 0 1 0 0 1 0 0 1 0 2 0 0 0 0 0 2 0 2 1 0 0 0 1 2 1 0 0 0 1 0 2 0 3 2 1 1 2 0 0 2 0 2 2 1 0 3 7 0 2 4 1 2 2 1 2 3 3 4 1 2 1 4 4 3 1 6 2 2 3 1 4 0 3 1 12 0 4 2 2 7 3 3 1 2 4 3 3 1 6 4 2 2 2 1 3 2 4 3 0 0 3 1 4 3 1 3 4 2 0 1 1 1 1 2 4 2 3 1 1 1 0 4 4 1 2 0 6 4 2 1 2 3 1 2 2 2 2 2 0 6 1 3 1 2 4 3 0 4 1 4 1 6 0 3 2 3 2 0 2 2 3 0 0 4 6 1 2 2 3 3 2 0 3 2 2 2 2 0 6 2 4 1 3 2 3 2 2 7 1 1 2 6 3 2 2 1 7 1 1 3 6 1 2 6 1 2 2 0 4 2 4 4 1 2 2 3 2 2 1 2 3 8 2 1 4 2 1 3 3 2 2 1 6 2 1 4 6 7 4 2 1 2 0 2 7 3 1 4 1 2 1 3 3 3 4 3 3 0 3 2 1 3 0 4 2 3 1 6 2 2 2 1 6 3 1 3 2 3 6 2 0 0 3 4 2 2 2 2 3 2 2 3 4 6 8 3 3 1 2 7 1 2 3 4 3 6 2 2 1 7 0 2 2 3 3 2 4 3 2 6 4 1 4 6 2 1 6 3 3 3 1 1 6 2 4 2 1 3 2 6 2 4 2 3 4 3 7 2 2 7 3 1 7 2 6 3 2 4 3 4 2 3 1 4 4 2 3 2 3 3 2 3 8 7 2 8 3 4 6 2 3 7 6 6 3 3 1 2 3 6 3 7 7 2 4 3 3 2 6 6 3 2 6 7 6 10 6 8 7 10 3 7 2 7 6 3 7 6 2 3 4 8 9 3 9 2 1 7 9 9 9 4 6 4 13 8 4 7 3 4 6 7 4 8 4 4 7 9 4 6 7 12 7 6 10 4 7 8 8 9 2 14 10 15 23 16 10 14 15 18 19 14 14 24 20 16 23 35 21 19 20 20 23 36 27 23 16 16 32 35 32 24 35 29 29 24 23 20 37 27 27 26 25 37 36 25 26 29 35 32 35 29 29 33 36 33 52 50 55 69 66 80 67 70 99 129 124 134 151 168 169 218 241 284 334 377 537 672 880 1228 1815 2628 3300 3725 3625 3060 2443 1825 1398 1058 802 575 493 386 330 266 242 189 153 175 150 140 140 136 110 129 118 147 186 192 201 229 269 327 430 550 715 975 1196 1446 1598 1668 1612 1329 1133 854 666 514 395 307 272 201 147 166 116 112 95 71 93 76 72 52 69 40 54 44 35 23 44 37 31 27 24 30 15 21 23 23 24 29 27 16 21 13 23 14 21 16 16 19 16 9 9 16 20 21 10 13 19 6 16 19 10 10 13 10 13 10 15 7 9 10 12 9 8 7 14 12 10 6 9 12 8 6 14 8 13 8 4 9 12 10 6 6 6 8 10 7 7 4 12 1 3 4 8 2 4 4 8 8 4 3 8 10 4 4 2 1 7 3 3 2 2 2 6 3 3 6 7 6 9 7 9 4 6 3 6 6 2 3 4 6 4 10 2 3 6 9 4 3 6 4 1 9 6 6 3 2 4 8 2 7 2 6 8 6 2 1 4 3 4 3 4 4 9 4 4 1 7 2 2 2 2 4 7 4 3 6 4 3 4 1 3 1 0 2 2 2 2 3 2 4 3 6 7 2 3 3 3 1 9 3 3 2 3 4 6 1 6 3 4 1 1 3 2 2 6 1 2 3 3 1 0 0 7 1 3 2 6 3 1 1 1 2 2 1 0 3 2 2 2 1 1 2 4 1 1 0 3 3 1 0 1 6 4 1 0 2 2 2 4 3 1 2 3 4 7 2 1 2 3 1 3 1 4 4 3 3 2 3 3 1 2 1 3 2 6 3 0 3 1 2 2 2 2 4 2 1 2 2 1 3 0 3 1 6 1 4 0 0 1 0 4 1 0 0 3 3 1 4 3 2 3 1 1 7 4 2 1 6 2 1 8 1 6 4 0 1 1 2 1 0 1 0 2 3 2 2 1 1 3 4 1 2 3 3 2 2 0 3 3 0 1 4 3 1 8 1 2 4 2 4 0 0 4 4 1 1 2 1 2 1 1 2 1 1 2 0 2 1 2 2 4 1 3 4 2 2 1 8 1 0 1 1 1 0 3 2 2 0 0 1 0 2 3 3 0 6 1 6 2 1 2 2 2 3 6 3 2 1 0 1 0 2 3 1 6 3 3 2 3 3 0 2 2 0 2 0 2 0 1 1 3 0 0 4 1 0 2 3 1 2 2 1 2 3 1 1 1 2 1 0 3 2 1 3 1 1 2 1 3 2 2 1 2 2 3 3 0 3 1 3 0 1 1 4 0 1 1 2 3 0 2 0 2 0 1 1 2 1 1 0 0 0 1 1 4 2 1 2 3 2 0 2 0 0 3 0 0 1 3 3 0 2 2 4 2 0 4 0 2 3 2 2 4 1 1 0 1 2 0 1 0 6 3 1 1 1 1 1 2 1 1 2 1 1 0 0 1 1 0 2 1 4 0 2 2 1 1 0 3 3 0 1 1 1 0 2 0 1 4 2 2 0 6 0 3 4 1 3 1 4 0 2 3 2 2 4 4 1 1 1 1 4 1 1 3 3 3 1 2 3 2 2 0 0 1 1 1 0 3 1 2 1 2 4 2 0 3 1 2 0 1 3 4 2 1 2 2 1 1 3 1 2 1 2 0 2 0 1 2 1 3 0 0 2 2 6 1 3 1 1 7 0 0 2 2 1 0 1 1 1 4 0 2 1 1 1 2 3 1 3 0 0 2 0 0 2 1 2 0 2 2 2 3 1 0 1 3 2 1 0 2 1 3 3 0 0 1 1 1 3 3 1 1 0 0 1 1 1 1 1 3 0 1 3 0 2 1 2 2 0 2 2 1 2 2 2 2 2 2 3 0 2 1 2 3 0 0 2 0 0 1 3 3 2 1 0 2 1 1 3 0 1 3 4 0 0 2 1 0 1 2 2 1 1 1 2 0 0 3 1 6 3 3 1 2 1 3 3 1 1 1 3 3 1 4 2 2 2 0 1 2 3 0 2 1 0 0 1 7 3 1 0 1 4 1 3 1 0 0 2 1 4 3 7 0 0 0 6 2 2 4 0 1 2 1 1 0 2 1 1 1 0 0 3 3 0 0 1 2 0 1 1 2 0 1 1 2 2 1 1 3 0 0 1 1 3 1 1 2 3 2 0 0 0 2 2 1 7 3 3 2 1 2 2 2 1 2 1 1 0 1 1 2 2 0 4 2 0 0 1 2 2 0 2 0 2 2 2 1 0 1 1 0 3 2 1 2 1 2 1 2 1 1 1 2 0 0 2 3 1 1 1 0 2 1 1 1 1 1 2 0 1 1 3 1 2 1 1 1 2 3 1 0 1 0 1 1 1 1 3 3 1 2 2 1 2 0 2 0 0 0 0 1 1 1 3 1 0 0 1 2 1 3 3 3 3 0 1 0 2 0 2 0 2 0 0 6 1 0 4 2 1 0 1 3 0 1 6 3 1 0 2 2 1 1 1 0 2 1 1 3 2 2 1 0 1 0 2 2 1 0 4 0 1 0 2 1 0 0 1 0 2 3 1 1 3 1 0 0 0 2 0 1 3 0 1 0 0 1 0 0 3 0 2 1 2 2 2 1 0 2 0 4 2 1 1 2 3 0 1 0 0 0 1 2 1 0 2 3 0 1 3 1 1 3 0 2 1 0 1 0 4 0 0 0 0 3 1 2 1 2 1 0 2 0 3 2 1 1 1 3 1 0 1 4 1 0 4 3 8 0 0 1 1 1 1 0 3 1 2 2 1 3 2 1 3 1 1 0 1 1 2 2 0 0 3 0 1 1 0 1 0 3 1 0 1 1 2 1 2 1 3 1 3 2 1 1 0 1 1 2 0 1 0 0 1 0 1 1 2 4 2 1 1 2 2 1 2 0 1 1 0 1 1 0 1 2 2 1 1 0 1 1 1 3 1 2 0 2 0 1 0 3 2 1 1 0 0 1 1 1 1 3 2 2 1 1 0 2 4 1 1 2 0 1 1 0 2 0 0 0 1 2 0 3 2 0 0 2 0 1 1 2 1 0 0 2 0 0 2 1 0 0 1 1 0 1 0 2 1 2 0 0 2 1 0 0 1 1 1 1 1 1 1 2 2 1 0 2 0 3 0 1 1 1 1 0 0 1 1 0 0 2 1 1 1 0 0 1 0 0 2 1 1 0 1 0 0 2 1 1 0 0 0 0 1 1 1 2 1 2 1 1 0 0 2 1 0 0 0 0 1 0 0 2 2 1 1 3 1 0 3 1 0 1 1 2 2 2 2 1 1 1 1 1 2 2 2 2 0 0 0 0 2 2 0 1 2 1 1 4 1 0 0 2 1 3 2 0 0 1 0 0 3 0 0 2 1 1 0 0 0 2 2 4 2 1 1 0 1 2 2 0 1 0 0 2 0 1 1 0 2 1 2 2 3 1 1 1 3 0 0 1 2 2 2 0 0 0 1 3 0 1 3 2 0 2 3 0 2 0 1 0 1 1 0 0 0 1 0 2 2 1 0 0 2 0 0 1 2 1 1 0 0 1 3 3 1 3 2 0 0 1 0 0 1 0 1 1 1 1 0 1 0 1 2 1 0 1 1 0 0 2 0 1 3 1 1 0 1 0 0 1 1 0 2 1 0 3 0 3 0 6 0 2 7 1 3 3 0 2 1 0 1 1 0 1 0 3 2 0 0 1 0 1 2 0 0 1 1 2 0 1 1 2 3 1 1 2 0 1 0 0 0 0 1 1 1 0 1 1 0 2 2 1 0 1 0 0 1 0 0 0 1 0 0 2 0 1 0 0 0 1 2 1 2 0 0 0 1 1 1 3 1 1 0 0 3 1 0 1 0 2 2 2 0 1 0 2 0 1 1 1 2 3 1 2 2 0 0 0 2 2 1 2 1 0 0 0 2 0 6 0 1 1 1 2 0 1 1 0 0 0 3 3 2 0 0 0 2 0 1 1 1 2 0 2 2 2 0 0 2 0 0 1 1 0 2 1 2 2 0 1 0 1 0 0 0 0 2 0 2 1 1 2 2 2 0 0 0 0 2 0 2 1 1 0 2 1 0 1 0 0 0 1 0 0 3 0 0 0 1 2 0 1 0 1 1 1 2 1 1 1 0 2 3 1 0 1 0 2 1 1 0 0 1 2 2 1 1 0 2 0 0 0 1 0 1 1 2 1 0 0 1 0 1 2 2 0 2 1 1 0 1 2 2 1 1 4 1 0 2 1 0 1 2 1 0 0 3 1 0 1 1 0 1 2 0 1 0 0 1 1 3 1 0 0 0 0 0 2 2 0 2 1 0 2 1 0 0 1 0 0 1 1 0 2 1 0 1 0 1 0 0 1 0 0 1 0 0 1 0 1 1 0 1 2 0 0 0 0 2 0 0 1 3 0 1 0 0 0 1 0 2 0 0 1 2 0 1 1 0 1 1 0 0 3 0 0 1 1 0 0 0 0 0 2 1 0 2 0 2 0 0 0 1 1 0 0 1 1 2 1 1 1 2 0 0 2 0 0 2 3 0 1 1 0 0 0 1 0 0 0 0 1 1 1 2 0 0 0 1 2 2 4 1 0 2 2 2 0 1 0 0 0 1 1 3 3 2 1 1 1 0 0 0 1 0 2 0 2 1 0 4 1 0 0 0 0 1 0 0 1 0 2 0 1 0 0 1 0 3 2 1 0 3 0 0 0 0 1 1 1 2 0 3 0 0 1 0 0 0 0 0 1 2 1 1 1 0 0 1 1 0 0 0 1 0 1 1 0 0 0 2 0 1 0 1 0 1 0 1 0 1 3 0 0 0 1 0 0 1 0 1 1 1 1 0 1 0 2 0 1 0 0 0 0 0 1 0 0 2 0 1 2 0 0 1 1 0 1 0 1 0 1 1 1 0 1 1 2 0 0 1 0 0 0 1 1 0 2 0 1 0 1 6 2 0 1 0 0 0 1 0 2 0 0 2 0 0 1 0 0 0 0 2 2 0 2 0 0 0 0 0 1 0 0 0 2 0 2 1 1 0 0 0 0 1 2 0 1 1 1 1 1 2 1 0 1 0 0 0 0 1 1 1 1 0 0 1 1 1 2 1 4 2 0 0 1 0 3 1 1 1 1 0 0 1 1 0 0 0 0 1 0 0 2 0 1 2 1 1 0 0 0 1 1 1 2 0 1 0 0 1 3 0 1 1 3 0 0 2 0 0 1 1 1 1 1 0 0 0 3 1 0 1 1 3 2 0 2 1 1 0 1 1 0 0 0 0 0 0 1 0 1 1 1 3 2 0 1 0 0 0 0 0 2 0 0 0 3 0 1 1 4 1 1 3 0 0 1 0 1 0 0 3 1 2 2 1 1 0 0 0 0 0 2 0 2 0 0 0 0 1 1 0 0 0 2 0 2 1 0 1 1 2 0 1 0 0 1 0 0 1 0 0 0 3 0 2 0 0 2 0 0 0 3 1 1 0 2 1 2 1 0 2 1 2 1 0 0 1 1 0 1 0 1 1 1 0 1 2 1 0 0 3 0 0 0 0 3 0 1 1 2 0 0 0 1 0 2 0 0 1 0 1 0 2 1 1 0 1 2 1 1 1 1 0 1 3 0 2 0 0 0 1 0 0 1 0 1 0 2 0 2 1 0 2 1 0 0 1 0 0 0 0 1 0 1 0 0 1 2 1 2 1 2 1 0 1 0 0 1 0 0 0 0 0 0 0 1 0 0 0 2 2 2 0 1 1 1 4 0 1 1 2 0 1 0 0 0 1 0 2 1 0 0 0 1 1 1 0 0 0 0 1 2 1 0 0 0 0 1 2 1 0 1 1 0 0 0 0 0 1 0 0 0 1 0 0 0 0 0 0 1 0 1 1 0 0 1 0 1 1 2 1 2 0 0 2 1 1 0 2 0 1 0 1 1 1 0 0 2 1 1 1 1 0 1 0 1 1 2 0 0 0 0 1 2 1 2 1 0 0 2 0 1 1 0 0 1 0 0 0 0 1 0 0 1 1 1 0 0 2 1 0 0 1 1 2 3 2 1 0 1 1 4 2 0 1 0 1 0 1 3 1 0 1 1 2 1 2 0 1 1 3 0 0 0 0 1 2 0 0 1 2 1 0 0 0 1 1 1 1 0 0 2 0 0 0 0 0 0 0 1 0 0 0 2 2 1 1 0 0 1 0 1 0 0 1 0 0 1 0 1 1 0 2 0 0 0 1 0 0 1 1 1 0 0 0 0 1 1 0 2 0 1 1 0 0 0 1 1 0 1 0 0 0 1 0 1 0 0 0 1 1 2 0 0 1 1 1 2 1 0 0 1 0 3 0 0 0 0 0 0 2 0 0 0 0 1 0 0 2 2 1 2 1 1 2 2 1 0 1 2 0 0 1 0 0 1 0 1 1 0 0 0 0 0 1 1 0 2 0 0 1 1 0 2 0 1 2 0 0 0 1 2 0 0 0 0 0 0 1 1 0 1 1 1 0 1 2 1 2 1 1 0 0 0 1 1 0 0 1 1 0 0 0 0 1 0 0 1 0 0 0 0 1 2 0 1 2 0 0 0 0 0 0 0 0 0 1 1 0 0 1 0 1 0 0 2 0 3 0 2 1 0 0 2 1 2 1 2 0 1 1 1 1 2 0 1 1 1 0 0 1 2 1 2 0 1 0 0 0 1 0 0 1 2 1 0 0 0 1 1 0 2 0 1 0 0 1 2 0 2 0 0 0 1 1 0 0 0 3 0 2 0 1 0 0 1 0 0 0 3 0 2 1 0 0 0 0 0 1 0 1 0 0 0 0 1 1 1 1 0 0 1 1 0 0 1 1 0 0 0 0 0 1 0 0 1 2 0 0 0 1 2 0 2 0 0 1 0 0 0 2 1 2 1 1 0 1 1 2 0 0 2 1 1 0 0 1 2 1 0 0 0 2 0 0 0 0 3 0 0 2 1 0 0 0 0 0 0 0 3 0 1 0 0 0 1 0 2 0 1 0 0 3 0 0 0 2 1 0 1 0 0 1 1 0 1 1 0 0 1 0 2 1 1 1 3 1 0 2 0 0 1 1 1 0 3 0 0 1 1 1 0 0 1 1 0 1 1 2 1 3 0 1 1 1 0 1 1 0 0 1 1 0 2 1 0 0 0 1 1 1 0 0 0 0 0 0 0 0 0 0 2 0 0 1 1 0 0 2 1 1 0 0 0 1 1 0 0 0 0 0 0 1 1 0 0 0 1 0 2 0 1 1 0 0 0 1 1 0 0 2 0 1 1 1 0 1 0 0 0 2 0 0 0 0 1 0 1 0 0 1 0 0 1 1 1 0 2 1 0 0 0 1 2 0 0 0 0 0 1 1 1 0 1 0 0 0 0 0 2 0 0 0 0 1 1 1 0 0 0 1 1 0 0 0 0 0 1 1 2 0 2 2 0 0 0 0 0 1 1 0 0 1 2 1 0 3 0 0 0 0 1 0 0 1 0 0 0 2 0 0 1 0 1 1 0 1 0 0 0 0 0 1 0 1 1 0 0 0 0 2 0 1 0 0 1 1 0 1 0 0 0 0 1 0 0 1 0 1 1 0 0 2 1 2 0 1 0 0 0 0 1 0 0 0 1 0 0 0 0 0 0 3 1 0 0 0 2 0 0 2 0 1 0 1 0 1 2 0 0 0 0 1 2 0 1 0 0 0 0 0 0 0 0 0 0 2 0 0 0 0 1 0 2 0 1 0 1 0 1 3 0 0 1 0 2 1 0 0 3 0 0 0 1 0 1 2 1 1 0 0 0 2 2 0 1 1 0 0 1 0 1 0 1 1 0 0 0 1 1 0 1 0 0 3 2 1 1 0 0 0 1 0 1 2 1 0 1 0 2 0 0 0 1 1 1 1 1 1 0 0 0 0 0 0 1 0 2 0 0 0 0 1 2 2 0 1 2 0 1 0 2 0 0 0 0 0 0 1 0 0 0 0 0 2 0 1 0 0 0 0 1 1 0 1 0 0 1 1 1 0 1 0 0 1 1 0 2 1 0 0 0 2 2 1 0 1 0 0 1 0 0 0 0 0 0 1 2 0 0 1 1 1 0 1 3 3 2 1 2 2 0 0 1 3 1 4 3 2 1 1 0 1 2 1 1 2 0 0 0 3 1 1 2 2 2 2 0 4 1 2 3 2 0 3 2 2 3 2 2 2 2 6 3 3 4 0 4 6 6 4 3 1 4 3 3 4 3 9 3 1 4 8 10 6 9 4 8 3 8 6 2 9 4 4 3 3 3 2 1 2 0 4 4 3 1 3 2 2 4 0 1 1 1 4 1 1 1 2 1 1 3 2 1 3 3 0 1 1 3 2 1 3 1 3 1 2 1 3 0 1 1 2 3 3 4 0 3 2 1 2 0 3 1 0 0 1 0 3 1 1 0 1 2 2 0 1 3 1 0 3 3 2 1 0 2 0 1 2 2 2 0 0 2 2 2 1 0 1 3 4 1 2 1 1 0 1 3 1 1 0 2 1 1 0 1 1 2 1 1 1 1 4 1 1 1 2 3 1 2 3 1 2 1 1 1 1 2 1 1 1 1 0 1 1 0 0 3 1 1 0 1 1 1 0 0 3 0 2 0 1 2 0 0 0 2 0 0 1 0 2 2 3 1 2 1 0 2 1 1 1 0 1 0 0 2 0 1 0 1 0 0 0 1 0 0 1 1 0 0 0 0 0 3 2 1 0 1 0 0 2 1 0 2 0 1 0 1 0 0 0 0 1 0 1 0 0 0 0 0 0 0 2 1 0 1 1 0 1 0 0 0 1 0 0 1 0 1 1 1 1 0 2 2 1 0 2 0 0 0 1 1 0 0 0 0 0 0 1 0 1 1 0 0 0 1 2 0 0 0 1 2 0 1 0 2 1 0 1 0 1 0 0 1 0 0 2 0 1 1 0 2 0 0 0 1 0 3 0 0 0 0 1 0 1 1 1 0 0 0 0 1 0 0 0 1 0 0 0 0 0 0 1 2 1 0 0 0 1 0 1 1 2 0 1 1 1 1 0 1 1 1 1 0 0 0 0 0 0 0 2 0 3 2 0 0 0 1 0 0 0 1 1 0 0 0 1 0 1 1 1 0 0 0 1 0 0 0 0 0 1 1 1 1 0 2 0 0 0 1 0 0 1 1 1 0 1 1 0 3 2 0 0 0 0 1 0 0 1 1 0 2 0 0 0 0 1 0 0 0 0 0 0 1 1 0 0 0 0 2 0 2 0 1 0 0 0 0 0 0 1 1 0 0 0 1 1 0 0 0 1 3 0 1 1 1 1 0 1 0 0 0 1 0 3 0 1 2 1 0 0 0 0 1 0 1 1 0 0 0 0 0 1 0 0 0 1 1 1 0 1 1 0 1 0 2 0 0 1 0 1 0 0 0 0 0 0 0 0 2 0 0 0 0 1 1 1 1 1 0 0 0 0 0 0 1 1 0 0 0 0 0 1 0 0 0 1 1 0 0 1 1 1 0 0 2 1 1 4 0 0 1 1</intensities>
			</dataPoints>
		</scan>
	</xrdMeasurement>
</xrdMeasurements>