File: Roentgen/Messdaten/Si111_40_10.xrdml
<?xml version="1.0" encoding="UTF-8"?>
<xrdMeasurements xmlns="http://www.xrdml.com/XRDMeasurement/1.3" xmlns:xsi="http://www.w3.org/2001/XMLSchema-instance" xsi:schemaLocation="http://www.xrdml.com/XRDMeasurement/1.3 http://www.xrdml.com/XRDMeasurement/1.3/XRDMeasurement.xsd" status="Completed">
	<comment>
		<entry>huhuu</entry>
		<entry>Configuration=stage XYZ Phi Psi, Owner=User-1, Creation date=17.03.2006 13:32:17</entry>
		<entry>Goniometer=PW3050/60 (Theta/Theta); Minimum step size 2Theta:0.001; Minimum step size Omega:0.001</entry>
		<entry>Sample stage=IR Stage (Phi, Tilt, X, Y, Z)</entry>
		<entry>Diffractometer system=XPERT-PRO</entry>
		<entry>Measurement program=FP, Owner=User-1, Creation date=18.04.2011 15:14:00</entry>
	</comment>
	<sample type="To be analyzed">
		<id></id>
		<name></name>
		<preparedBy></preparedBy>
	</sample>
	<xrdMeasurement measurementType="Scan" status="Completed" sampleMode="Reflection">
		<comment>
			<entry/>
		</comment>
		<usedWavelength intended="K-Alpha 1">
			<kAlpha1 unit="Angstrom">1.5405980</kAlpha1>
			<kAlpha2 unit="Angstrom">1.5444260</kAlpha2>
			<kBeta unit="Angstrom">1.3922500</kBeta>
			<ratioKAlpha2KAlpha1>0.5000</ratioKAlpha2KAlpha1>
		</usedWavelength>
		<incidentBeamPath>
			<radius unit="mm">240.00</radius>
			<xRayTube id="1010041" name="PW3373/00 Cu LFF DK369848">
				<tension unit="kV">40</tension>
				<current unit="mA">10</current>
				<anodeMaterial>Cu</anodeMaterial>
				<focus type="Line">
					<length unit="mm">12.0</length>
					<width unit="mm">0.4</width>
					<takeOffAngle unit="deg">6.0</takeOffAngle>
				</focus>
			</xRayTube>
			<sollerSlit id="21010002" name="Soller 0.04 rad.">
				<opening unit="rad">0.0400</opening>
			</sollerSlit>
			<mask id="22080002" name="Inc. Mask Fixed  10 mm (MPD/MRD)">
				<distanceToSample unit="mm">101.00</distanceToSample>
				<width unit="mm">6.60</width>
			</mask>
			<divergenceSlit id="22010012" name="Prog. Div. Slit" xsi:type="fixedDivergenceSlitType">
				<distanceToSample unit="mm">140.00</distanceToSample>
				<angle unit="deg">0.25</angle>
			</divergenceSlit>
		</incidentBeamPath>
		<sampleOffset>
			<position axis="2Theta" unit="deg">0.012</position>
			<position axis="Omega" unit="deg">0.012</position>
		</sampleOffset>
		<diffractedBeamPath>
			<radius unit="mm">240.00</radius>
			<antiScatterSlit id="22060009" name="Prog. AS Slit" xsi:type="automaticAntiScatterSlitType">
				<observedLength unit="mm">0.5</observedLength>
				<offset unit="mm">0.00</offset>
			</antiScatterSlit>
			<detector id="7010012" name="X'Celerator Scientific" xsi:type="rtmsDetectorType">
				<phd>
					<lowerLevel unit="%">45.0</lowerLevel>
					<upperLevel unit="%">80.5</upperLevel>
				</phd>
				<mode>Scanning</mode>
				<activeLength unit="deg">2.122</activeLength>
			</detector>
		</diffractedBeamPath>
		<scan appendNumber="0" mode="Continuous" scanAxis="Gonio" status="Completed">
			<header>
				<startTimeStamp>2015-09-03T11:05:10+02:00</startTimeStamp>
				<endTimeStamp>2015-09-03T11:17:04+02:00</endTimeStamp>
				<author>
					<name>Daniel</name>
				</author>
				<source>
					<applicationSoftware version="2.2">X'Pert Data Collector</applicationSoftware>
					<instrumentControlSoftware version="1.7 ">XPERT-PRO</instrumentControlSoftware>
					<instrumentID>0000000000000819</instrumentID>
				</source>
			</header>
			<dataPoints>
				<positions axis="2Theta" unit="deg">
					<startPosition>15.00108891</startPosition>
					<endPosition>129.99550932</endPosition>
				</positions>
				<positions axis="Omega" unit="deg">
					<startPosition>7.50054446</startPosition>
					<endPosition>64.99775466</endPosition>
				</positions>
				<commonCountingTime unit="seconds">3.175</commonCountingTime>
				<intensities 4 9 6 4 7 6 15 6 16 7 13 4 10 10 9 12 4 9 7 1 10 6 7 9 6 3 14 8 10 6 9 12 3 10 7 12 6 7 8 6 9 8 15 8 9 6 6 6 8 14 10 10 7 9 8 13 4 9 8 6 7 9 6 8 6 3 7 9 7 7 10 8 8 8 10 6 4 8 6 10 3 6 6 14 9 7 6 7 7 2 4 6 8 1 8 9 6 9 6 10 4 8 8 15 7 6 13 9 7 9 3 10 9 8 8 9 13 12 10 15 12 9 9 9 4 13 12 14 3 9 9 12 12 8 10 7 12 9 14 18 16 14 6 10 10 12 10 10 6 12 6 8 12 14 6 19 15 7 19 9 16 10 9 6 10 18 4 12 13 10 10 16 18 9 9 15 8 12 10 15 9 12 15 8 9 8 7 8 9 18 15 8 9 8 9 12 9 14 10 8 12 13 7 7 7 15 9 7 18 9 9 18 14 9 14 10 13 16 6 8 12 8 8 21 16 16 16 14 13 10 10 14 6 9 12 8 16 14 7 2 12 9 15 7 16 16 9 13 12 19 6 20 9 8 15 18 14 10 10 12 8 12 13 15 18 14 12 15 13 10 12 16 16 14 13 8 15 18 14 14 16 20 19 14 10 4 19 9 24 23 14 10 10 20 8 7 20 26 13 14 16 20 29 15 7 13 15 16 14 8 16 20 15 16 14 13 8 19 13 14 15 26 10 12 15 7 15 14 12 9 15 14 15 16 29 23 25 15 14 19 14 15 19 9 16 19 16 12 15 20 9 9 15 23 10 23 16 29 20 24 14 13 9 25 13 12 14 21 18 21 8 14 9 10 19 19 16 19 21 15 18 14 14 23 16 13 19 12 13 18 19 10 19 23 25 9 23 19 16 20 24 13 21 25 26 21 16 15 20 14 23 24 29 16 29 26 18 21 15 18 27 19 19 24 24 25 21 23 18 25 21 12 16 12 29 16 19 15 27 18 19 24 27 19 29 19 18 27 31 14 23 20 16 23 14 29 23 19 23 25 29 14 20 19 21 21 19 18 25 26 15 16 14 21 14 29 30 25 21 24 12 19 26 16 30 21 25 21 14 24 18 26 18 36 24 25 31 25 27 21 19 24 21 25 21 16 25 23 19 37 23 19 21 24 24 29 32 29 16 30 26 30 29 16 21 25 30 20 30 32 23 18 33 33 36 30 37 32 26 31 35 20 20 29 23 32 26 31 33 35 35 27 18 38 18 20 30 27 21 29 19 24 30 21 35 14 23 29 31 31 23 25 31 27 24 18 20 24 25 23 26 23 29 29 18 26 25 18 30 49 23 29 36 26 33 19 25 36 21 31 20 20 23 29 20 27 36 27 26 33 32 23 38 46 40 61 67 84 63 50 36 30 33 25 40 27 31 38 20 24 25 18 30 23 32 30 37 32 50 35 23 32 18 36 23 19 26 27 33 29 40 31 19 32 25 29 38 25 33 27 32 25 25 24 24 40 43 40 29 31 29 18 27 24 24 29 32 21 29 31 36 23 31 36 31 25 31 33 20 23 30 27 21 27 32 23 32 20 29 47 29 29 23 33 35 26 31 24 33 20 23 33 19 18 27 30 20 20 35 21 36 29 30 19 31 26 38 30 30 25 31 33 16 33 36 19 27 30 32 26 30 21 33 36 29 18 30 29 25 24 29 30 32 38 25 26 30 38 35 36 19 36 24 30 26 18 24 30 32 29 19 41 20 21 29 32 27 29 33 32 20 40 25 18 29 24 16 25 33 19 31 21 19 24 35 30 21 16 18 23 23 35 24 21 29 27 35 23 20 25 31 30 23 27 26 29 41 32 20 20 15 20 30 30 27 30 43 14 33 18 19 25 33 31 19 35 29 27 18 33 20 24 38 26 19 26 21 24 24 33 26 30 35 32 36 26 23 32 29 31 25 37 26 24 19 24 32 18 29 30 27 20 24 23 25 23 30 20 24 27 26 21 23 18 21 27 29 24 25 20 33 24 31 23 25 29 27 38 31 25 25 25 19 32 27 27 27 24 25 24 32 31 21 23 16 23 29 32 27 21 26 33 30 24 27 24 32 24 31 27 31 27 27 29 36 33 40 46 48 58 93 118 109 104 95 82 65 47 40 54 38 31 32 31 24 27 25 35 33 24 23 33 32 27 30 25 25 16 32 29 29 29 31 26 36 36 31 33 32 46 46 46 82 43 36 46 46 40 36 29 40 27 29 29 29 26 18 27 16 25 18 30 35 27 35 36 25 40 25 30 36 24 24 35 27 33 40 42 41 52 53 70 80 164 192 300 288 270 163 87 71 53 43 43 35 46 23 24 26 32 36 29 33 40 35 36 19 14 27 21 35 21 35 30 23 23 15 21 29 42 31 26 29 36 36 41 26 36 53 50 29 31 40 33 15 21 32 29 20 20 20 23 36 25 27 21 19 19 23 14 23 26 14 18 24 14 26 23 23 26 20 32 16 16 19 26 14 25 27 16 19 21 26 20 12 27 36 33 20 27 18 26 30 16 30 20 19 20 18 32 24 16 19 18 21 30 19 15 13 15 21 13 15 23 19 10 19 20 21 18 24 20 16 18 21 25 12 18 9 19 10 15 21 19 24 18 18 33 21 18 24 12 23 19 14 25 19 23 24 21 21 16 21 19 14 25 18 14 26 18 16 23 14 7 26 16 15 15 15 21 19 21 25 21 20 21 16 16 21 16 15 31 21 24 20 20 21 19 13 14 21 19 31 24 26 23 30 24 24 21 23 15 24 19 26 27 14 18 25 20 37 42 50 64 81 112 130 176 174 174 147 116 147 149 113 140 143 150 139 164 161 179 216 220 246 297 441 610 996 1727 3447 6024 7873 8310 6913 4398 2374 1432 857 632 492 397 316 280 281 255 198 197 247 184 172 161 144 118 135 128 130 118 129 129 90 94 103 106 104 109 93 92 99 66 96 101 94 101 70 87 100 78 111 89 83 95 83 92 81 84 105 109 83 82 77 92 81 76 78 81 88 78 90 84 77 81 70 75 71 67 72 71 86 73 77 73 64 64 82 67 59 67 76 70 72 89 89 66 75 58 66 73 86 59 63 77 48 81 75 49 48 53 77 77 56 80 52 59 56 65 49 64 61 58 47 69 56 47 66 54 63 42 66 67 49 36 75 50 54 77 58 53 55 56 56 64 64 55 48 43 59 44 61 48 55 54 55 50 44 46 63 55 50 49 65 60 69 52 47 47 52 46 44 46 54 71 65 75 76 60 87 66 71 86 73 88 98 84 106 120 107 169 235 364 506 607 629 516 339 237 181 140 100 90 86 71 81 69 71 54 61 58 75 50 75 61 81 82 73 126 110 136 123 103 84 81 67 67 67 61 58 50 59 54 58 60 63 67 49 61 64 59 46 54 54 41 48 56 76 60 63 59 71 50 56 49 54 64 44 66 41 55 43 54 64 63 69 73 61 72 58 59 49 63 55 73 69 52 69 63 43 76 65 61 75 64 76 63 66 80 52 73 69 78 69 67 72 73 84 90 70 89 110 92 115 92 86 117 96 122 126 107 147 118 144 153 126 176 200 243 337 347 459 625 654 733 755 773 806 807 866 1001 1133 1360 1705 2326 3646 6896 14178 21457 24223 24119 20409 12746 6899 4729 5823 9957 14265 16520 15245 11194 5776 3052 1657 1195 818 653 568 475 413 340 315 298 261 241 200 232 184 166 181 155 140 129 132 133 133 128 138 120 121 117 118 99 103 116 89 84 89 98 101 78 89 76 75 90 80 73 76 67 86 77 70 84 64 63 65 54 76 59 69 48 53 58 66 55 54 70 60 65 63 48 58 56 63 40 59 58 48 56 63 41 53 61 32 54 38 31 46 49 54 53 63 52 46 42 44 42 43 53 49 41 50 44 48 44 54 66 41 44 55 60 47 37 33 54 44 60 47 43 33 42 36 41 59 43 37 46 42 40 38 37 29 26 41 33 33 36 29 35 47 26 40 31 32 38 38 43 30 35 48 41 37 33 42 33 36 32 35 43 33 31 44 38 36 33 27 46 41 37 35 32 33 30 36 21 30 37 38 35 32 33 37 37 36 27 32 24 42 31 35 31 33 31 33 36 24 26 24 40 38 33 27 24 25 29 23 29 42 25 33 19 25 32 26 33 36 29 19 29 20 41 24 35 32 26 41 35 31 33 35 29 25 29 27 23 46 35 32 24 24 42 36 32 29 26 21 35 33 25 37 41 43 24 32 53 29 30 26 26 24 25 32 40 37 19 29 20 18 32 29 20 21 19 23 27 26 29 33 24 27 36 25 31 29 29 40 23 25 23 26 25 37 37 25 20 23 25 30 30 29 29 32 41 29 37 25 21 31 24 25 20 26 12 33 23 26 33 24 16 27 10 31 36 30 27 16 24 27 21 19 21 27 20 29 24 19 27 15 21 27 32 27 25 14 19 20 21 27 25 23 23 19 21 23 24 18 20 18 26 15 30 24 21 24 13 23 14 18 20 15 20 19 18 21 24 21 15 18 29 15 21 31 21 21 19 20 29 16 15 21 16 23 21 18 19 26 19 15 18 20 13 20 23 23 18 24 23 10 20 15 16 18 24 23 13 24 12 27 8 16 16 23 19 15 19 16 14 29 14 19 18 20 12 21 24 24 23 18 13 26 14 18 24 12 16 24 18 14 24 14 27 20 14 18 21 18 14 15 8 12 23 16 27 14 8 19 20 29 15 20 15 15 19 19 18 14 14 20 12 13 15 14 18 21 24 14 23 10 9 14 15 8 19 18 10 18 18 15 3 19 14 14 8 14 10 20 13 12 15 9 16 23 15 9 18 10 13 23 18 14 12 19 16 15 15 15 12 15 25 21 23 16 19 23 9 12 10 16 20 13 9 15 12 14 15 9 12 14 14 15 8 13 12 15 16 10 19 9 8 10 9 13 16 20 10 12 18 15 14 9 14 14 15 12 18 7 10 14 16 8 8 13 10 13 16 12 12 14 9 12 16 12 10 7 8 10 8 10 18 12 13 12 12 14 12 14 2 6 8 9 20 12 15 10 6 16 14 12 8 13 9 12 18 9 13 8 12 14 13 18 16 12 14 10 7 14 15 13 2 10 9 13 9 12 9 13 7 14 3 9 14 10 10 12 9 8 9 12 15 15 8 10 10 13 8 13 8 6 7 8 8 10 7 9 16 9 6 7 10 10 8 12 8 9 4 9 15 8 7 10 13 8 8 8 12 7 4 15 14 12 10 10 12 8 6 10 12 9 9 13 6 9 10 12 2 10 13 7 3 9 4 6 12 14 10 9 7 9 3 8 7 13 7 6 3 10 12 4 8 13 7 8 9 6 9 9 6 12 7 6 10 13 4 8 8 12 6 13 10 12 10 9 8 9 9 3 7 7 8 14 7 13 10 10 7 12 6 9 7 8 10 8 7 9 7 8 6 9 10 4 8 1 13 8 2 4 6 7 8 7 12 7 10 7 7 6 3 7 13 3 7 9 2 6 4 4 15 9 4 10 9 8 4 9 6 6 3 6 12 6 3 7 6 6 8 6 8 9 6 7 7 6 7 6 6 10 13 7 12 7 7 6 4 8 3 1 4 4 7 6 1 8 4 6 10 6 4 12 3 8 4 9 12 4 4 14 14 15 10 2 3 7 7 6 6 7 7 8 10 10 12 3 10 3 8 7 7 3 3 10 6 3 6 6 9 3 8 4 4 8 7 6 7 7 3 7 7 1 3 1 2 3 6 4 2 3 7 2 13 8 13 6 4 3 2 9 6 7 6 3 4 6 2 6 10 7 6 3 7 6 6 2 7 0 2 1 1 1 3 2 4 4 4 6 3 4 4 4 2 6 3 1 6 1 3 7 3 8 6 7 1 3 1 2 6 0 6 3 13 6 4 2 6 1 1 8 6 4 1 4 4 3 4 8 2 3 0 1 6 3 2 4 2 6 0 3 3 1 1 0 6 6 7 4 3 3 4 1 1 3 7 2 2 1 7 4 4 1 1 7 1 0 1 3 1 4 1 6 3 1 2 2 8 0 3 2 3 2 1 7 1 3 6 2 4 1 4 1 2 7 4 0 0 7 4 3 2 4 2 1 4 6 2 6 6 4 1 2 2 3 4 2 2 2 6 2 4 3 3 3 2 3 4 3 2 2 4 3 7 2 2 3 3 0 3 9 3 0 9 0 1 1 2 4 1 1 3 2 2 0 2 2 1 1 1 4 1 4 2 2 1 1 1 0 3 1 2 4 4 2 1 4 3 3 3 1 0 1 4 1 2 4 3 0 2 4 0 4 6 2 1 1 3 1 1 0 2 1 4 2 6 1 2 2 2 1 2 2 8 2 8 4 4 1 4 0 4 1 1 0 1 2 4 4 2 3 2 3 2 1 3 0 1 0 1 3 2 8 2 0 1 1 3 2 3 3 2 1 3 3 4 1 1 4 1 7 2 0 0 6 1 1 1 1 4 2 1 1 0 1 6 3 2 2 3 1 1 2 4 4 2 0 1 2 3 6 6 6 3 6 7 8 4 6 6 3 2 4 4 3 7 2 6 2 6 1 2 2 3 1 3 1 0 1 3 1 4 0 3 2 1 1 4 0 7 2 6 2 3 0 3 3 1 4 2 0 2 0 2 1 1 0 2 2 1 1 1 0 0 2 2 0 1 2 2 0 1 1 1 2 2 0 2 2 2 0 1 0 1 2 3 1 0 2 0 1 1 3 2 3 1 0 4 0 1 1 0 1 1 0 6 3 2 0 0 8 1 2 2 2 1 1 1 1 3 3 1 1 2 1 1 1 0 1 1 1 3 2 4 0 1 1 3 1 3 6 1 1 1 1 3 2 1 0 1 0 3 0 4 0 1 0 0 2 1 2 1 1 0 3 1 1 2 1 1 0 1 0 1 1 2 2 2 0 0 0 0 1 1 0 1 4 2 2 1 1 0 1 1 1 0 2 2 2 1 1 1 1 0 0 0 2 1 0 1 2 2 0 0 0 2 3 2 2 1 0 1 0 2 1 2 3 2 4 1 4 2 1 2 1 3 1 0 1 0 0 3 3 2 1 0 0 3 1 1 2 1 1 1 1 1 2 2 0 0 0 3 2 1 2 1 2 0 3 4 2 1 0 2 2 2 2 1 1 3 1 0 1 1 1 0 2 1 0 1 0 2 2 1 1 1 1 0 1 0 0 0 2 0 1 2 0 3 0 0 1 2 0 1 1 0 1 0 0 2 1 0 0 0 0 1 0 2 1 0 3 0 2 0 1 1 0 1 2 1 2 0 2 1 1 1 0 2 1 2 3 1 3 1 0 1 1 0 1 1 1 1 3 1 0 0 1 0 0 2 0 0 0 1 0 0 3 0 0 1 1 0 1 0 1 2 0 0 1 2 1 3 2 2 1 0 1 0 0 1 3 1 2 0 2 1 4 3 1 0 0 1 0 1 0 0 2 0 3 0 1 1 0 0 1 2 2 1 1 0 1 0 0 1 1 2 3 1 2 2 1 1 1 1 0 2 1 0 0 0 0 0 0 0 0 2 1 0 2 0 0 2 2 0 1 1 1 1 0 4 0 1 1 0 0 2 0 3 2 2 0 0 0 0 0 1 0 2 0 1 0 0 0 0 1 0 2 0 0 0 0 2 1 1 2 0 1 1 1 2 0 2 1 0 0 1 0 1 0 2 1 0 0 0 1 0 0 0 1 1 0 0 1 1 1 0 0 0 0 0 0 0 0 1 0 0 3 0 1 0 0 1 0 2 1 2 0 1 1 1 0 1 0 1 0 0 0 2 1 1 1 2 1 0 1 0 1 1 3 2 3 2 3 1 0 1 0 0 0 1 0 1 0 1 0 0 1 1 1 0 0 1 2 0 1 1 0 0 0 0 1 1 0 1 1 1 1 1 1 1 4 1 1 0 0 2 0 0 1 1 0 0 1 0 1 0 1 1 2 0 0 0 1 0 1 1 0 1 2 1 2 0 1 2 0 0 0 0 2 0 0 0 2 0 1 1 1 0 1 1 1 0 2 2 1 1 1 1 0 1 0 1 1 1 1 1 2 2 2 0 0 1 1 3 1 1 1 0 0 2 0 1 0 1 0 1 0 1 0 0 0 0 1 0 0 1 0 1 1 0 0 2 0 0 0 1 0 1 1 1 1 0 1 1 0 3 0 0 0 1 0 0 1 2 0 1 1 0 0 0 0 0 0 1 0 1 0 1 0 1 2 1 1 0 0 1 1 0 1 0 1 0 1 0 1 1 0 2 0 0 1 1 0 0 1 1 0 2 0 0 0 0 0 0 1 0 3 0 4 1 1 0 2 0 1 0 0 0 0 1 0 0 0 0 1 1 1 0 0 0 2 1 0 0 0 1 1 1 1 0 1 0 1 1 0 0 1 0 1 1 2 0 1 1 1 1 1 0 1 2 3 0 2 0 0 1 1 0 0 0 0 2 0 0 3 1 0 1 3 0 0 2 1 0 0 1 1 1 1 2 0 0 0 3 0 0 3 0 1 1 0 0 1 0 1 0 1 0 0 1 0 2 1 0 0 1 0 1 1 2 1 0 2 0 3 0 1 1 1 0 0 0 1 0 1 2 2 1 1 0 0 1 2 0 0 0 0 0 0 0 0 1 0 0 0 0 2 1 0 1 0 1 0 0 1 1 1 1 1 2 2 0 0 1 0 0 1 1 1 1 0 3 1 1 1 2 3 2 1 1 1 1 2 0 0 1 1 0 0 1 0 1 1 0 0 1 0 0 0 1 0 1 1 1 0 0 0 1 1 3 0 0 0 0 0 0 0 0 0 1 0 1 0 2 1 1 1 3 1 0 1 0 2 0 0 1 2 0 0 0 0 1 1 1 0 0 0 0 0 1 0 0 1 1 0 0 0 0 2 0 1 2 1 1 0 2 0 1 1 0 0 1 1 1 0 0 1 1 0 1 0 0 2 0 0 0 2 0 0 0 1 0 1 1 3 2 6 0 0 0 1 0 1 0 1 0 0 0 2 0 1 0 1 0 1 0 0 0 0 0 0 0 1 0 1 0 0 1 0 0 0 1 0 1 0 0 1 0 0 0 0 0 0 1 0 0 0 0 0 1 1 0 1 1 1 1 3 0 1 1 0 1 0 0 1 0 0 0 2 0 2 0 0 0 2 0 1 0 1 0 0 0 1 1 1 0 0 0 0 0 1 1 0 0 0 0 1 0 1 1 1 1 1 0 1 0 2 0 1 0 2 0 4 0 1 0 1 0 1 0 0 1 1 0 0 1 0 0 2 0 0 0 0 2 0 2 1 1 1 0 1 2 0 0 0 1 0 2 2 1 0 0 1 0 1 1 0 1 1 1 1 2 1 2 1 0 0 0 2 0 0 1 0 1 1 1 0 1 0 0 0 0 0 1 2 2 2 3 0 1 0 0 0 0 1 0 0 1 1 1 1 1 1 1 3 1 2 2 0 3 0 0 0 1 0 0 0 1 1 1 0 0 0 0 0 0 2 1 0 1 0 0 0 0 1 1 0 0 0 0 0 0 2 1 1 0 2 2 1 0 1 0 0 0 0 0 0 2 1 1 0 2 0 1 1 3 1 0 1 2 1 0 0 0 0 3 1 1 2 1 1 1 2 0 1 0 0 2 0 0 0 0 2 0 3 1 1 1 1 0 1 0 2 1 2 0 1 0 3 0 1 1 2 2 0 0 1 0 1 1 0 1 1 0 0 0 1 0 0 0 1 2 1 0 2 2 0 2 0 1 1 0 1 0 2 0 2 1 2 1 3 0 0 0 0 0 2 0 0 1 0 2 0 1 0 0 0 0 1 0 1 1 2 1 0 2 1 1 1 1 2 1 1 2 1 0 0 2 1 0 2 2 0 0 0 0 0 1 1 0 0 0 1 0 1 0 2 1 0 2 0 2 0 1 0 0 0 2 0 0 1 1 1 0 1 2 2 0 1 0 0 1 0 0 0 0 1 1 2 0 0 0 0 1 0 0 0 1 0 0 2 1 0 0 1 0 0 1 1 2 1 1 1 0 1 3 1 1 0 2 1 0 0 2 2 2 2 0 0 0 1 0 2 0 2 0 1 1 0 0 1 1 0 1 0 1 0 2 2 1 0 1 0 2 0 2 0 2 1 0 1 0 1 0 1 2 0 1 1 2 1 6 3 2 3 7 9 7 12 10 8 10 6 4 7 1 8 1 3 3 1 1 0 3 1 4 3 0 1 3 0 0 1 2 0 0 0 2 4 2 0 1 2 0 2 1 1 1 0 2 0 0 1 2 6 1 3 0 1 1 0 0 1 1 0 1 1 1 1 0 1 0 1 2 1 0 1 0 1 0 3 0 0 0 0 1 1 1 7 0 2 2 0 0 1 0 1 0 1 1 1 1 1 1 0 0 1 0 0 0 1 0 1 0 2 0 0 0 1 0 1 1 0 0 2 1 0 0 0 1 1 1 0 0 1 1 1 2 2 1 1 1 0 0 1 0 0 1 1 0 1 1 1 2 2 3 1 2 0 0 0 0 2 1 1 1 1 0 0 0 1 0 0 1 1 0 0 1 2 2 0 1 2 0 1 2 2 2 0 2 1 0 2 0 1 0 1 2 0 1 1 2 1 1 1 2 0 2 0 0 0 0 0 2 2 2 1 1 0 1 0 2 0 0 2 0 1 1 0 2 1 0 0 6 0 0 2 0 0 1 0 0 1 3 2 2 2 1 0 1 1 4 1 0 0 0 0 0 2 2 0 0 1 3 2 1 1 1 0 4 0 1 0 0 1 3 0 1 1 0 0 1 2 0 2 1 1 1 2 2 0 1 1 2 0 1 1 1 1 0 1 0 1 0 0 1 1 1 2 6 2 1 0 1 1 2 1 0 1 0 1 0 1 0 0 1 1 0 1 2 0 3 0 1 1 1 1 2 0 1 0 2 1 2 0 0 0 1 0 2 2 1 0 0 1 0 1 1 0 0 0 2 2 0 0 1 1 0 1 1 0 2 0 0 1 1 0 2 1 1 1 0 1 1 0 0 2 0 1 1 1 0 0 0 0 0 1 2 2 0 1 3 2 2 2 2 1 2 0 1 2 2 1 0 0 1 1 3 2 1 0 0 2 3 2 1 2 2 1 0 1 0 0 0 0 1 0 2 1 0 0 1 1 0 1 1 2 1 3 2 1 7 0 3 2 1 1 2 0 0 2 1 0 0 1 1 1 3 4 1 2 1 3 1 2 1 1 1 0 2 1 1 1 1 1 2 2 0 1 0 1 0 2 0 0 1 1 2 2 0 2 1 0 0 0 3 2 0 3 0 2 2 0 0 0 0 1 0 2 2 3 2 0 3 0 1 1 1 1 2 0 0 1 3 1 0 2 4 0 2 1 1 1 1 0 0 1 1 1 0 1 1 0 1 1 2 1 0 1 1 0 0 2 0 1 1 3 1 2 1 0 1 0 0 1 1 1 3 1 1 0 1 3 1 0 2 2 4 0 4 2 0 1 1 1 0 1 2 0 2 0 2 0 0 1 1 2 0 2 0 0 1 0 0 1 0 3 1 0 0 0 0 0 2 0 1 0 1 1 0 1 0 2 2 1 0 3 0 1 2 0 2 0 0 2 0 1 3 1 1 0 1 1 1 1 2 2 3 2 1 3 2 1 2 1 0 1 0 0 2 0 2 0 2 0 2 0 1 3 0 4 1 1 0 0 0 2 2 4 1 0 3 1 3 1 1 2 1 0 0 1 2 4 1 2 1 4 3 2 4 1 6 4 4 3 2 4 2 6 1 3 2 3 1 3 0 2 1 0 0 2 4 3 2 3 3 7 1 4 13 15 37 40 54 60 42 31 20 12 8 3 3 9 1 0 0 8 3 4 14 23 13 20 19 27 24 8 6 4 3 3 6 0 4 1 1 1 1 1 1 2 0 4 4 2 1 6 1 0 2 0 0 0 3 4 0 0 1 4 1 0 1 3 2 2 2 1 3 1 2 3 2 0 0 2 1 0 3 1 0 3 0 1 1 1 0 2 2 1 1 3 3 2 1 1 1 1 3 2 0 3 0 0 3 2 0 0 0 0 1 1 1 1 2 2 1 0 0 0 4 3 0 0 2 0 2 0 1 0 0 2 2 2 0 1 3 0 1 1 0 1 1 1 0 1 1 0 0 0 0 0 0 2 1 2 2 0 2 2 3 1 2 1 1 0 2 3 1 1 2 1 3 0 1 1 3 0 1 1 0 1 1 2 2 3 0 0 2 1 0 0 1 3 1 2 0 1 2 1 1 0 1 0 3 4 2 1 0 1 1 2 2 1 1 0 1 1 2 0 1 2 1 0 2 0 0 1 2 2 1 1 0 1 3 2 2 0 0 2 2 0 2 1 2 3 2 1 3 1 1 2 0 3 1 0 2 0 1 2 1 1 2 3 2 3 2 3 0 0 0 4 2 0 3 0 0 3 2 1 0 0 1 2 2 0 1 1 0 3 0 1 1 0 2 2 3 0 2 3 2 2 2 1 2 2 3 1 2 2 1 1 1 2 0 2 2 2 2 2 3 2 4 2 1 1 3 2 2 2 2 3 3 4 1 0 1 2 3 2 1 1 1 0 2 1 1 3 3 1 2 1 3 1 2 0 3 4 1 1 2 2 1 3 1 2 0 1 2 1 1 2 0 1 3 2 2 3 1 0 1 2 0 1 0 2 1 1 2 0 3 2 3 0 0 2 0 4 1 2 0 4 0 2 2 3 2 2 3 1 1 1 0 1 1 2 3 0 2 1 0 2 0 2 1 2 1 1 0 1 2 1 2 1 0 0 1 3 1 0 0 1 0 1 2 1 2 0 0 1 2 0 2 0 0 1 0 0 2 0 4 2 3 1 4 0 2 2 1 1 1 2 2 1 3 0 2 4 1 1 1 2 3 1 1 1 1 1 0 1 3 3 1 0 1 3 2 1 1 2 1 1 2 0 3 0 2 3 1 1 0 2 2 2 0 3 3 1 4 3 3 3 0 1 4 3 1 2 1 1 1 0 2 2 1 3 1 3 3 0 2 3 4 4 3 3 1 4 2 2 4 1 3 1 4 0 0 1 3 0 0 0 0 2 0 2 0 0 1 4 1 1 1 2 1 4 2 1 6 1 2 1 1 2 2 4 1 1 1 2 2 2 1 3 1 2 2 0 1 0 3 2 3 2 1 1 1 2 3 0 1 0 0 2 2 2 2 0 2 1 4 2 1 0 3 0 2 0 2 0 1 1 3 0 0 2 0 3 2 0 2 0 0 2 0 0 0 1 2 3 0 3 2 0 1 1 2 1 1 1 2 2 0 2 1 2 3 2 2 2 0 0 0 1 0 3 2 0 1 2 2 1 1 2 0 0 2 4 0 1 2 0 3 2 2 3 2 4 1 1 0 2 1 1 2 2 0 1 1 4 1 2 1 1 3 2 0 3 2 2 2 0 1 0 4 0 4 0 3 0 0 1 2 0 4 1 1 1 1 0 2 2 3 1 1 0 0 1 0 0 0 2 2 3 1 0 3 1 0 0 2 2 0 0 0 1 1 2 1 1 0 2 0 2 2 1 2 1 0 1 1 1 1 2 1 2 1 4 2 3 3 2 1 1 0 1 1 0 0 1 3 2 2 1 6 0 0 0 1 2 4 1 1 0 1 1 4 1 0 0 1 0 0 1 0 4 2 0 1 0 3 3 0 1 0 0 4 0 1 3 2 1 1 1 3 2 1 1 0 0 0 0 3 1 0 0 2 2 0 0 0 2 1 3 2 2 0 3 1 4 3 1 3 1 0 1 2 0 2 1 3 1 4 0 2 2 1 2 2 2 3 2 0 0 2 0 0 2 0 0 1 3 0 2 1 4 0 1 0 1 1 0 1 2 1 0 1 0 1 4 0 0 1 0 1 0 0 2 0 2 1 0 1 3 1 1 0 0 1 1 1 1 3 1 2 3 1 2 1 4 1 0 0 1 1 0 2 0 1 1 2 2 1 3 3 1 1 3 1 0 1 1 2 0 1 2 1 1 0 0 2 1 0 2 3 1 1 1 0 1 0 0 3 1 1 0 1 1 3 0 2 6 1 3 1 1 1 1 4 1 0 1 1 4 3 0 3 2 2 3 0 3 4 3 1 0 1 1 0 1 0 1 1 1 2 0 3 2 4 0 0 0 1 1 0 1 1 3 1 2 1 2 0 0 1 2 2 2 0 1 3 1 4 2 1 3 3 0 1 1 1 0 2 2 2 1 1 1 2 2 2 1 1 2 2 2 1 3 1 0 0 0 0 1 1 1 1 1 1 1 1 2 0 0 1 1 0 1 0 1 1 2 0 1 1 1 0 0 2 4 1 0 1 0 1 0 1 4 4 2 0 2 1 1 1 0 2 1 0 1 2 1 2 1 4 0 0 0 1 0 0 3 2 1 3 2 0 2 3 2 0 1 2 1 0 1 2 2 1 2 2 1 0 1 2 2 0 2 1 1 2 0 4 2 3 2 2 0 6 1 4 0 4 1 0 0 1 1 0 0 1 2 2 1 3 0 0 1 1 2 0 1 1 0 0 1 2 3 4 0 0 3 2 1 1 2 1 0 0 1 1 3 0 0 1 1 0 1 1 0 0 0 0 2 2 1 1 0 2 1 0 1 1 0 2 2 0 1 1 4 1 1 1 2 2 1 3 0 1 1 0 3 0 2 2 3 2 2 1 0 0 0 3 4 1 1 1 1 3 3 0 1 2 0 3 1 0 0 1 0 3 1 1 0 2 3 0 0 1 1 2 0 1 1 0 0 1 2 1 1 3 2 1 1 3 2 1 1 1 1 4 2 1 1 2 1 3 1 2 1 0 3 6 3 0 3 0 1 1 3 1 0 2 2 1 1 3 1 0 6 1 3 1 1 1 3 0 1 0 0 1 0 2 1 0 2 2 2 1 0 0 2 3 0 2 2 1 0 0 2 2 2 6 0 2 0 1 3 0 0 0 1 2 1 1 1 1 1 4 2 0 1 1 1 0 1 0 2 2 3 0 1 0 0 1 1 2 3 0 0 0 0 0 1 1 3 3 4 1 2 0 1 0 2 4 4 1 1 0 1 6 3 0 1 1 2 3 1 2 0 1 0 3 1 0 2 0 1 2 0 1 0 0 1 0 1 0 3 2 2 3 3 1 0 2 2 1 2 2 3 2 0 0 0 3 2 1 2 0 1 0 0 0 2 1 2 2 0 0 2 1 0 1 0 0 1 1 1 2 2 2 1 2 0 0 2 2 3 1 1 2 2 3 0 2 0 1 1 1 3 0 1 0 1 1 0 1 0 0 2 0 2 2 2 3 2 0 2 2 1 1 1 6 1 0 0 0 2 2 3 0 0 0 4 0 0 1 2 2 0 0 2 1 0 1 2 4 1 2 2 4 4 2 2 1 0 0 0 2 0 0 2 0 1 1 2 3 1 1 0 2 2 4 1 0 1 3 3 1 2 0 1 1 1 1 0 2 0 1 3 1 1 1 1 2 2 2 0 1 3 0 1 1 0 2 1 1 2 2 0 0 2 2 0 3 1 1 2 0 0 2 0 7 1 1 1 2 1 1 1 2 4 2 1 1 1 1 3 1 1 0 1 1 0 2 0 2 0 4 3 2 2 3 1 4 2 1 8 2 6 3 4 8 4 3 3 6 7 6 7 3 9 6 4 2 4 1 1 2 2 4 2 0 1 0 2 1 4 0 0 6 3 2 2 7 3 1 1 1 3 1 0 1 0 1 2 1 1 0 0 2 0 1 1 1 4 2 1 2 2 2 0 1 1 2 0 1 3 0 3 0 0 1 1 0 2 3 3 3 0 1 1 0 1 2 1 3 2 1 1 0 1 0 2 2 2 1 1 3 1 0 2 0 0 0 2 0 0 0 2 1 0 1 2 2 2 0 2 0 3 0 2 2 1 3 1 0 1 0 1 1 1 1 1 2 1 6 0 0 1 1 3 1 4 0 3 1 1 1 6 1 2 2 2 4 2 1 0 2 6 4 3 1 0 1 2 2 3 0 0 4 1 3 1 1 4 0 1 1 1 1 2 0 1 2 0 1 0 1 1 0 1 2 0 0 2 0 2 0 0 0 1 1 0 0 2 0 0 3 0 2 2 3 2 1 0 2 1 3 1 2 0 0 1 0 1 0 2 0 3 1 1 2 0 3 0 1 1 1 4 2 1 2 2 2 3 0 2 0 1 4 1 2 0 2 1 1 1 0 1 0 0 0 0 4 4 6 0 1 2 0 1 1 0 0 2 1 3 2 2 0 1 1 3 0 1 4 2 1 4 0 1 3 2 4 0 2 3 2 3 2 6 3 2 2 6 3 4 7 14 13 8 27 20 15 16 13 8 6 8 9 9 6 4 2 1 3 1 3 4 4 3 2 3 2 3 3 1 1 1 4 2 3 0 2 1 1 2 3 0 1 1 1 1 0 1 0 2 3 0 2 1 2 1 3 2 1 0 0 1 2 1 3 1 4 1 0 4 4 1 1 0 0 1 1 1 1 1 1 1 2 1 1 1 2 0 1 0 2 4 1 2 1 1 0 0 1 3 2 4 2 0 1 0 0 1 0 1 2 0 1 1 1 1 1 0 1 2 1 3 0 0 1 2 1 1 0 0 0 1 7 3 1 1 2 2 0 1 2 1 2 0 0 1 3 0 1 1 0 0 3 1 1 2 1 2 3 1 1 0 4 2 2 0 1 6 2 4 2 2 4 1 3 0 1 2 3 3 3 1 2 2 0 0 1 0 1 1 0 0 1 3 0 4 1 4 0 1 2 2 0 2 3 1 0 0 2 0 1 2 1 1 0 1 2 2 2 3 0 1 2 0 0 1 0 2 1 1 1 2 1 0 1 0 0 3 1 1 1 0 0 2 2 1 1 3 2 2 0 2 0 0 1 1 3 1 0 0 0 1 0 3 0 1 3 4 1 2 2 2 2 0 1 2 0 3 1 0 3 1 4 1 0 2 1 1 0 1 0 0 0 3 0 1 1 0 0 1 2 0 2 1 2 1 4 2 0 2 2 2 1 1 2 0 1 1 0 1 0 1 2 0 0 2 1 1 1 1 0 1 0 3 0 1 1 1 1 1 0 2 0 0 0 3 1 1 0 3 0 1 0 1 0 2 1 0 0 3 0 2 1 2 1 2 0 2 2 4 0 0 0 1 0 1 2 3 0 2 0 0 0 2 0 1 1 2 1 1 2 3 1 0 1 0 0 1 2 0 0 1 1 0 1 2 2 2 1 6 2 0 1 1 0 0 0 3 1 1 0 0 3 2 1 1 0 0 0 1 1 2 1 0 1 2 1 0 0 3 2 3 4 1 1 2 2 2 2 1 0 3 2 3 0 1 2 3 0 0 0 2 0 0 0 1 0 1 0 1 0 1 2 1 2 0 1 1 1 6 0 0 0 0 1 0 0 0 6 0 1 0 0 3 3 1 0 0 1 1 1 2 0 1 0 2 0 1 1 2 2 0 0 0 1 2 2 3 0 1 1 2 2 3 3 0 3 0 1 1 0 0 1 0 0 1 1 1 1 2 1 2 1 0 1 1 2 1 1 3 0 2 2 0 1 2 1 3 1 1 1 1 0 1 2 3 0 1 0 0 2 2 2 2 0 1 1 2 0 0 3 2 2 0 0 2 1 2 1 1 1 1 1 1 4 1 1 1 1 1 2 2 1 1 2 0 0 0 1 0 1 0 0 0 2 0 0 0 1 0 1 1 1 1 0 2 1 2 2 1 1 1 1 2 0 1 0 0 1 2 1 0 1 3 1 1 0 1 2 2 0 0 2 1 1 1 1 1 1 4 1 4 2 0 0 1 2 0 0 0 0 1 0 2 2 0 1 0 2 0 2 2 3 0 2 0 3 0 2 2 1 1 2 1 1 0 1 1 2 1 0 2 0 0 1 1 0 0 3 1 0 1 1 1 1 2 2 0 3 0 0 2 4 0 1 1 1 0 2 1 0 1 0 1 6 2 1 1 1 1 0 1 3 2 0 2 1 0 0 0 0 0 2 4 3 1 0 1 2 1 2 0 0 3 1 1 1 3 1 0 1 0 2 1 1 1 2 2 2 2 1 0 1 1 2 0 2 2 2 2 3 1 1 2 1 1 3 3 4 4 4 1 2 3 1 1 2 0 1 1 2 1 1 2 1 2 1 3 1 1 3 4 2 1 1 2 2 3 3 3 4 2 0 0 1 1 2 1 3 3 6 2 3 1 0 4 6 9 7 6 4 4 14 3 10 10 6 4 1 2 3 4 4 3 6 7 2 0 2 7 10 4 4 3 1 4 2 1 2 6 3 2 3 2 1 10 3 2 6 3 8 4 9 0 8 4 3 4 3 6 2 6 7 2 1 14 7 4 4 9 9 9 12 7 3 4 6 9 14 9 6 16 9 8 6 14 12 16 24 30 24 25 33 44 46 50 61 73 89 72 98 147 173 214 275 318 387 410 464 499 467 461 387 320 237 216 145 103 111 117 72 77 76 66 52 42 47 42 25 32 31 20 25 16 26 15 13 10 21 12 14 10 7 10 13 12 12 14 10 12 4 13 9 14 15 9 7 7 8 4 9 9 13 8 6 6 13 4 4 9 10 3 8 4 7 7 9 9 8 3 4 10 4 3 10 7 4 6 7 6 4 6 7 7 2 7 6 3 8 3 6 4 6 7 1 7 7 2 1 2 7 1 6 2 4 2 3 4 3 3 7 10 2 2 3 3 2 7 3 2 4 7 0 4 1 4 4 2 2 6 2 1 4 7 3 6 4 0 7 7 3 3 3 6 4 4 6 0 0 2 4 0 6 2 4 7 2 4 4 2 6 6 0 4 2 3 4 6 0 7 4 2 3 4 4 6 3 3 4 4 4 2 4 2 0 3 4 3 2 3 6 4 2 3 2 2 8 3 8 1 4 4 3 0 3 4 7 1 4 4 2 2 1 3 4 4 3 2 8 4 3 1 7 3 1 4 1 4 2 4 1 3 7 4 6 7 4 2 6 6 2 1 0 2 2 2 3 4 6 4 2 4 2 3 3 3 2 1 2 2 2 1 0 2 6 0 0 3 3 10 2 6 7 1 2 3 3 2 0 1 6 4 2 2 3 1 2 3 4 2 3 4 4 4 1 3 1 3 2 2 6 3 3 4 4 2 6 3 3 2 1 1 3 3 3 4 1 2 2 2 3 0 2 2 2 3 4 2 0 1 1 1 0 2 0 2 3 3 4 3 3 1 6 7 4 3 1 1 2 6 2 4 1 2 3 2 3 3 2 1 3 2 4 1 4 1 2 2 1 4 0 0 6 2 3 3 2 6 2 2 0 1 1 2 2 2 3 2 1 3 2 3 4 3 3 2 2 4 1 2 1 3 2 2 1 0 0 1 2 3 3 1 2 2 3 2 0 1 4 2 0 1 3 4 3 0 0 1 0 3 4 2 2 0 3 1 3 1 2 3 0 2 1 0 2 3 3 1 1 1 4 1 6 0 2 3 2 1 4 2 3 3 3 1 1 4 2 2 2 1 0 3 1 8 6 2 4 4 1 4 2 4 2 2 2 1 1 7 3 2 6 2 0 3 3 1 2 3 0 2 0 0 2 1 4 3 6 1 2 3 2 2 6 2 0 0 1 3 2 1 2 2 4 3 2 2 1 7 4 1 4 1 2 3 1 0 2 9 6 3 2 3 2 3 1 8 3 3 2 2 2 0 1 6 0 2 4 2 6 3 1 3 4 1 2 1 3 3 2 1 2 1 2 2 2 2 3 1 4 2 3 3 2 1 4 0 6 2 0 1 1 4 2 4 3 4 0 4 1 3 2 3 2 0 0 6 3 3 0 1 4 0 2 3 3 1 4 3 2 0 1 1 4 0 1 7 3 2 0 1 3 1 1 1 2 6 4 4 2 4 4 1 1 0 1 6 2 6 4 1 7 3 3 1 3 2 7 1 1 2 1 4 6 1 4 3 1 0 7 2 1 2 0 2 1 4 2 3 6 0 2 4 2 2 7 6 1 1 3 7 7 3 2 1 1 1 3 2 4 4 4 4 3 4 1 1 0 3 0 4 3 0 1 1 6 3 1 2 1 1 2 2 3 4 7 4 6 3 3 2 2 6 3 7 4 3 3 4 7 6 13 4 1 13 4 7 8 2 9 13 9 4 9 23 21 21 13 32 14 35 21 30 24 25 18 12 18 6 14 10 10 4 9 2 3 4 8 3 1 4 3 1 4 4 8 1 3 2 3 6 2 7 2 4 6 2 6 0 3 2 2 4 0 4 2 0 4 3 4 7 2 2 6 6 2 4 3 4 1 1 3 0 0 2 4 1 4 3 4 6 3 4 2 3 2 1 2 0 0 4 3 2 3 2 1 2 4 1 3 3 6 6 2 2 6 1 6 7 3 4 2 6 4 9 3 4 4 3 6 1 3 8 3 2 7 4 7 4 4 0 4 1 3 0 3 3 4 4 2 1 2 3 1 2 1 4 1 3 3 3 2 2 3 2 1 1 2 4 7 6 3 1 4 0 2 2 4 3 7 3 2 1 3 8 3 1 4 0 2 2 1 1 3 1 6 2 2 6 2 2 1 2 3 3 1 3 1 4 3 0 1 2 0 2 3 0 2 3 1 0 4 1 2 3 2 2 4 2 2 2 2 7 2 1 1 4 3 3 2 2 2 1 3 4 4 4 4 4 3 2 4 1 2 1 2 2 2 0 2 2 1 3 1 1 4 3 1 3 1 6 3 3 0 3 7 4 8 2 2 6 3 1 1 0 3 4 6 2 3 2 4 0 4 0 3 4 1 1 6 0 2 0 2 2 1 2 4 3 2 3 1 3 2 3 3 2 2 1 1 4 3 6 6 0 2 6 4 1 1 2 2 2 3 4 2 2 2 2 2 3 1 2 0 4 4 4 2 6 1 2 2 2 2 2 2 3 1 1 6 0 0 0 4 2 2 1 1 2 1 1 3 2 3 2 4 4 1 6 3 1 2 4 1 2 1 3 1 4 1 2 3 2 2 3 2 3 0 2 6 4 3 3 3 2 2 8 4 2 4 1 4 2 4 1 4 10 6 2 1 4 2 2 3 6 0 4 2 3 6 6 6 7 3 1 2 6 4 6 2 2 1 6 6 6 8 1 4 1 3 7 3 2 7 6 6 1 4 6 0 1 4 7 1 3 2 2 3 2 3 4 1 2 1 3 7 6 4 6 4 2 6 6 3 4 2 3 1 3 2 2 3 2 3 6 1 1 6 1 4 3 2 1 6 2 4 3 3 7 7 7 6 7 2 3 2 4 4 6 6 3 2 4 4 2 6 8 2 7 10 6 7 8 6 2 9 7 3 6 4 6 7 7 16 9 12 2 8 9 15 13 6 18 18 9 13 18 9 16 19 18 21 18 30 15 12 20 19 20 19 14 24 20 27 16 19 18 20 13 14 21 15 12 9 20 24 18 20 19 13 31 18 20 21 30 26 31 31 25 15 33 44 26 47 50 65 61 58 81 64 112 101 109 117 143 162 202 218 270 317 355 480 647 897 1257 1840 2500 2851 2898 2640 2125 1548 1149 905 710 554 369 344 261 175 173 152 158 100 112 94 106 87 100 84 98 104 126 157 139 187 176 219 311 379 477 746 904 1131 1311 1339 1257 1064 857 715 528 410 330 283 216 195 130 129 105 109 80 67 71 67 59 43 38 29 37 31 19 31 41 35 26 23 25 25 31 20 25 29 16 21 23 12 14 15 15 15 12 14 19 7 13 18 4 16 14 8 10 4 13 15 10 19 8 9 8 7 6 9 6 13 8 13 6 8 13 4 4 2 4 8 4 6 6 14 4 7 4 8 4 2 3 6 6 4 9 3 2 9 4 2 8 3 4 9 1 6 4 2 7 6 10 6 3 7 4 3 1 7 2 2 1 4 4 7 2 4 2 4 6 2 4 7 2 3 2 4 8 1 6 2 2 3 4 9 4 4 3 3 6 3 2 6 6 3 4 9 6 4 6 6 3 1 4 2 3 2 3 3 7 6 2 3 3 6 1 3 2 4 3 6 7 7 4 9 2 3 2 3 6 2 2 0 2 3 4 6 3 3 8 7 1 4 4 2 4 1 7 2 4 1 3 4 4 4 0 3 6 4 2 2 3 0 2 2 2 4 0 2 1 6 1 3 1 1 2 1 4 7 2 4 6 1 6 1 1 1 1 3 3 4 2 3 2 2 1 3 3 3 2 2 0 4 3 2 1 4 1 1 1 3 1 2 1 1 2 2 0 2 3 4 2 2 2 3 1 1 2 3 0 2 1 3 1 3 3 3 2 2 6 3 3 2 2 0 7 1 2 7 6 0 3 1 1 2 1 1 2 0 2 3 2 6 4 3 4 1 3 1 2 0 2 0 1 0 2 1 1 3 4 2 4 3 1 0 2 2 1 2 6 1 2 3 4 1 2 3 4 2 2 2 0 3 4 0 6 1 2 1 0 2 1 3 1 0 0 1 4 2 4 2 3 3 1 2 1 1 3 2 2 0 6 4 6 2 0 2 0 2 3 2 2 6 1 1 3 1 1 0 3 2 1 1 4 3 1 4 2 1 1 0 3 1 0 3 2 2 2 1 8 0 1 1 3 1 2 4 1 3 7 3 2 4 6 3 1 4 6 3 2 3 4 1 3 1 1 4 2 1 3 1 1 4 3 0 1 1 4 0 1 0 0 3 3 2 1 3 2 3 3 0 0 0 1 0 2 6 1 1 1 1 3 0 6 1 3 0 0 1 0 2 1 2 4 2 0 1 1 1 3 3 1 1 3 4 2 1 4 1 2 1 2 1 2 1 2 1 2 0 3 2 0 0 0 2 1 2 1 6 0 1 0 3 1 0 3 1 1 1 0 4 0 1 1 4 4 1 3 0 6 0 2 1 2 1 3 0 3 1 2 6 3 1 6 7 2 3 2 1 2 1 3 0 1 4 0 2 2 2 1 1 4 2 1 0 2 3 1 1 2 3 0 2 2 1 0 2 4 2 2 0 2 2 2 1 2 0 2 3 1 1 2 4 0 1 2 0 4 0 2 0 0 1 2 0 0 4 0 3 1 2 3 1 6 6 0 1 2 2 1 0 0 0 2 2 2 1 2 3 0 0 3 1 4 0 3 3 3 1 6 4 1 2 1 2 0 2 2 3 0 2 1 3 1 3 1 1 0 1 1 1 1 1 0 8 3 1 1 3 2 2 1 1 3 1 2 2 0 3 2 1 3 2 2 0 0 2 1 3 1 2 0 2 1 3 7 3 2 2 2 0 1 0 1 3 3 3 0 1 2 2 1 1 1 1 0 1 0 2 1 0 3 6 3 2 0 2 7 1 1 3 0 1 1 2 3 6 3 1 3 1 2 1 2 6 2 1 2 1 2 1 4 0 0 1 2 0 2 1 0 1 4 1 2 3 2 3 3 1 1 4 0 2 2 2 0 1 2 1 3 3 3 1 0 2 4 2 2 0 3 2 2 2 4 4 3 0 2 3 3 2 1 1 2 2 2 1 2 1 3 3 2 0 1 1 3 3 0 3 0 1 3 2 2 3 2 3 2 1 2 3 2 2 1 3 2 4 1 2 2 0 6 2 0 2 0 0 4 1 0 2 4 3 1 2 0 4 2 0 2 1 1 2 2 3 0 0 0 0 2 1 1 1 3 3 2 1 0 0 2 0 1 3 0 4 1 3 1 0 1 1 0 4 1 0 1 2 2 0 7 1 0 0 1 1 2 1 0 2 0 1 0 1 2 1 1 2 1 2 0 0 1 1 0 3 1 1 6 0 6 2 1 2 0 1 2 0 0 4 2 1 3 2 0 2 3 1 2 1 2 1 1 2 1 3 1 0 0 2 1 3 3 1 1 4 3 2 1 0 1 1 2 2 0 2 2 3 0 2 1 4 3 2 4 1 3 2 2 1 4 1 1 0 3 4 3 3 0 2 1 1 0 2 1 2 0 0 2 0 1 3 3 2 2 0 2 2 2 2 2 1 1 2 1 0 0 2 1 2 0 0 3 0 2 2 2 2 2 4 1 0 2 4 1 4 2 1 0 1 1 2 0 2 0 1 2 0 0 0 1 1 0 2 6 3 3 2 4 1 1 4 2 3 1 0 2 2 0 2 2 0 1 2 4 1 2 2 2 2 0 1 1 0 3 3 3 1 1 3 1 1 0 1 6 0 2 0 2 1 0 2 1 1 0 2 4 3 2 3 2 2 2 4 3 0 4 2 0 0 3 4 0 2 4 4 1 2 3 3 2 6 2 7 1 4 7 3 3 3 6 12 7 2 3 9 2 3 3 0 4 4 1 3 2 1 3 2 2 6 2 1 1 2 6 2 2 4 1 10 0 3 1 7 1 2 1 1 2 2 2 0 1 2 0 1 0 2 3 1 0 0 2 3 0 1 0 0 6 2 3 1 4 2 2 2 1 2 1 1 0 2 0 0 1 2 2 2 0 2 2 3 3 2 2 3 1 3 1 3 0 0 2 1 1 3 3 2 3 4 2 2 0 1 3 2 0 0 2 2 2 1 0 3 3 1 0 1 1 0 0 2 4 2 2 6 0 4 2 2 2 2 2 3 1 1 3 1 3 2 1 3 1 1 1 1 3 1 6 2 0 1 0 0 0 4 2 0 2 1 0 1 0 1 3 2 0 0 2 1 2 1 1 1 3 2 1 0 3 3 3 1 1 2 4 1 3 4 0 1 1 3 0 2 2 2 1 2 1 1 0 2 1 2 0 3 1 3 3 1 1 3 2 1 3 1 0 0 2 1 2 1 3 0 8 1 0 1 0 2 1 2 3 4 3 2 4 2 1 2 1 0 1 0 4 2 1 4 4 2 0 2 1 0 4 2 6 1 2 3 1 1 1 3 4 3 2 1 2 1 2 2 1 0 2 2 1 1 1 0 0 0 3 3 0 3 2 3 1 1 4 1 2 3 3 1 2 1 1 2 3 6 3 1 2 0 3 2 3 0 1 1 3 0 0 6 2 1 0 1 4 0 2 0 1 0 1 1 2 0 2 2 6 1 2 0 0 1 2 7 2 4 1 1 1 1 2 0 1 0 1 2 0 1 2 1 1 2 3 0 1 2 0 2 2 2 3 2 1 1 4 2 1 0 3 1 0 1 0 2 2 0 1 2 1 1 2 1 1 2 2 3 0 2 2 1 3 1 1 1 1 1 2 2 3 2 0 0 1 3 2 0 1 0 0 3 0 3 4 1 0 1 0 1 3 2 2 2 1 1 2 0 2 1 1 2 2 0 2 3 1 2 0 1 1 0 3 1 0 2 0 1 2 2 0 2 3 1 2 2 3 1 1 3 0 1 0 1 2 0 2 1 3 6 1 3 0 3 1 0 1 2 6 0 3 2 3 1 1 1 2 1 1 2 2 2 0 1 3 1 0 3 4 3 2 1 0 1 3 0 1 2 1 3 0 1 2 3 2 1 2 3 2 12 1 3 6 1 2 6 3 1 1 4 4 2 6 3 7 3 7 1 4 9 6 8 7 8 14 10 10 10 9 18 9 16 6 4 3 7 3 2 7 3 6 4 7 6 3 4 2 0 2 3 3 1 2 3 2 2 1 1 1 3 1 0 0 1 2 1 2 4 1 2 3 1 0 2 3 2 1 2 2 2 1 2 1 3 0 2 2 2 4 0 3 1 3 0 0 2 0 0 1 0 3 2 2 3 1 2 0 0 0 2 1 7 2 2 2 1 1 2 0 1 2 2 6 1 2 0 1 0 2 1 2 0 1 0 1 1 1 2 1 1 2 3 0 2 2 3 4 2 1 0 2 0 1 3 1 0 0 0 1 0 3 0 1 2 0 0 1 2 1 1 3 3 1 3 1 4 1 2 1 1 0 4 1 1 0 1 2 3 1 0 1 1 3 1 4 1 6 3 4 1 0 2 1 1 6 0 6 1 1 1 7 2 3 0 0 1 2 2 3 0 0 3 0 1 0 1 4 0 1 0 0 1 0 0 3 2 1 3 1 2 3 1 2 1 3 0 1 2 0 1 0 1 2 0 0 0 0 1 3 0 1 2 0 0 0 0 1 1 1 1 1 0 1 1 1 4 0 2 3 1 2 1 2 2 2 1 1 1 2 1 0 2 0 0 1 0 2 1 2 3 1 2 1 0 0 0 2 1 1 3 1 0 0 2 1 2 0 7 0 7 1 6 3 3 0 0 1 0 1 3 2 0 2 4 3 1 3 2 1 1 0 4 4 3 1 2 4 1 0 2 3 0 1 1 1 2 0 0 0 3 2 2 0 1 1 2 2 1 1 1 7 7 2 0 3 2 2 1 2 0 0 3 0 1 3 2 1 1 1 2 2 2 1 0 0 0 0 1 2 2 2 0 1 0 3 6 1 0 1 1 1 0 0 2 2 1 1 0 0 2 0 1 0 0 0 1 0 0 3 3 2 0 1 1 3 4 1 4 0 1 1 3 1 3 0 1 0 0 2 1 1 1 0 1 1 1 1 1 2 0 3 2 0 2 2 3 0 0 0 2 1 2 0 0 4 1 0 4 2 1 0 2 2 0 1 1 1 0 1 2 0 2 1 1 1 0 0 0 3 1 0 1 0 2 0 1 0 0 1 2 0 2 0 2 1 1 3 3 2 0 3 4 2 1 4 1 2 0 0 1 0 1 1 1 2 0 1 4 1 1 1 1 1 0 0 3 0 1 1 3 2 4 2 0 4 0 1 0 1 1 4 1 3 0 3 1 0 0 1 2 1 0 4 1 1 3 7 0 1 2 1 2 1 1 0 1 1 1 2 3 4 0 0 0 3 2 0 2 2 3 4 0 3 2 0 1 1 1 0 2 1 1 2 0 2 1 2 0 1 2 1 2 4 1 3 0 2 3 1 1 0 1 2 3 0 4 4 3 0 2 0 2 1 2 1 1 0 2 0 4 2 1 2 2 0 1 1 1 1 6 1 1 3 0 2 2 0 2 0 0 1 0 2 1 1 0 1 4 2 2 0 0 1 1 0 1 0 2 0 2 1 0 1 1 1 3 0 1 2 1 1 2 7 1 0 1 3 2 1 0 2 3 2 2 0 3 1 0 0 4 1 2 1 0 1 0 1 1 1 1 1 1 0 3 0 0 2 3 0 1 1 1 1 2 3 2 1 0 1 0 2 3 1 2 1 2 2 1 2 1 0 0 1 1 0 1 1 1 0 2 1 1 1 1 1 2 2 2 1 0 1 0 2 1 3 0 0 3 2 1 2 2 1 2 0 0 2 0 1 1 1 2 0 1 0 1 1 0 1 0 2 1 2 3 2 0 2 0 0 0 1 2 1 2 2 3 0 1 1 0 0 0 0 1 0 2 2 0 0 1 0 1 2 0 3 1 0 1 2 2 2 1 1 2 2 0 0 1 0 4 1 0 2 2 2 0 2 1 1 1 0 6 2 0 3 2 1 0 1 0 0 1 1 1 4 0 2 0 0 0 1 1 2 2 2 3 0 0 0 1 0 1 3 0 2 2 0 3 2 1 0 2 0 1 1 2 0 0 1 0 1 1 1 0 0 0 0 2 3 4 0 2 2 1 0 0 2 1 2 3 0 0 2 0 1 0 0 1 0 6 1 7 1 2 0 3 2 1 4 2 0 0 0 1 0 4 1 3 2 2 0 1 2 1 1 0 1 3 2 1 1 1 3 2 1 0 1 0 0 0 1 1 1 1 3 1 2 1 2 2 1 2 1 0 1 1 1 1 0 0 2 4 2 2 1 0 1 3 2 2 2 0 1 1 0 1 0 3 1 1 2 0 1 2 0 2 0 0 0 2 0 2 2 1 2 0 4 3 1 0 0 2 1 1 2 1 1 3 1 2 4 3 2 1 2 1 2 1 0 2 1 0 1 0 0 1 0 0 2 2 0 0 1 0 1 1 2 2 0 1 0 1 3 3 1 1 0 3 4 2 2 1 1 1 1 2 2 2 1 0 2 1 2 0 0 0 2 1 0 2 2 2 3 2 0 0 0 2 1 3 0 2 1 2 0 2 3 1 0 1 1 1 0 3 1 3 0 2 2 1 1 1 1 2 2 1 1 0 1 2 0 0 0 0 0 2 3 1 1 2 3 0 1 0 3 0 0 1 1 1 1 1 0 2 1 2 0 0 0 1 1 1 0 3 2 2 0 1 1 2 0 1 1 1 1 3 2 0 1 0 1 0 1 1 1 0 2 0 2 0 1 2 3 0 3 0 1 1 2 1 1 1 0 0 3 1 0 1 0 1 3 1 1 0 1 1 1 0 0 1 2 0 1 2 1 1 2 1 3 2 0 2 1 0 2 2 0 3 0 2 0 0 2 2 0 3 1 0 0 2 0 3 1 0 2 0 1 2 1 2 1 3 2 1 2 2 3 3 3 1 1 0 2 3 1 0 4 1 6 4 1 3 0 1 0 0 0 6 3 1 3 0 1 3 1 1 2 3 1 1 1 2 2 1 0 0 0 1 1 2 0 2 1 2 2 3 6 3 2 0 0 2 1 2 0 0 0 0 0 2 1 2 1 3 0 1 0 0 1 1 0 0 0 2 1 0 1 1 1 1 3 1 1 0 2 4 0 3 1 1 1 1 3 2 1 0 3 2 3 1 0 3 0 0 0 0 2 1 3 2 2 1 2 0 0 2 2 0 1 2 1 2 1 2 1 1 1 1 0 3 1 1 0 1 1 2 3 0 3 1 3 0 2 1 2 2 2 1 0 2 0 3 1 0 0 2 0 3 2 3 1 0 0 2 4 1 1 1 0 2 0 0 3 1 0 1 0 1 1 2 2 1 1 2 0 1 1 0 2 1 1 2 1 1 0 1 3 3 0 1 0 0 1 6 1 2 1 2 0 1 0 3 0 6 1 4 3 2 0 0 1 0 1 3 1 2 0 2 2 3 2 3 2 1 1 0 1 2 1 1 0 2 3 1 0 4 2 0 2 3 3 2 2 1 0 3 4 2 0 2 2 3 0 3 7 0 2 0 0 1 1 1 0 3 1 1 0 0 1 2 2 0 2 0 0 1 0 2 0 0 1 2 1 0 1 1 3 0 2 2 3 0 1 3 2 0 4 1 3 2 0 1 2 1 3 2 2 2 0 1 3 0 0 3 1 1 0 1 0 1 1 2 3 1 3 0 2 3 1 2 3 4 2 1 3 3 2 6 2 2 2 2 2 1 2 2 0 4 2 2 4 3 7 3 4 6 3 4 10 4 4 2 6 9 3 8 8 6 9 10 6 8 8 7 8 7 8 4 10 6 6 3 1 4 6 4 3 7 4 3 4 2 6 9 7 6 2 3 6 4 3 6 2 7 2 7 6 12 3 4 3 3 3 4 4 4 6 8 4 2 1 2 1 0 4 7 7 2 2 4 4 6 2 7 6 9 7 1 2 1 3 1 3 3 4 3 3 4 3 4 6 3 4 7 3 6 8 9 3 7 3 3 6 4 6 1 7 6 3 9 3 3 10 7 8 3 6 4 4 2 4 2 14 8 8 9 8 4 1 2 7 7 7 10 2 8 3 3 10 9 4 4 2 6 12 4 12 9 12 7 9 7 3 7 15 6 9 19 10 7 9 7 14 9 9 8 8 16 15 20 9 10 10 15 21 12 12 8 9 15 24 23 36 21 25 32 33 41 23 44 56 41 47 43 49 66 70 75 93 100 116 117 128 109 145 162 190 196 230 240 273 255 317 309 340 380 427 471 429 453 455 377 398 400 361 303 349 276 213 198 187 134 151 100 128 141 117 104 75 80 77 67 69 78 58 65 56 46 53 49 49 47 41 35 40 32 29 37 31 24 26 24 20 24 15 20 29 16 14 6 12 23 13 18 13 18 14 10 19 14 15 9 18 16 10 8 13 10 10 15 8 18 9 18 9 13 19 15 14 13 9 6 10 13 8 7 10 10 7 6 12 12 8 7 12 4 9 2 7 6 8 10 6 10 9 9 9 7 8 10 8 4 6 8 7 10 4 6 9 8 4 4 0 6 10 3 6 4 4 7 2 8 3 7 7 1 9 7 7 3 7 3 4 4 4 1 6 6 3 4 1 3 2 6 7 2 3 6 3 6 8 4 8 6 7 4 4 4 8 3 3 4 2 3 9 4 2 3 3 1 3 6 2 6 6 7 2 8 3 6 8 2 6 3 3 7 4 3 2 7 0 6 4 4 1 6 4 6 1 7 4 12 4 1 1 9 2 3 7 3 6 6 4 6 2 0 9 2 2 4 3 2 6 3 2 2 1 0 3 1 3 4 3 3 0 3 9 6 4 9 6 2 1 0 4 1 6 2 4 2 1 9 9 1 3 1 2 1 9 2 7 9 3 6 4 4 4 2 0 3 3 3 6 3 9 3 1 4 1 1 4 8 2 4 2 4 4 7 7 4 1 3 2 3 0 4 3 4 1 2 6 2 4 7 6 4 3 6 2 7 7 4 4 2 8 3 4 4 1 3 2 1 1 4 4 3 2 6 1 7 9 4 4 6 7 4 1 2 1 7 3 9 3 3 2 2 6 0 3 6 8 4 3 1 3 6 1 3 6 2 4 4 6 2 2 3 1 0 3 3 2 2 8 6 2 3 2 2 3 1 4 1 2 1 7 1 2 3 3 1 2 3 3 3 2 4 1 6 4 7 1 7 2 2 3 4 2 1 2 1 2 4 2 1 0 3 1 2 2 1 2 3 2 7 6 2 4 3 4 2 1 4 2 2 3 2 6 2 4 2 0 2 4 7 1 4 2 2 6 3 2 3 4 6 4 2 4 2 6 3 3 2 4 3 1 3 0 4 2 3 3 1 2 3 0 4 1 2 3 1 4 2 4 7 3 2 2 0 7 6 1 3 2 2 2 1 2 3 3 8 0 2 8 0 4 8 0 2 6 7 0 3 2 2 2 3 2 4 1 1 7 7 7 2 2 6 0 4 3 1 3 3 3 1 3 3 3 0 6 3 1 2 2 3 2 0 2 2 6 3 6 0 3 2 2 4 1 4 3</intensities>
			</dataPoints>
		</scan>
	</xrdMeasurement>
</xrdMeasurements>