File: Roentgen/Messdaten/Si311_40_30_Ni.xrdml
<?xml version="1.0" encoding="UTF-8"?>
<xrdMeasurements xmlns="http://www.xrdml.com/XRDMeasurement/1.3" xmlns:xsi="http://www.w3.org/2001/XMLSchema-instance" xsi:schemaLocation="http://www.xrdml.com/XRDMeasurement/1.3 http://www.xrdml.com/XRDMeasurement/1.3/XRDMeasurement.xsd" status="Completed">
	<comment>
		<entry>huhuu</entry>
		<entry>Configuration=stage XYZ Phi Psi, Owner=User-1, Creation date=17.03.2006 13:32:17</entry>
		<entry>Goniometer=PW3050/60 (Theta/Theta); Minimum step size 2Theta:0.001; Minimum step size Omega:0.001</entry>
		<entry>Sample stage=IR Stage (Phi, Tilt, X, Y, Z)</entry>
		<entry>Diffractometer system=XPERT-PRO</entry>
		<entry>Measurement program=FP, Owner=User-1, Creation date=18.04.2011 15:14:00</entry>
	</comment>
	<sample type="To be analyzed">
		<id></id>
		<name></name>
		<preparedBy></preparedBy>
	</sample>
	<xrdMeasurement measurementType="Scan" status="Completed" sampleMode="Reflection">
		<comment>
			<entry/>
		</comment>
		<usedWavelength intended="K-Alpha 1">
			<kAlpha1 unit="Angstrom">1.5405980</kAlpha1>
			<kAlpha2 unit="Angstrom">1.5444260</kAlpha2>
			<kBeta unit="Angstrom">1.3922500</kBeta>
			<ratioKAlpha2KAlpha1>0.5000</ratioKAlpha2KAlpha1>
		</usedWavelength>
		<incidentBeamPath>
			<radius unit="mm">240.00</radius>
			<xRayTube id="1010041" name="PW3373/00 Cu LFF DK369848">
				<tension unit="kV">40</tension>
				<current unit="mA">30</current>
				<anodeMaterial>Cu</anodeMaterial>
				<focus type="Line">
					<length unit="mm">12.0</length>
					<width unit="mm">0.4</width>
					<takeOffAngle unit="deg">6.0</takeOffAngle>
				</focus>
			</xRayTube>
			<sollerSlit id="21010002" name="Soller 0.04 rad.">
				<opening unit="rad">0.0400</opening>
			</sollerSlit>
			<mask id="22080002" name="Inc. Mask Fixed  10 mm (MPD/MRD)">
				<distanceToSample unit="mm">101.00</distanceToSample>
				<width unit="mm">6.60</width>
			</mask>
			<divergenceSlit id="22010012" name="Prog. Div. Slit" xsi:type="fixedDivergenceSlitType">
				<distanceToSample unit="mm">140.00</distanceToSample>
				<angle unit="deg">0.25</angle>
			</divergenceSlit>
		</incidentBeamPath>
		<sampleOffset>
			<position axis="2Theta" unit="deg">0.012</position>
			<position axis="Omega" unit="deg">-0.145</position>
		</sampleOffset>
		<diffractedBeamPath>
			<radius unit="mm">240.00</radius>
			<antiScatterSlit id="22060009" name="Prog. AS Slit" xsi:type="automaticAntiScatterSlitType">
				<observedLength unit="mm">0.5</observedLength>
				<offset unit="mm">0.00</offset>
			</antiScatterSlit>
			<detector id="7010012" name="X'Celerator Scientific" xsi:type="rtmsDetectorType">
				<phd>
					<lowerLevel unit="%">45.0</lowerLevel>
					<upperLevel unit="%">80.5</upperLevel>
				</phd>
				<mode>Scanning</mode>
				<activeLength unit="deg">2.122</activeLength>
			</detector>
		</diffractedBeamPath>
		<scan appendNumber="0" mode="Continuous" scanAxis="Gonio" status="Completed">
			<header>
				<startTimeStamp>2015-09-03T11:48:55+02:00</startTimeStamp>
				<endTimeStamp>2015-09-03T12:00:47+02:00</endTimeStamp>
				<author>
					<name>Daniel</name>
				</author>
				<source>
					<applicationSoftware version="2.2">X'Pert Data Collector</applicationSoftware>
					<instrumentControlSoftware version="1.7 ">XPERT-PRO</instrumentControlSoftware>
					<instrumentID>0000000000000819</instrumentID>
				</source>
			</header>
			<dataPoints>
				<positions axis="2Theta" unit="deg">
					<startPosition>15.00108891</startPosition>
					<endPosition>129.99550932</endPosition>
				</positions>
				<positions axis="Omega" unit="deg">
					<startPosition>7.50054446</startPosition>
					<endPosition>64.99775466</endPosition>
				</positions>
				<commonCountingTime unit="seconds">3.175</commonCountingTime>
				<intensities 0 2 0 0 3 2 0 1 0 0 0 1 1 2 3 0 1 4 2 0 2 1 0 1 2 0 1 0 0 1 6 0 2 3 3 0 3 4 3 0 0 1 1 3 3 2 0 1 2 1 4 2 3 3 2 1 0 0 0 2 0 1 4 1 3 1 1 1 3 2 0 2 0 0 3 1 2 0 2 1 1 2 0 1 2 1 1 0 1 1 0 4 1 3 3 1 2 2 1 0 1 2 0 2 2 0 3 0 1 2 2 2 0 0 1 1 3 1 1 1 0 1 4 1 1 2 0 2 1 3 0 2 0 1 2 1 1 1 2 2 2 3 0 3 2 0 2 0 0 0 2 4 3 2 2 0 2 1 1 1 2 0 1 0 2 0 1 1 0 1 1 3 1 1 2 2 2 6 0 2 1 1 3 1 2 0 0 1 1 2 0 0 2 1 0 0 1 0 3 0 0 7 3 2 0 1 1 2 0 1 2 0 1 0 1 2 1 0 3 2 4 2 2 0 1 1 0 2 0 0 2 1 0 1 0 0 3 0 0 0 1 2 1 0 0 0 0 0 0 0 2 0 0 0 0 0 1 2 2 2 0 0 2 1 1 1 1 3 1 2 2 4 2 1 0 0 0 2 2 1 0 1 4 0 1 2 0 0 0 0 1 0 0 1 0 4 1 2 2 2 0 1 0 6 0 0 2 2 1 3 1 0 1 3 0 1 1 1 1 1 2 0 2 0 1 2 1 3 2 0 0 1 1 0 3 0 1 2 1 1 1 2 1 2 1 2 0 1 0 1 0 0 0 1 1 1 2 1 3 1 0 1 2 2 0 0 0 0 0 1 2 3 2 1 0 0 2 0 1 0 0 2 0 0 0 1 0 1 0 1 3 4 0 0 4 1 1 1 2 1 1 1 2 1 0 0 0 2 0 1 0 1 0 0 1 0 0 2 2 2 2 6 0 0 1 4 2 1 1 1 0 0 0 2 2 1 2 2 0 2 1 1 2 1 0 1 1 1 1 1 1 2 1 0 2 1 0 1 1 0 1 1 1 3 0 0 1 2 2 0 2 3 4 3 1 1 2 0 8 2 0 2 4 1 4 0 2 1 3 1 1 0 1 1 0 0 2 0 0 0 2 0 1 2 1 1 3 1 0 0 1 2 1 0 2 1 1 1 3 3 1 1 2 2 1 1 0 0 1 1 2 0 0 0 0 0 0 1 1 0 0 1 3 1 0 2 1 0 2 0 0 0 1 0 0 1 0 0 2 2 2 1 0 0 3 2 0 0 3 0 2 2 2 4 1 1 1 1 1 1 1 1 0 0 1 0 1 1 1 1 2 0 3 2 1 1 0 0 3 0 2 2 0 4 0 0 0 0 1 6 0 2 1 1 0 0 1 1 2 1 0 0 0 3 1 0 1 2 0 1 1 3 1 2 3 3 1 6 2 3 2 2 0 0 1 3 1 1 2 2 0 0 0 2 1 0 1 1 1 1 2 1 0 0 2 0 1 0 0 2 0 0 3 0 2 2 0 0 0 0 1 1 1 2 0 0 1 1 1 3 1 1 3 1 2 1 0 1 2 1 2 3 2 2 3 2 0 1 0 3 0 1 1 0 2 2 0 1 2 2 1 0 0 0 1 1 1 2 0 3 1 2 0 2 1 0 0 2 1 1 0 1 1 0 2 0 1 0 2 0 1 1 1 0 1 1 0 0 1 0 2 0 2 0 1 0 0 1 1 2 1 3 1 2 1 1 0 1 0 0 2 0 2 1 1 1 1 3 0 1 1 1 2 1 0 0 2 2 0 1 1 2 0 1 0 1 2 0 0 1 2 2 1 0 2 0 2 0 2 3 0 2 2 1 0 0 0 0 2 1 0 0 3 0 0 1 0 1 1 0 0 2 1 2 0 1 0 6 1 0 0 1 0 2 1 1 1 1 1 0 3 0 0 1 3 2 0 0 0 0 0 2 1 3 2 1 1 2 1 0 0 1 1 1 0 2 2 0 0 0 2 1 2 0 0 1 0 2 2 2 2 0 0 1 1 1 2 3 2 3 0 2 0 2 0 0 0 2 2 0 2 1 1 0 1 2 1 1 0 0 1 0 2 0 1 0 2 2 0 1 1 1 1 2 2 1 1 0 1 1 0 0 0 4 0 1 2 2 1 0 0 1 0 1 2 0 0 1 0 0 1 0 1 3 2 1 1 1 0 3 1 0 1 1 0 2 0 1 2 1 0 1 1 3 2 2 1 0 0 2 2 3 0 0 0 1 1 2 0 0 0 0 1 3 4 1 1 0 1 2 0 0 2 1 2 1 2 1 1 1 1 1 1 1 2 2 1 0 0 1 0 0 0 1 0 0 0 2 0 2 2 1 0 0 1 0 2 2 1 0 0 1 0 1 1 1 2 2 1 3 2 0 0 0 2 1 2 1 1 0 0 2 1 3 0 0 1 2 2 3 1 2 1 0 0 0 0 0 1 2 0 1 0 0 0 1 2 1 0 1 2 0 0 0 2 2 1 0 1 0 2 1 2 1 0 2 0 1 1 2 0 3 4 1 0 1 2 0 0 1 1 0 1 2 1 0 0 1 0 0 1 0 1 1 1 2 2 3 2 3 1 2 1 0 0 1 0 1 0 1 2 1 0 0 1 1 0 1 2 1 2 1 0 2 0 1 1 1 0 1 1 0 1 0 0 2 0 0 1 1 2 0 1 0 0 1 7 3 1 2 1 2 4 1 0 2 1 2 2 2 1 2 0 2 1 1 0 1 1 0 2 1 0 1 2 2 3 0 0 2 1 2 0 1 2 1 0 0 0 0 0 1 0 0 0 0 2 0 3 1 0 0 1 1 0 0 0 0 0 1 0 1 0 0 1 2 1 0 1 2 3 2 0 1 1 4 0 1 2 0 0 3 2 1 3 1 3 1 2 1 2 1 1 0 2 1 2 2 2 1 1 0 1 0 4 3 2 1 3 1 1 1 1 0 0 2 0 1 0 1 1 1 1 0 0 0 0 0 1 3 0 1 1 6 2 2 3 1 2 0 0 1 1 1 1 2 0 1 0 2 0 1 0 1 0 0 1 3 1 0 1 0 1 0 0 2 1 6 1 1 1 0 1 1 1 1 1 1 0 0 0 0 1 1 1 0 0 1 2 1 0 0 0 0 2 0 2 2 0 1 0 0 3 0 1 3 1 1 2 0 1 0 1 1 1 2 0 3 0 1 2 1 4 2 1 0 2 1 0 0 1 0 3 0 1 1 2 4 0 3 0 1 2 1 3 1 1 0 2 2 2 1 1 2 1 3 1 1 0 1 0 1 0 0 2 0 1 1 1 1 1 1 1 0 0 1 2 0 0 0 0 0 1 1 1 1 1 2 1 2 1 3 1 3 0 0 0 1 2 1 0 1 1 0 0 2 1 2 1 1 1 0 4 0 1 0 2 2 2 2 0 3 0 2 3 3 2 1 0 1 0 0 1 1 2 1 0 1 1 0 2 0 0 0 3 0 1 0 1 0 0 0 1 1 3 0 2 2 1 0 1 0 3 1 1 0 0 0 1 0 4 0 2 0 1 0 1 0 0 1 0 0 2 1 0 0 1 2 1 0 1 1 1 3 1 1 2 4 0 0 0 0 1 0 3 0 1 1 2 0 0 0 2 1 0 1 1 2 2 0 0 2 1 2 0 2 2 1 0 0 1 1 1 3 1 2 3 2 2 0 3 1 0 1 1 1 0 1 0 0 2 1 3 0 0 1 0 0 0 1 0 1 0 1 2 0 1 0 0 0 0 0 0 2 1 0 1 1 1 3 0 2 1 1 1 2 1 2 1 0 1 2 1 1 0 0 0 2 2 3 2 1 1 1 2 0 2 1 1 1 0 2 0 3 2 0 1 2 0 0 0 1 2 1 3 1 2 1 3 0 0 1 1 2 2 1 2 0 2 1 1 2 1 0 1 0 1 0 1 1 1 2 1 0 3 0 0 1 1 0 2 2 1 1 2 1 1 0 1 1 0 3 0 0 1 2 0 1 1 1 1 0 2 0 0 1 4 2 2 1 1 1 0 0 0 1 1 0 2 0 1 0 1 0 2 0 1 2 0 1 1 3 2 2 0 0 1 0 0 1 2 0 1 1 0 0 0 1 0 0 0 1 0 3 2 2 3 2 1 1 1 1 2 1 2 0 2 0 1 1 1 1 0 0 1 2 0 3 0 2 0 1 1 0 2 0 1 1 0 1 0 1 0 2 0 3 1 0 1 1 1 0 0 1 0 1 2 0 2 1 1 1 0 2 1 0 0 0 2 0 2 1 0 2 0 2 1 1 2 0 2 2 1 2 1 1 0 1 0 0 2 1 2 2 2 3 0 1 1 3 0 0 1 1 0 1 1 0 3 0 0 0 0 2 0 0 1 0 1 0 2 1 1 1 0 0 2 1 2 1 2 3 2 2 4 1 3 0 0 3 2 2 0 0 1 2 1 1 0 0 0 0 0 1 1 2 1 1 1 2 2 2 1 1 0 2 1 0 0 0 0 1 3 0 2 0 1 0 2 0 1 0 1 1 1 2 0 1 1 0 0 1 0 2 1 1 1 1 0 0 0 1 1 0 1 2 1 2 2 2 1 2 0 2 0 1 2 2 2 1 0 0 0 0 2 0 1 0 2 0 2 2 0 1 0 1 1 1 2 1 3 1 1 0 1 0 3 0 1 1 1 1 0 2 1 0 1 0 0 1 2 1 0 0 1 0 0 0 1 0 3 0 1 0 0 0 0 1 1 1 2 0 2 0 0 2 0 2 1 1 0 1 0 1 1 0 2 2 4 1 2 3 0 2 0 1 1 0 1 1 0 2 0 0 1 0 1 0 2 1 2 2 2 3 4 0 0 0 0 2 1 0 2 1 1 2 2 0 0 1 1 2 1 1 0 0 1 1 2 1 2 0 1 1 0 0 0 1 1 0 0 2 1 0 2 0 0 1 2 3 1 2 0 0 0 0 2 1 3 0 3 0 0 0 0 1 1 1 2 1 0 1 2 1 1 0 2 2 1 2 0 1 1 3 1 0 1 0 1 0 0 1 0 2 1 1 2 0 0 1 1 0 0 2 0 1 1 1 0 2 3 2 0 2 0 0 2 1 1 1 0 1 1 0 2 1 2 4 1 2 0 2 0 1 1 1 0 1 1 0 1 0 0 2 1 1 2 0 1 0 1 2 1 2 0 1 0 0 0 1 2 0 0 1 1 1 1 0 3 0 0 1 1 0 0 0 1 2 0 0 1 4 2 2 0 2 0 3 1 0 1 0 1 1 1 6 2 1 0 2 0 1 0 0 0 1 0 1 1 2 0 1 2 2 0 2 0 0 0 1 1 3 1 1 3 0 0 0 0 0 2 0 1 1 1 0 0 0 6 0 3 1 1 2 1 2 0 2 3 0 2 0 1 1 0 0 0 0 0 0 1 0 1 0 2 0 0 1 1 0 1 0 2 2 1 1 1 0 1 0 1 2 1 6 0 2 1 0 1 0 0 0 0 1 2 0 1 1 2 2 0 2 2 3 2 1 0 0 0 2 0 3 1 1 0 2 0 2 1 1 2 1 1 1 0 1 0 2 0 1 0 0 1 0 2 0 2 1 0 1 0 1 0 2 0 1 0 0 0 1 0 2 3 2 0 1 1 0 1 0 2 2 0 1 0 2 2 0 1 2 3 2 2 0 1 1 0 2 0 1 1 0 0 0 0 0 0 0 0 2 1 3 2 3 0 0 2 1 1 3 0 1 1 1 2 1 0 0 0 3 0 1 0 0 1 0 0 2 0 0 0 0 0 0 0 0 1 0 1 0 1 0 1 0 0 2 1 0 1 1 1 2 1 3 1 2 0 1 1 0 0 1 0 0 0 0 1 2 0 1 0 1 1 0 1 3 0 3 1 0 2 0 0 1 2 0 1 1 0 1 0 0 2 1 0 2 0 0 1 0 1 1 0 1 1 1 3 0 2 1 3 3 2 3 0 1 0 2 1 0 2 0 2 1 0 1 0 0 0 0 0 2 1 1 1 3 1 1 2 0 0 0 1 0 2 2 2 2 1 1 0 1 2 1 1 1 2 1 2 0 1 0 0 0 3 0 4 3 2 1 3 2 1 0 1 1 2 0 0 0 2 0 0 1 2 1 2 1 1 1 1 0 1 0 0 1 1 2 0 0 1 0 1 2 2 0 0 1 0 0 0 3 1 3 0 3 0 0 1 2 0 0 0 1 0 2 1 1 2 1 1 0 2 0 0 1 0 2 0 1 2 1 1 2 0 0 0 2 0 0 2 0 1 2 1 0 1 0 0 0 1 0 0 2 2 2 1 0 1 0 0 1 1 0 1 0 1 2 1 2 0 1 0 0 0 0 1 0 1 1 1 0 0 1 0 1 2 1 0 1 0 0 1 0 0 1 0 0 1 2 1 3 2 0 1 1 0 0 0 0 0 0 1 0 0 2 2 2 1 0 0 0 1 1 1 1 0 0 1 0 0 1 0 1 2 1 2 1 0 0 0 2 2 2 0 0 1 1 1 4 2 3 0 0 2 0 2 0 0 2 2 2 0 1 1 2 3 1 2 1 2 1 0 3 2 2 0 0 1 1 1 1 1 0 2 0 0 1 0 0 0 0 0 0 2 0 1 1 0 0 1 1 1 1 1 3 0 1 2 1 1 2 1 0 0 0 1 0 0 0 0 0 2 1 0 0 1 0 0 1 0 0 0 1 1 2 2 0 1 0 0 0 0 2 0 0 2 0 1 1 2 0 0 1 2 1 0 0 0 1 0 0 2 0 0 2 3 2 3 1 2 0 1 0 0 1 1 2 1 1 1 0 1 0 1 3 2 2 1 1 2 1 1 3 1 0 0 0 0 0 0 2 0 3 2 1 0 0 0 1 0 0 3 1 3 0 1 0 1 1 1 0 0 0 1 2 0 4 1 2 0 1 0 0 2 0 2 0 1 0 0 0 1 0 0 0 0 0 2 0 1 0 0 2 1 2 1 0 3 1 1 2 2 0 2 0 1 0 2 0 0 0 1 0 1 1 1 1 0 0 0 1 0 1 0 1 0 0 1 3 0 1 1 0 1 0 0 0 0 0 0 2 0 1 1 0 0 0 1 1 2 0 0 1 0 2 0 1 1 2 1 0 0 0 0 2 1 0 2 0 1 0 0 0 1 1 1 1 1 1 0 0 1 0 0 3 0 1 1 1 1 1 0 2 0 0 1 0 1 0 1 0 1 1 0 0 0 2 1 0 1 0 0 1 0 1 0 1 2 2 1 1 0 0 0 0 0 0 1 1 1 1 1 1 0 0 1 2 0 0 4 2 0 1 1 1 1 2 2 1 0 1 4 0 1 0 0 1 0 0 1 3 1 0 2 2 0 1 0 2 1 1 2 0 0 3 0 2 1 1 0 1 2 0 0 0 0 1 1 0 0 1 2 0 1 1 1 1 1 0 1 3 0 0 0 1 2 3 0 1 2 1 0 1 1 0 0 1 1 2 0 2 2 1 0 0 0 2 0 0 1 1 1 1 0 2 0 0 0 1 0 0 0 1 0 0 0 0 0 0 1 1 1 0 0 2 1 2 2 0 0 1 0 0 0 0 1 3 0 0 2 0 0 1 2 0 1 0 0 1 0 0 3 1 0 2 0 0 1 1 2 0 1 2 1 0 1 1 0 0 0 0 1 0 0 1 0 1 1 0 1 2 2 0 0 0 0 0 1 0 1 2 0 0 0 0 1 0 2 0 1 0 2 0 4 2 0 0 2 0 1 1 2 2 0 1 0 1 1 1 2 0 0 2 2 0 0 0 0 2 0 2 1 1 1 3 2 0 0 0 1 0 2 0 1 1 1 2 1 1 1 1 3 1 2 0 0 0 0 0 0 1 0 1 0 2 0 0 0 1 1 1 2 0 3 2 1 0 1 2 0 0 1 2 0 0 1 1 1 2 0 1 1 0 1 0 0 0 1 0 2 0 2 0 1 2 0 1 1 1 1 0 0 0 1 0 1 0 1 0 0 0 0 2 0 0 1 0 1 0 2 1 0 0 1 0 0 0 1 1 1 2 1 1 0 2 0 1 1 0 0 0 0 2 1 0 0 0 1 0 0 3 1 2 1 1 0 1 2 1 0 0 0 0 0 0 3 1 0 2 2 1 2 1 1 1 1 1 1 0 1 1 1 2 1 1 0 2 0 0 0 1 0 2 0 0 1 0 0 0 2 0 1 1 0 4 4 1 0 2 0 1 1 0 1 0 1 0 1 0 1 1 0 0 0 0 1 1 1 3 0 1 2 0 0 3 1 1 0 1 0 0 1 1 2 1 3 1 1 0 2 6 0 3 1 0 1 2 1 0 1 0 0 0 0 0 0 1 0 2 0 0 0 1 1 2 0 1 0 0 3 1 1 1 1 0 1 0 1 1 0 1 1 3 1 0 1 0 2 1 2 2 2 0 2 0 0 0 1 1 0 1 0 1 0 0 0 2 2 0 0 0 2 0 0 0 1 1 0 1 0 1 0 2 0 1 4 1 1 1 1 2 0 1 0 1 1 3 3 0 1 1 3 2 1 0 1 0 0 1 1 1 1 1 2 1 1 2 0 2 0 0 1 0 1 1 1 2 1 1 2 1 2 1 1 0 0 0 2 1 0 0 1 1 0 2 1 0 0 0 1 0 0 1 2 0 0 0 1 0 2 1 0 0 0 0 0 2 0 1 0 1 2 0 1 0 0 3 1 1 0 0 0 0 0 1 3 1 2 0 2 1 0 1 0 0 2 2 1 0 1 0 1 1 0 1 1 2 1 0 1 0 0 2 3 2 0 2 0 1 0 0 0 0 1 0 0 1 2 0 4 0 1 2 1 2 1 0 0 0 1 0 0 1 0 2 2 1 1 1 1 0 1 1 0 0 1 2 1 0 0 1 0 1 1 1 2 0 0 0 1 0 1 1 1 0 1 2 3 0 2 0 0 0 0 2 0 0 2 0 3 0 2 0 2 0 0 1 0 0 0 0 2 1 3 0 1 1 1 0 1 2 0 0 2 1 1 1 0 0 1 0 0 0 1 0 1 0 2 0 0 3 0 1 1 1 0 0 0 0 0 1 0 0 0 1 0 0 0 0 2 1 0 1 0 2 0 0 0 0 1 0 0 1 1 1 1 1 1 2 1 0 1 0 0 0 2 0 0 1 0 0 0 2 1 0 0 1 1 0 3 0 1 0 0 0 0 0 0 0 3 0 0 0 1 0 0 0 1 1 0 1 1 2 0 0 0 1 1 1 0 0 2 0 1 1 0 0 1 0 0 1 2 2 0 2 0 1 0 0 0 1 1 0 2 0 1 1 0 0 1 0 1 1 0 1 1 0 1 0 0 1 1 0 0 1 1 3 2 1 0 0 0 1 0 1 1 0 1 2 0 0 0 0 1 1 0 1 0 0 1 0 0 1 0 4 1 1 1 1 0 0 0 1 0 0 0 0 1 0 0 0 0 1 2 0 1 0 0 1 0 0 0 1 0 1 0 4 1 1 0 0 0 0 1 0 1 0 1 0 0 0 1 1 0 1 1 2 0 1 0 0 0 2 0 0 0 1 0 0 0 2 0 0 1 1 1 0 0 2 1 0 0 0 0 1 0 2 1 1 0 1 0 0 1 0 0 2 2 0 0 0 0 2 1 0 1 0 0 2 0 4 0 0 0 0 2 1 0 1 0 0 0 0 0 0 1 0 1 1 0 1 1 0 0 0 1 0 1 0 2 0 2 1 1 2 0 0 0 0 2 1 0 0 1 0 1 0 1 1 0 0 0 1 0 1 1 1 0 0 3 1 1 0 0 0 1 1 1 0 2 1 1 2 0 0 1 2 0 0 0 0 2 0 1 2 0 1 2 0 1 1 2 0 0 1 1 0 1 0 2 3 1 0 0 2 0 0 1 1 0 1 1 3 0 0 0 2 0 1 2 2 2 0 1 0 1 0 0 3 0 0 1 1 1 0 0 0 1 0 0 0 1 0 0 0 1 3 1 1 0 1 3 1 1 0 1 1 1 2 0 1 1 0 1 0 1 1 0 0 0 1 0 1 0 0 1 1 2 0 0 1 0 1 1 2 1 0 0 1 0 1 1 0 1 0 1 1 2 0 0 1 0 0 1 0 1 1 1 0 2 0 1 0 2 0 0 1 0 0 1 1 1 0 1 2 0 0 1 0 1 1 1 0 0 0 1 0 0 0 2 0 0 0 1 0 1 1 1 3 0 0 0 2 0 0 1 0 0 0 0 0 1 1 1 0 0 0 1 0 0 0 0 1 0 1 1 0 0 0 0 0 0 1 1 0 0 1 0 1 0 0 0 0 0 0 1 0 0 1 0 0 0 0 1 0 0 0 0 0 1 1 1 3 1 0 1 0 0 1 0 2 0 0 1 0 1 0 0 1 0 0 0 1 0 2 0 0 1 0 1 0 0 0 1 3 0 1 1 0 3 0 0 0 1 1 0 0 0 0 0 0 1 0 0 0 1 1 0 0 0 0 1 1 2 1 0 1 0 2 0 0 0 0 0 1 0 0 1 1 1 1 0 3 0 0 0 1 0 0 0 1 0 0 1 4 0 0 1 0 0 2 1 1 0 1 2 0 2 0 0 0 0 0 0 1 0 0 0 1 1 0 2 0 0 0 1 0 0 1 1 1 0 0 0 0 1 1 0 1 0 2 2 1 1 0 0 1 1 0 1 0 0 0 0 0 1 1 0 0 3 0 1 1 0 0 0 1 2 0 0 0 0 1 0 1 0 0 1 0 2 1 1 1 0 0 0 2 0 0 2 0 2 1 2 1 1 0 0 1 0 0 1 1 1 0 0 2 1 0 1 0 0 0 0 0 0 0 0 1 0 0 1 0 0 1 0 1 0 1 1 0 0 2 1 0 0 0 0 0 0 0 0 0 1 0 0 1 0 0 0 0 2 0 1 0 0 0 1 1 1 2 0 0 1 0 0 0 1 0 1 0 0 0 0 0 0 2 0 0 0 1 2 0 0 0 0 1 0 0 1 1 0 0 0 0 0 1 0 1 0 1 0 0 0 2 1 0 0 0 1 1 0 0 0 0 1 1 0 1 1 0 0 0 1 1 0 0 0 1 0 0 0 2 0 0 2 0 0 0 0 0 0 0 0 1 1 1 0 0 0 0 0 0 0 0 1 1 0 0 1 0 1 0 0 0 0 0 1 0 0 0 0 1 1 0 1 1 1 0 0 1 0 0 0 1 0 1 0 0 0 0 1 0 0 0 0 0 0 0 0 1 0 1 0 0 0 0 0 0 0 1 0 0 0 1 0 0 1 0 0 0 0 0 0 0 0 0 1 0 0 2 0 0 0 0 0 0 1 1 0 1 0 1 0 0 0 0 0 0 1 0 0 1 0 0 0 0 0 1 0 0 0 1 0 1 0 1 0 0 0 1 0 1 0 1 1 0 0 1 1 0 1 0 1 0 0 0 0 0 0 0 0 1 0 0 0 0 0 0 0 0 0 0 0 0 1 0 0 1 1 1 0 0 1 0 0 1 0 0 1 2 1 0 0 0 1 0 1 0 0 0 0 2 0 0 0 0 0 0 1 1 2 0 1 0 0 0 0 0 1 0 0 0 0 0 0 0 0 0 1 0 0 0 0 2 0 1 0 1 2 1 0 1 0 0 0 0 0 1 0 0 0 0 0 0 1 1 1 1 2 1 0 0 0 0 0 2 1 1 0 0 0 0 1 2 0 0 0 1 1 0 0 0 1 0 0 1 0 1 0 0 0 3 0 0 1 0 0 1 0 0 0 0 0 0 0 0 0 0 0 1 0 1 0 0 1 0 0 1 0 1 0 0 1 0 0 0 0 0 0 0 0 1 1 0 1 0 1 0 1 0 1 1 0 0 1 1 0 1 0 1 0 0 0 0 0 0 0 1 0 0 0 0 0 1 0 0 0 1 1 0 1 1 0 1 0 0 0 1 0 0 1 0 0 0 0 0 0 0 0 0 0 1 0 0 1 0 0 0 0 0 0 1 0 0 0 1 0 0 1 0 0 1 0 1 0 2 0 2 1 0 1 1 0 1 0 1 1 1 1 1 1 2 0 0 0 0 0 1 1 0 0 1 0 0 1 0 0 0 0 0 0 1 2 1 0 0 1 0 1 0 0 0 0 0 0 0 0 0 0 0 2 1 0 2 0 0 2 0 0 0 0 1 0 0 1 0 0 0 0 0 0 2 0 0 0 0 0 0 0 1 1 0 0 0 0 0 1 0 0 1 2 1 1 0 0 0 1 0 0 1 0 0 0 0 0 1 0 0 0 1 0 1 0 0 1 0 0 0 0 0 0 2 1 1 0 0 0 2 0 0 0 0 0 0 0 0 0 0 0 0 0 0 0 0 1 0 0 0 0 2 0 1 0 0 0 0 1 2 0 0 0 0 1 0 0 0 0 0 0 1 1 0 1 0 0 0 0 0 0 0 0 0 0 0 0 0 0 0 0 0 1 0 0 0 0 0 0 0 0 0 0 0 0 0 0 0 0 0 1 0 1 0 1 1 1 0 0 0 0 0 0 0 0 0 0 1 0 0 0 0 0 0 0 1 0 0 1 1 0 1 0 1 1 1 0 1 0 1 0 0 0 0 2 0 0 1 1 0 0 1 0 0 0 0 0 0 0 0 0 0 0 0 1 0 0 1 0 0 2 1 1 0 0 0 0 1 0 0 0 0 0 1 0 0 0 0 0 0 0 0 0 1 0 1 0 0 1 0 0 1 1 1 1 0 0 1 0 0 0 0 0 0 0 0 0 0 1 0 0 0 1 1 0 0 0 0 0 0 1 1 0 0 0 0 0 0 0 0 0 0 0 0 0 0 0 1 0 0 0 0 1 0 0 0 1 0 1 0 0 0 0 1 0 0 0 2 0 0 0 1 0 0 0 1 0 2 1 0 0 0 0 0 1 0 1 1 1 0 0 0 0 0 0 1 0 1 0 0 0 0 0 0 0 0 0 0 0 1 1 0 1 1 0 0 0 0 0 0 0 0 0 0 1 0 0 0 0 0 0 1 0 0 3 1 0 0 0 0 0 0 0 0 0 0 0 0 0 0 0 0 0 1 0 0 0 0 0 0 0 1 0 0 0 0 1 0 0 0 0 0 0 2 0 1 0 1 0 0 0 0 0 0 0 0 0 0 0 0 0 1 0 0 0 1 0 0 1 0 0 0 1 0 0 0 0 0 0 1 1 0 0 1 0 0 0 0 0 0 0 0 0 1 0 0 0 0 0 0 0 0 0 0 0 0 0 1 0 0 0 0 0 0 0 0 0 1 0 0 0 0 0 0 0 0 0 0 0 0 0 0 0 0 0 1 0 0 1 0 0 2 0 0 0 1 1 0 0 0 0 0 0 1 1 1 0 0 0 0 0 0 2 0 0 0 0 1 0 0 0 0 1 0 0 1 0 0 0 0 1 0 0 1 0 0 0 0 0 0 1 0 0 0 0 0 0 0 0 0 1 1 0 0 0 1 0 0 0 0 1 0 0 0 0 0 0 0 0 0 0 0 0 0 0 0 1 0 0 0 0 0 0 0 1 0 0 0 0 0 0 0 0 1 1 0 0 0 0 1 0 1 0 0 0 0 0 0 0 0 0 0 0 0 0 1 0 0 0 0 0 0 0 0 0 0 0 0 0 0 0 0 0 0 0 0 0 0 0 1 0 0 0 1 2 0 0 0 0 1 0 0 0 0 0 0 0 0 0 0 1 0 0 0 0 0 0 0 0 0 0 0 0 0 0 1 0 0 0 1 0 2 1 0 0 0 0 1 0 0 0 0 0 0 0 0 0 1 0 0 0 0 0 0 0 0 0 0 2 1 1 0 0 1 1 0 0 0 0 0 3 0 1 2 0 1 1 1 0 0 0 0 1 1 1 2 1 0 1 1 1 1 2 1 0 1 0 0 1 1 0 0 0 0 1 0 0 1 1 0 2 0 3 0 1 1 0 2 1 1 1 0 1 1 3 0 0 0 1 1 0 0 2 2 0 1 1 0 1 1 2 0 3 0 0 1 0 1 2 1 2 0 0 1 0 1 0 1 0 0 1 0 1 0 2 0 1 0 0 1 1 2 2 1 3 2 0 2 0 0 0 1 2 0 0 0 0 2 0 1 0 1 0 1 0 0 0 1 1 1 1 2 0 3 2 1 1 2 2 1 3 1 2 1 1 1 1 1 4 7 12 8 8 19 9 19 10 8 9 4 4 7 0 3 4 0 1 1 2 3 1 2 2 2 0 3 1 1 1 1 2 0 2 0 2 2 2 1 2 1 0 3 0 2 0 1 0 1 1 3 2 0 0 0 1 3 1 1 0 0 0 0 1 1 0 2 1 2 1 0 1 1 1 1 1 0 3 0 2 1 1 0 2 1 0 0 0 0 3 0 2 0 2 1 1 1 0 1 1 1 0 0 1 0 1 0 0 1 1 2 1 1 0 0 0 2 0 0 0 0 0 1 0 0 0 0 0 1 0 0 1 0 0 0 0 1 0 0 0 1 1 0 0 0 1 0 0 0 0 0 1 0 0 0 0 0 1 0 0 0 1 0 0 0 0 0 0 0 1 1 0 0 0 0 0 0 0 0 0 0 1 0 1 0 0 0 0 0 0 0 0 0 0 1 2 0 0 0 0 1 0 1 1 0 0 0 0 0 0 0 0 0 1 0 0 0 0 0 1 0 1 0 0 0 0 0 0 0 0 0 0 0 0 1 1 0 0 1 0 0 0 0 0 0 1 0 0 1 2 0 2 0 1 0 0 0 0 1 0 0 1 0 0 0 0 0 0 1 0 2 0 0 0 0 0 1 0 0 0 1 0 0 0 0 0 0 1 0 0 1 0 1 1 0 1 1 0 1 0 0 0 0 0 1 0 0 0 0 1 0 0 0 0 2 2 2 0 0 0 1 0 1 0 0 0 0 2 0 0 0 1 0 0 0 0 0 0 0 0 0 0 0 0 0 1 1 0 0 1 0 0 0 0 0 0 0 0 0 1 0 0 0 0 0 1 0 0 0 0 0 0 0 0 0 1 1 0 0 0 0 0 0 1 0 0 0 0 0 0 0 0 2 0 0 0 0 0 1 0 1 0 1 0 0 0 0 0 0 0 0 1 0 2 0 0 0 0 0 0 0 0 0 0 0 0 1 0 1 1 2 0 0 0 0 0 0 0 0 1 0 0 1 0 1 0 0 0 0 1 0 1 1 2 0 2 0 0 1 2 0 0 1 1 1 0 0 0 0 0 0 0 1 0 1 0 1 0 1 1 1 0 0 0 0 0 0 0 0 0 0 0 1 0 0 0 0 0 0 0 0 1 0 0 0 0 0 0 0 0 0 0 0 0 0 1 0 0 0 1 0 0 0 0 0 1 0 1 1 0 0 0 1 0 0 0 1 0 1 1 1 0 0 0 0 0 1 0 0 0 1 0 0 0 1 0 0 0 1 2 0 2 1 0 0 0 1 0 0 0 0 1 0 0 1 0 0 0 1 0 0 0 0 0 0 0 0 0 0 0 1 0 0 1 0 0 1 0 1 0 0 2 0 0 0 2 0 0 0 1 0 0 0 1 0 0 1 0 1 0 0 0 0 0 0 0 0 0 0 0 0 0 0 2 1 1 0 0 1 0 0 0 0 0 1 0 4 2 1 3 7 0 2 6 7 7 8 3 8 6 1 3 7 7 2 10 7 1 6 7 4 2 3 4 2 6 6 4 7 3 3 3 3 6 6 1 2 3 7 1 7 3 6 2 2 7 1 3 3 3 4 2 4 6 10 8 2 4 6 3 3 7 2 4 3 8 3 2 4 3 2 3 3 8 4 7 4 6 2 7 2 1 0 7 2 6 7 3 2 2 1 3 2 2 6 7 2 3 10 2 3 6 3 3 4 6 0 2 6 3 4 6 4 2 4 2 2 9 4 8 4 6 1 6 1 0 0 12 7 2 3 8 2 1 7 4 3 7 2 6 1 8 2 6 7 3 2 2 8 2 4 3 6 3 9 7 6 6 7 1 4 3 4 4 3 2 1 2 6 3 1 2 4 6 7 9 1 3 2 4 1 7 2 3 6 4 6 4 4 3 8 7 2 8 3 9 7 7 2 1 3 3 3 7 3 4 1 7 8 4 4 3 6 4 7 6 7 6 8 3 7 4 3 9 12 1 6 2 6 2 0 6 8 3 3 4 6 7 3 3 3 8 3 3 4 4 7 8 3 3 8 4 7 8 4 3 7 8 12 9 12 3 9 6 9 10 7 1 7 10 7 7 8 0 6 9 10 8 10 2 9 15 9 16 8 12 10 10 6 8 6 15 8 14 19 12 12 14 10 13 13 18 16 13 10 16 14 18 19 25 20 15 32 30 30 32 37 40 25 40 46 33 37 42 43 29 36 41 31 47 27 37 37 35 41 32 50 41 43 49 52 47 60 65 65 83 95 121 122 151 140 183 204 191 261 280 360 442 555 723 1023 1535 2577 3825 4781 5213 4615 3625 2588 1802 1255 935 688 583 415 344 282 293 247 261 244 243 271 294 333 389 487 619 901 1349 1909 2289 2431 2291 1862 1406 962 664 534 366 287 198 196 176 140 152 116 115 93 81 64 66 56 55 56 46 48 43 48 38 29 48 30 31 35 25 32 30 27 31 21 36 20 25 16 16 16 14 14 20 14 10 18 10 14 12 12 12 12 19 16 18 14 10 12 25 9 18 9 13 12 7 7 6 9 2 10 10 8 3 9 4 10 4 3 7 20 7 4 10 12 6 10 4 10 4 8 9 12 6 6 6 6 4 14 8 10 12 6 9 6 7 13 10 7 13 7 6 7 7 13 2 6 13 6 6 7 8 7 2 2 3 6 3 4 10 6 4 4 2 9 7 4 9 8 8 6 8 3 2 4 8 7 4 4 7 6 7 3 7 4 4 3 7 6 0 2 4 2 10 7 7 2 7 4 2 7 2 7 4 2 8 2 4 4 2 3 2 2 3 6 6 7 2 1 6 7 8 1 3 7 3 1 6 4 3 6 3 6 2 3 1 2 9 2 1 7 6 3 7 4 3 2 3 4 3 3 8 1 3 1 2 2 1 6 6 2 1 1 6 1 4 2 3 1 4 3 2 1 3 1 3 2 2 7 6 2 7 1 4 3 1 1 6 6 4 8 1 1 3 2 4 3 8 4 3 6 2 3 1 4 3 2 3 2 2 7 1 3 2 6 4 7 4 2 3 2 6 2 3 2 3 1 2 2 2 4 4 1 3 3 7 4 0 1 1 4 4 2 0 1 1 1 4 9 1 4 7 1 2 2 3 2 2 3 2 2 2 1 4 0 3 4 1 3 4 3 6 3 3 2 2 2 1 4 4 2 1 3 2 6 2 3 4 0 1 2 2 3 1 1 4 4 3 2 3 2 1 2 4 2 1 2 1 3 0 2 1 2 2 7 3 1 1 2 2 4 3 1 0 1 1 8 2 1 2 1 0 4 3 1 3 4 0 3 0 1 0 0 3 1 1 2 1 6 2 1 6 3 2 2 3 0 3 3 0 2 2 2 1 2 3 1 0 4 0 0 4 0 4 2 2 3 1 2 2 1 1 1 1 1 1 1 0 1 10 2 1 4 3 0 6 1 0 0 3 2 1 0 0 3 0 0 1 3 2 0 2 4 1 3 1 2 2 1 0 3 0 1 2 6 0 0 2 1 1 3 0 3 2 0 4 1 1 4 1 3 1 1 0 4 3 6 1 1 2 3 1 2 0 4 2 1 2 2 2 1 0 0 1 1 2 2 3 1 2 3 3 2 2 3 2 1 2 2 1 2 2 1 3 1 3 2 4 1 0 4 2 1 1 2 1 3 2 3 0 2 0 2 3 0 6 2 1 1 1 0 1 2 0 2 1 2 2 0 2 1 0 1 0 2 1 3 2 4 0 1 3 3 1 1 8 3 2 1 1 0 0 2 2 0 3 2 1 2 3 2 0 2 1 2 1 2 4 2 3 4 0 2 2 1 6 3 2 2 2 2 1 1 1 1 2 2 1 2 2 2 2 0 1 0 1 1 1 3 0 1 0 1 0 0 1 2 0 1 3 0 3 1 0 2 3 0 1 4 2 2 2 0 0 1 2 2 2 2 2 3 1 0 2 0 4 4 1 2 0 1 0 1 3 0 3 3 4 3 2 0 3 0 2 3 0 3 0 0 4 2 2 0 1 0 0 1 1 1 1 0 1 1 2 2 3 3 1 0 2 3 0 1 1 0 1 3 1 0 2 0 1 1 1 2 2 0 0 3 0 1 3 2 0 2 0 3 2 2 1 1 1 2 2 2 1 1 2 1 3 1 1 3 2 4 0 1 1 0 3 0 1 1 0 0 1 3 2 1 0 1 1 1 1 4 0 1 1 3 2 0 2 3 2 1 1 0 3 1 3 2 2 2 2 0 2 1 1 0 2 1 0 0 1 0 0 2 1 4 0 2 2 4 1 0 3 3 1 2 2 1 1 3 0 0 0 1 2 0 1 1 1 0 0 2 1 1 2 1 1 2 0 1 2 0 2 1 2 1 2 3 1 0 2 0 0 0 1 0 0 0 1 2 0 1 3 0 1 0 1 2 2 0 0 4 2 2 0 2 1 1 0 0 2 1 2 1 0 2 1 1 1 2 0 3 0 0 2 0 0 1 0 1 1 0 0 2 2 0 0 1 1 1 1 4 2 1 1 3 2 0 1 0 1 2 1 1 6 0 3 6 6 2 0 1 4 1 2 3 2 2 1 3 0 2 2 1 1 2 1 3 2 3 1 1 2 2 0 1 0 0 0 2 1 2 0 1 1 1 2 0 2 1 1 1 1 3 1 1 1 0 1 4 2 0 0 0 0 0 0 0 1 2 0 0 1 1 0 1 1 2 1 0 0 2 2 0 3 1 2 0 1 0 4 1 0 3 1 0 2 2 0 1 1 2 0 0 0 2 2 1 0 1 0 1 3 2 1 0 1 0 0 1 0 0 1 1 0 1 3 0 0 2 0 1 0 3 1 2 1 1 2 1 1 4 2 1 1 0 2 1 0 0 0 1 2 1 0 1 1 0 2 1 1 2 1 0 0 1 0 1 1 0 0 0 0 1 2 2 1 1 0 0 2 0 1 2 0 1 1 1 0 0 0 1 2 2 0 0 1 0 1 2 0 1 1 0 1 2 0 0 0 0 2 0 0 2 3 1 0 2 0 1 1 1 1 0 1 2 1 1 2 0 1 0 1 1 0 0 1 0 0 1 4 1 0 2 2 1 3 0 4 0 0 0 2 1 1 0 1 1 1 1 1 1 0 2 1 0 0 0 1 0 0 0 1 2 1 0 1 1 1 0 0 1 1 2 1 1 4 0 1 2 2 0 0 1 1 3 1 0 1 1 0 1 0 3 0 1 0 1 0 1 0 1 0 0 2 0 1 2 0 0 0 0 1 1 0 0 1 0 0 2 1 0 0 2 0 0 0 1 2 2 1 2 3 1 0 4 2 0 0 1 1 0 0 0 0 0 1 1 0 0 0 0 0 0 0 1 2 0 0 2 0 0 1 0 2 0 0 0 0 1 1 0 1 0 1 1 1 0 0 0 0 1 0 0 2 0 0 1 0 0 1 1 0 0 0 0 1 2 0 2 1 1 0 1 0 2 1 1 0 0 0 0 1 0 0 1 2 2 1 0 0 1 1 0 1 0 0 1 2 0 2 0 3 0 0 0 2 0 1 0 0 0 0 0 3 1 1 1 0 0 0 0 0 4 2 1 1 1 1 2 1 1 0 0 0 1 4 0 1 1 0 0 1 0 1 1 1 0 1 2 1 1 0 1 0 3 0 4 0 1 1 0 0 1 1 0 0 1 0 0 2 1 0 1 1 2 0 0 1 1 2 3 2 0 0 0 1 0 1 0 0 0 1 0 3 1 1 0 1 0 0 0 0 0 1 1 0 1 0 0 0 1 0 4 0 6 2 1 0 1 1 1 1 0 1 2 2 0 1 0 0 0 0 0 0 0 2 1 1 2 3 1 2 0 1 0 0 1 0 0 0 1 1 1 1 0 1 1 0 0 0 0 0 1 0 2 0 1 0 2 1 1 0 2 1 1 1 0 0 0 1 1 2 1 1 1 1 0 0 2 1 0 1 1 1 0 0 3 0 1 1 1 0 1 0 0 0 1 0 2 3 0 2 2 0 0 1 0 1 0 0 0 0 0 2 1 0 0 0 3 1 0 0 1 0 2 0 0 1 0 0 1 0 0 0 1 0 1 0 0 0 2 0 0 2 0 0 0 0 0 0 2 0 1 0 0 0 0 0 0 0 0 1 0 0 0 0 0 0 0 1 0 2 0 0 0 0 1 0 0 0 0 2 0 0 0 2 0 0 1 0 1 0 1 1 0 0 2 0 1 0 0 0 0 1 0 3 1 1 0 0 3 1 1 0 0 1 1 0 0 1 0 1 0 1 0 1 0 0 0 1 2 0 0 0 2 0 1 0 1 0 0 1 2 1 0 0 1 0 0 0 0 0 0 0 0 0 1 0 0 0 0 0 0 1 0 0 0 1 2 0 0 3 0 0 0 0 1 1 0 0 0 1 0 0 0 0 0 1 1 1 1 0 0 0 0 2 0 2 0 2 1 1 1 0 1 0 0 0 1 3 0 0 0 0 0 0 1 0 1 2 0 0 0 0 0 1 0 1 0 0 0 0 0 2 0 1 1 0 0 1 0 1 0 0 0 0 0 0 0 0 1 1 2 1 2 1 0 0 0 0 0 1 1 0 1 1 0 1 1 1 1 0 1 1 0 0 0 1 0 0 1 1 1 2 1 0 0 2 0 0 1 0 3 1 0 0 0 0 2 0 0 1 0 0 0 0 0 1 0 1 1 1 1 1 0 1 0 0 0 0 1 1 1 0 0 0 1 1 0 0 1 0 1 0 0 2 0 1 1 0 0 2 0 1 1 1 0 0 0 0 0 0 0 0 0 0 0 0 1 2 0 0 0 0 0 0 0 0 0 0 0 0 0 1 1 1 0 1 1 0 0 2 0 0 0 0 0 0 0 0 0 0 1 0 0 0 2 1 1 0 0 1 1 0 0 1 0 0 0 1 3 0 1 0 0 1 0 0 0 0 0 0 0 1 0 0 2 1 0 0 0 0 0 0 0 0 0 1 0 0 0 0 0 1 0 0 0 1 0 4 0 0 0 1 0 1 0 0 0 1 0 0 0 0 1 0 0 1 0 0 0 1 0 0 0 0 0 1 0 0 0 1 0 0 0 0 0 0 0 1 1 1 1 0 0 1 2 0 0 1 1 0 0 0 0 1 1 0 0 0 2 0 0 1 0 0 0 0 0 0 1 0 0 0 1 1 0 0 0 0 0 0 0 0 0 0 1 0 1 0 1 0 0 0 1 0 1 1 1 1 0 1 0 1 0 0 0 0 0 0 0 0 1 1 2 0 0 1 0 1 0 0 0 1 0 0 1 0 1 0 1 1 1 0 1 0 0 0 1 1 1 0 0 0 0 1 0 0 1 0 1 0 0 1 0 1 0 0 1 0 0 1 0 0 1 0 0 0 0 0 0 0 2 1 0 1 0 1 0 0 1 1 2 1 0 1 0 0 0 0 0 0 0 0 0 0 1 0 0 1 0 0 2 1 0 0 0 0 0 1 1 0 1 0 0 0 1 0 1 1 0 0 1 1 0 1 1 1 0 3 1 0 0 1 0 0 0 0 0 0 0 0 1 0 0 0 0 0 1 0 0 0 2 0 1 0 1 0 0 0 0 0 0 0 1 1 0 0 1 1 0 1 0 0 1 0 1 0 1 0 0 0 0 0 1 1 0 1 1 2 1 1 0 2 0 1 1 0 0 0 1 0 0 0 0 1 0 0 1 1 0 2 0 0 0 0 1 0 1 0 0 0 1 0 0 0 1 0 0 1 0 1 0 1 1 1 2 0 0 1 0 0 0 0 0 2 1 0 1 1 1 0 0 0 0 0 1 1 0 0 0 1 1 1 0 0 0 1 1 1 1 1 0 0 0 0 1 1 0 0 0 0 0 0 0 0 0 1 1 0 1 0 0 1 1 0 0 0 0 0 1 0 0 0 0 0 0 0 0 0 0 0 0 0 0 0 1 2 0 0 1 0 1 0 0 1 0 0 1 0 0 0 0 0 1 1 0 1 0 0 1 1 1 0 2 0 0 2 2 2 0 0 1 2 0 0 1 0 0 0 0 0 0 0 1 0 0 0 0 0 0 0 0 0 0 0 0 0 0 0 0 0 1 1 0 2 2 1 0 0 0 0 0 0 1 1 1 0 0 0 0 0 1 0 0 0 0 0 0 1 0 0 0 0 0 0 1 0 1 0 0 0 1 1 0 0 0 0 0 0 0 0 0 0 0 0 0 0 0 0 0 0 0 0 0 0 0 0 0 0 0 0 1 1 0 0 1 0 0 0 0 0 1 0 1 1 0 1 1 0 0 0 2 0 1 0 0 0 0 0 0 0 0 0 0 0 0 0 0 0 0 0 1 0 0 0 0 0 0 0 0 0 1 0 0 0 0 1 1 0 0 1 0 0 0 0 0 0 0 1 0 0 0 1 0 1 0 0 1 0 1 0 0 0 1 0 0 1 1 0 0 0 0 1 0 0 0 1 0 1 0 0 0 0 0 1 0 0 2 0 1 0 0 0 0 0 2 1 0 1 0 0 1 0 0 0 1 0 2 1 0 0 2 2 2 1 0 0 0 0 2 1 0 1 0 0 0 0 2 0 0 1 0 1 0 0 0 0 1 0 0 0 0 0 0 0 0 2 0 2 1 0 0 0 1 0 0 2 0 0 1 0 0 0 1 1 0 1 0 0 0 1 0 0 0 0 0 0 0 1 0 0 1 0 0 0 0 0 2 0 1 1 0 0 1 0 0 0 0 0 0 0 1 0 1 1 0 1 0 1 2 1 0 0 0 1 0 0 0 0 1 0 0 0 0 0 1 0 0 0 2 0 0 0 0 1 1 0 0 0 0 1 0 1 0 1 0 0 2 0 1 0 0 0 0 0 0 2 0 0 0 0 0 0 0 0 0 0 0 0 0 0 0 0 0 0 2 0 0 1 0 0 0 0 0 0 1 0 0 0 0 0 0 0 0 1 0 0 1 0 1 0 0 1 0 0 0 0 1 0 0 0 0 0 0 0 0 0 1 1 0 0 0 0 0 0 1 1 0 0 1 0 0 0 0 0 0 0 0 0 0 1 1 2 1 0 0 0 0 2 0 0 0 0 0 0 0 0 0 0 0 0 0 0 0 0 1 0 1 0 1 0 0 0 0 0 1 0 0 0 1 0 0 0 1 0 0 0 1 0 0 0 0 0 0 0 0 1 1 1 0 2 0 0 0 0 0 0 1 0 0 0 0 1 0 0 3 1 0 0 0 0 0 0 3 0 1 0 0 0 0 0 0 0 1 1 0 1 0 2 1 1 2 0 0 0 0 2 0 0 0 0 0 0 1 1 1 0 0 0 0 0 0 0 0 0 0 1 0 0 0 0 0 0 0 1 1 0 0 0 0 0 1 1 0 0 0 0 0 0 0 0 0 0 0 1 0 0 0 0 0 0 0 1 0 0 0 0 0 0 0 0 0 1 0 0 0 0 1 0 0 0 0 0 0 2 0 0 2 0 1 0 1 0 1 0 0 0 0 0 1 0 0 0 1 0 0 0 0 1 0 0 0 0 0 0 0 0 1 0 0 0 1 0 0 1 0 0 0 0 0 0 1 0 1 0 2 0 0 1 0 1 1 0 0 0 0 0 0 0 0 0 0 0 1 0 0 0 0 0 0 1 0 0 0 0 0 0 0 1 1 0 0 1 0 0 0 1 1 0 0 0 0 0 0 0 0 0 1 1 0 0 0 0 1 0 0 0 0 0 0 0 0 0 0 0 0 0 0 0 0 0 1 1 0 0 0 0 1 0 0 0 0 0 1 0 0 0 0 0 0 1 0 0 0 0 0 0 0 1 0 0 0 0 0 0 0 0 1 0 1 0 0 0 0 0 0 0 0 0 1 0 0 0 0 0 0 0 0 0 0 0 1 0 0 0 0 0 0 0 0 0 0 0 0 1 0 0 0 0 0 0 0 0 1 0 0 0 0 0 0 0 0 0 0 0 0 0 0 0 2 0 0 0 0 0 0 1 0 0 1 0 0 0 0 0 0 0 0 1 0 0 0 0 1 0 0 0 0 0 1 0 0 0 0 0 0 1 0 0 0 0 0 1 1 0 0 0 0 0 0 0 0 0 0 0 0 0 1 0 1 0 0 0 0 1 0 0 0 0 0 0 0 0 0 0 0 0 1 0 0 0 1 0 0 0 0 0 0 0 0 1 0 0 0 0 0 1 0 0 0 0 1 0 1 1 1 1 0 0 1 0 0 0 1 0 0 1 0 0 0 0 0 0 0 0 1 0 0 0 0 0 0 0 0 0 0 0 0 0 1 1 0 0 0 0 0 1 1 1 0 0 1 0 0 0 0 0 0 0 0 0 0 0 0 0 0 0 0 0 0 0 0 0 0 0 0 0 0 1 0 0 0 0 0 0 1 0 0 0 0 0 1 0 0 0 0 0 0 0 0 1 0 0 0 0 1 0 0 0 0 1 1 0 0 0 1 0 0 0 0 1 0 0 1 1 0 0 0 1 0 0 0 0 0 1 0 0 0 0 0 0 0 0 0 1 0 0 0 1 0 0 0 0 0 0 1 1 1 0 0 0 0 0 0 0 0 1 0 0 0 1 0 0 0 1 0 1 0 0 0 1 0 1 0 0 0 0 0 0 0 0 0 0 0 0 0 0 0 0 0 1 0 1 0 1 0 0 0 0 0 0 0 0 0 1 0 0 2 1 0 0 0 0 0 0 0 0 1 0 1 1 1 1 0 0 0 0 0 1 0 0 0 0 0 0 0 0 0 0 0 1 1 0 0 0 0 0 0 0 0 0 0 0 0 0 0 0 0 0 0 1 0 0 0 0 0 0 1 0 0 0 0 0 0 0 1 0 0 0 0 0 0 0 0 0 0 1 1 0 0 0 0 0 0 1 0 0 0 0 0 0 1 1 1 0 0 0 1 0 0 0 0 0 0 1 0 0 0 0 0 1 0 0 1 0 0 1 0 0 0 0 0 0 0 0 0 0 1 0 0 0 0 0 0 0 1 0 0 0 0 0 1 1 0 0 0 0 0 0 1 1 0 0 0 0 0 1 0 0 0 0 0 0 0 0 0 0 0 0 0 0 0 0 0 0 0 0 0 1 0 0 0 0 0 0 1 0 0 0 0 0 0 0 0 0 0 0 0 0 0 0 0 0 1 0 0 1 1 1 0 0 0 0 0 0 1 1 0 0 0 1 1 0 0 0 0 0 0 1 1 1 0 0 0 0 0 0 0 1 1 0 0 1 1 0 3 0 0 0 0 0 1 0 0 0 0 0 0 0 0 0 0 0 0 0 0 0 1 0 0 0 0 1 0 0 0 1 1 0 0 0 0 0 0 0 0 0 0 0 1 1 0 0 0 0 0 0 0 0 0 0 0 0 0 2 1 0 0 0 1 0 0 0 0 0 1 0 1 0 0 0 0 0 0 0 1 0 0 0 0 0 0 0 0 0 0 0 0 0 0 0 0 0 0 0 0 0 0 0 1 0 0 1 0 0 0 0 1 1 0 1 0 0 0 1 0 0 0 0 0 1 0 0 0 0 0 0 1 0 0 0 0 0 0 1 0 0 0 0 0 1 0 0 0 0 0 0 0 0 0 0 0 0 0 0 0 1 2 2 1 0 0 0 0 0 0 0 0 0 1 0 0 0 1 0 1 0 1 0 0 0 0 0 0 0 0 0 0 0 0 0 0 0 0 0 0 0 0 0 1 0 1 0 0 0 0 0 2 0 1 0 1 1 0 0 0 0 0 1 0 0 0 0 0 0 0 0 0 0 1 0 0 0 0 0 0 0 0 0 0 0 0 0 1 0 0 0 0 1 0 0 0 0 1 3 0 0 0 0 0 0 1 0 0 0 0 0 2 0 0 0 1 0 0 1 0 0 0 0 0 0 0 0 0 0 0 1 1 0 0 0 0 0 0 0 0 1 0 1 0 0 0 0 0 0 0 0 0 0 0 0 0 0 1 0 0 0 0 0 0 0 0 0 0 0 0 0 1 0 0 1 0 0 0 0 1 0 0 0 0 0 0 1 1 0 0 0 0 0 0 0 0 0 0 0 0 0 0 0 0 0 1 0 0 0 0 0 0 0 0 0 0 0 1 0 1 0 0 0 0 0 0 0 0 0 0 0 2 0 1 0 1 0 1 0 0 2 0 0 0 1 0 1 0 0 0 0 0 0 0 0 0 0 0 0 0 0 0 0 0 0 0 1 0 0 0 0 0 0 0 1 0 0 0 0 0 0 0 0 0 0 0 0 0 0 0 0 0 0 0 0 0 0 1 0 1 0 0 0 0 0 0 0 0 0 0 0 0 0 0 0 0 0 0 0 0 0 0 0 0 0 1 0 0 0 0 0 0 0 0 0 0 0 0 0 0 0 0 0 0 0 0 0 1 0 0 0 0 0 0 0 0 0 1 0 0 0 0 0 0 0 0 0 0 0 0 1 0 1 0 0 0 2 0 1 0 0 0 0 0 0 0 0 0 0 1 0 0 1 1 1 0 0 0 0 0 0 0 0 1 0 0 0 0 0 0 0 0 0 0 0 0 0 0 0 0 0 1 0 0 0 1 0 0 0 1 0 2 0 1 0 1 1 0 1 0 0 0 1 0 0 0 0 0 0 1 0 0 0 0 1 0 0 0 0 0 0 0 1 0 0 0 0 0 0 1 0 0 0 1 1 1 1 0 1 0 0 1 0 1 0 0 0 0 0 1 0 0 0 0 1 0 1 0 0 1 0 0 0 0 0 0 0 0 0 0 1 0 1 0 0 0 0 0 0 0 0 0 0 0 0 0 0 0 0 0 0 0 0 0 0 0 0 0 0 1 0 1 0 0 0 0 0 1 0 0 0 0 0 0 0 0 0 0 0 0 0 0 0 0 0 0 0 2 0 1 0 1 1 0 0 0 2 0 0 0 0 0 1 2 0 0 2 0 0 0 0 1 0 0 0 0 0 0 0 0 0 0 0 0 0 0 1 1 0 0 0 0 0 0 0 1 0 0 0 0 0 0 0 0 0 0 0 0 2 0 0 0 0 0 0 1 0 1 1 0 0 0 2 0 1 0 0 0 0 0 0 1 1 0 0 0 0 0 0 2 0 0 1 0 0 0 0 0 0 0 0 0 0 0 0 0 0 0 0 0 0 0 0 0 0 0 1 0 0 0 0 0 1 1 0 0 0 0 0 0 0 0 0 0 0 0 0 0 0 0 0 1 0 0 0 0 0 1 1 1 0 0 0 0 0 0 0 0 0 0 0 0 0 0 0 0 1 0 0 0 0 0 0 0 0 0 0 0 1 1 0 0 0 0 0 0 0 0 0 0 0 0 0 0 0 0 0 0 0 0 0 1 0 0 0 0 0 0 3 0 0 0 0 0 0 0 0 1 0 0 0 0 0 0 1 0 1 0 0 0 0 0 0 0 0 0 0 1 0 0 0 0 0 0 0 0 0 0 0 0 0 0 0 1 0 0 1 0 0 0 0 0 0 0 0 0 0 0 0 0 0 0 0 0 0 0 0 0 1 0 0 0 0 0 0 0 0 1 0 0 0 0 0 0 1 1 1 1 0 0 0 0 0 1 0 0 1 0 0 0 0 1 1 1 0 0 0 0 0 0 0 0 0 0 0 0 0 0 0 1 0 0 0 0 0 0 0 0 0 0 1 0 1 0 1 0 0 0 0 0 0 0 0 1 1 2 1 0 2 0 0 1 0 0 0 0 0 1 0 0 0 0 0 0 1 1 0 1 0 2 0 0 0 0 1 0 0 0 1 0 1 0 0 0 0 0 0 0 1 0 1 0 0 1 1 0 0 1 0 0 0 0 0 0 1 0 1 0 0 0 0 0 0 1 0 0 0 0 0 0 2 0 0 0 0 1 0 0 2 0 0 0 0 0 0 0 0 0 1 0 0 0 0 1 0 0 0 0 0 0 0 0 0 0 0 0 0 0 0 0 0 0 0 0 0 0 0 0 0 0 0 0 0 0 0 0 0 0 0 0 0 0 2 0 1 0 1 0 0 0 0 0 0 0 0 0 1 0 0 1 0 0 0 1 0 1 0 1 0 2 0 0 0 0 0 0 0 0 0 0 0 0 0 0 0 0 0 0 0 0 1 0 0 0 1 0 0 0 1 0 0 0 0 0 0 1 1 0 0 0 1 0 0 0 1 0 1 0 0 0 0 0 0 0 1 0 0 1 0 1 1 0 0 1 0 0 0 0 0 0 0 0 0 1 0 0 0 0 0 0 0 0 0 1 0 1 0 0 0 0 0 0 0 0 0 0 1 0 0 0 1 0 1 0 0 0 1 0 0 0 1 0 0 0 1 0 1 0 0 0 0 0 0 0 0 0 0 0 0 0 1 0 0 0 0 0 0 0 0 0 0 0 0 0 0 0 0 0 0 0 0 0 0 0 0 0 0 0 2 1 0 0 0 0 0 0 0 0 0 0 0 0 1 0 0 0 0 0 0 0 0 0 0 2 0 0 0 0 1 0 0 0 0 1 0 0 0 0 0 0 0 0 0 0 1 0 0 0 0 0 0 0 0 0 0 0 1 0 1 0 0 0 0 0 0 0 0 0 0 0 0 0 0 0 0 0 1 0 0 0 0 0 0 0 0 0 0 0 2 0 0 1 1 1 1 0 1 0 0 0 1 0 0 0 1 1 0 0 0 0 0 0 0 0 0 0 1 0 0 0 0 0 0 0 0 0 0 0 0 0 0 0 1 0 0 0 0 0 0 0 0 0 0 0 1 1 0 0 0 0 1 0 0 0 1 0 0 0 0 0 0 0 0 0 1 0 1 1 0 2 1 0 1 1 0 0 1 0 0 1 0 0 0 1 0 0 0 0 0 1 0 1 0 0 1 1 0 0 0 0 0 0 0 0 1 1 0 0 0 0 0 0 1 0 1 0 0 0 1 0 0 0 0 1 0 1 0 0 0 0 0 1 0 1 0 0 3 1 0 0 0 0 0 0 0 0 0 1 0 0 0 0 0 1 0 0 0 1 0 0 0 0 0 0 0 0 0 0 0 0 0 0 0 0 0 1 0 1 0 0 0 0 0 0 1 0 0 0 0 0 0 0 0 2 0 2 0 0 1 0 0 0 0 1 0 0 0 0 0 0 0 0 0 0 0 0 0 1 0 0 0 1 0 1 0 0 0 0 0 0 1 1 0 0 0 0 0 0 0 0 0 1 2 0 0 0 0 0 0 0 1 0 0 1 0 1 0 0 0 0 0 0 0 0 0 0 0 0 0 0 0 0 0 0 0 0 0 0 0 0 0 0 0 0 0 0 0 0 0 0 0 0 0 0 0 0 0 1 1 0 0 0 0 0 0 0 0 0 0 0 0 0 0 0 0 0 0 0 0 0 0 0 0 0 0 1 0 0 0 0 0 0 0 0 0 0 0 0 0 0 1 0 2 0 0 1 1 0 0 1 0 1 0 0 0 0 0 1 0 0 0 0 0 0 1 0 0 0 1 0 0 0 0 0 0 0 0 0 0 0 0 0 0 1 0 0 0 1 0 1 0 1 0 1 0 0 0 0 0 0 0 0 0 0 0 0 0 0 0 0 0 0 0 0 0 0 0 1 1 0 0 0 1 0 0 0 0 0 0 0 0 0 0 0 0 0 0 0 0 0 1 1 0 0 0 0 0 0 0 0 1 0 0 0 0 0 0 1 0 0 0 0 0 0 1 1 1 0 0 0 0 0 0 0 0 0 0 0 0 1 0 0 0 0 0 1 0 0 0 0 0 2 0 0 0 0 0 0 0 1 0 0 0 0 0 0 0 0 1 0 0 0 0 1 0 0 0 0 0 1 1 0 0 0 0 0 0 2 0 0 0 1 0 0 1 2 0 1 1 0 0 0 0 0 0 0 0 0 0 0 0 0 0 0 1 1 0 0 0 0 0 0 0 0 0 0 0 0 1 0 0 0 0 0 0 0 0 0 0 0 1 0 0 0 1 1 0 0 0 0 0 0 1 0 1 0 0 0 0 0 0 0 0 0 0 0 0 0 0 0 1 0 1 1 0 0 1 0 0 0 0 0 1 0 0 1 0 0 0 0 0 1 0 0 0 0 0 0 0 0 0 1 0 0 0 0 0 1 0 1 0 1 0 0 0 1 0 2 0 0 1 0 1 1 0 0 0 0 0 0 0 0 0 0 0 0 0 0 0 0 0 1 0 0 1 0 1 0 0 0 0 0 0 0 0 0 0 0 0 0 0 0 0 0 1 0 0 0 0 0 0 0 0 0 0 0 1 0 0 0 0 0 0 0 0 0 1 0 1 0 0 0 0 0 0 1 0 0 0 0 0 0 0 0 0 1 0 0 1 0 0 0 0 0 0 1 0 0 0 0 1 0 0 0 0 1 0 0 1 1 0 0 0 0 0 0 0 0 0 1 0 0 0 1 0 0 1 0 0 1 0 0 0 0 0 0 1 0 0 0 1 0 0 0 0 0 1 0 1 0 0 0 0 0 0 1 0 0 0 0 0 1 0 0 0 0 0 0 0 0 0 1 0 0 0 0 0 1 0 0 0 0 0 0 0 0 0 0 0 1 0 1 0 0 0 1 0 1 0 0 1 0 0 1 0 0 0 0 0 0 0 0 0 0 0 0 0 0 0 0 0 0 0 0 0 0 1 0 0 0 1 0 2 0 0 1 0 0 0 0 0 0 0 0 0 0 0 0 0 0 0 0 1 0 0 0 0 0 1 0 0 1 0 0 0 0 0 0 0 0 1 0 0 0 0 0 1</intensities>
			</dataPoints>
		</scan>
	</xrdMeasurement>
</xrdMeasurements>